Workbook

Sheet Planilha2
A9: Nome Brawler | B9: Soma de Durability | C9: Soma de Distância-Ataque | D9: Soma de C Durability | E9: Soma de Ataque-Surpresa | F9: Soma de Aproximação-Fácil | G9: Soma de C Distância-ataque
A10: 8-BIT | B10: 7 | C10: 8 | D10: 6 | E10: 0 | F10: 1.9966667 | G10: 7.3318519
A11: ALLI | B11: 4 | C11: 1 | D11: 5 | E11: 6 | F11: 6.9966667 | G11: 5.5540741
A12: AMBER | B12: 3 | C12: 7 | D12: 6 | E12: 0 | F12: 1.9966667 | G12: 5.9985185
A13: ANGELO | B13: 3 | C13: 9 | D13: 6 | E13: 0 | F13: 3.33 | G13: 7.48
A14: ASH | B14: 9 | C14: 4 | D14: 5 | E14: 0 | F14: 3.9966667 | G14: 6.6651852
A15: BARLEY | B15: 2 | C15: 6 | D15: 5 | E15: 0 | F15: 1.6633333 | G15: 4.9614815
A16: BEA | B16: 3 | C16: 8 | D16: 6 | E16: 0 | F16: 1.9966667 | G16: 6.442963
A17: BELLE | B17: 2 | C17: 8 | D17: 4 | E17: 0 | F17: 1.6633333 | G17: 5.6281481
A18: BERRY | B18: 2 | C18: 5 | D18: 5 | E18: 7 | F18: 6.33 | G18: 6.5911111
A19: BIBI | B19: 7 | C19: 2 | D19: 5 | E19: 0 | F19: 4.6633333 | G19: 5.6281481
A20: BO | B20: 4 | C20: 7 | D20: 5 | E20: 0 | F20: 2.33 | G20: 6.1466667
A21: BONNIE | B21: 6 | C21: 8 | D21: 5 | E21: 7 | F21: 6.9966667 | G21: 9.1096296
... A109: Total Geral | B109: 442 | C109: 570 | D109: 514 | E109: 169 | F109: 394.33667 | G109: 641.03852

Sheet Planilha1
W1: durabilidade, (suporte-cura, suporte-escudo) | AA1: ataque-surpresa, (durabilidade, velocidade-movimento) | AB1: distancia-ataque, (durabilidade, aproximação-facil, counter-durabilidade) | AC1: durabilidade (C-durabilidade, potencial-dano-curto-alcance)
B3: ID | C3: Nome Brawler | H3: POT-DAN-CUR-ALC | J3: PODER-DE-STUN | P3: DANO-PETS | W3: Durability | X3: Distância-Ataque | Y3: C Durability | Z3: Ataque-Surpresa | AA3: Aproximação-Fácil | AB3: C Distância-ataque | AC3: Botão-de-Fuga
B4: 1 | C4: SHELLY | H4: 7 | W4: 4 | X4: 6 | Y4: 8 | Z4: 0 | AA4: =SUM(Z4, AVERAGE(7, W4))/1.5-0.67 -> 2.9966667 | AB4: =SUM(X4, AA4, AVERAGE(Y4, W4))/2.25 -> 6.6651852 | AC4: =SUM(AVERAGE(Y4, W4), AVERAGE(Y4, 7))/1.5 -> 9
B5: 2 | C5: NITA | H5: 9 | W5: 5 | X5: 5 | Y5: 6 | Z5: 0 | AA5: =SUM(Z5, AVERAGE(5, W5))/1.5-0.67 -> 2.6633333 | AB5: =SUM(X5, AA5, AVERAGE(Y5, W5))/2.25 -> 5.8503704 | AC5: =SUM(AVERAGE(Y5, W5), AVERAGE(Y5, 9))/1.5 -> 8.6666667
B6: 3 | C6: COLT | H6: 6 | W6: 3 | X6: 8 | Y6: 9 | Z6: 0 | AA6: =SUM(Z6, AVERAGE(5, W6))/1.5-0.67 -> 1.9966667 | AB6: =SUM(X6, AA6, AVERAGE(Y6, W6))/2.25 -> 7.1096296 | AC6: =SUM(AVERAGE(Y6, W6), AVERAGE(Y6, 6))/1.5 -> 9
B7: 4 | C7: BULL | H7: 7 | W7: 7 | X7: 2 | Y7: 8 | Z7: 4 | AA7: =SUM(Z7, AVERAGE(7, W7))/1.5-0.67 -> 6.6633333 | AB7: =SUM(X7, AA7, AVERAGE(Y7, W7))/2.25 -> 7.1837037 | AC7: =SUM(AVERAGE(Y7, W7), AVERAGE(Y7, 7))/1.5 -> 10
B8: 5 | C8: BROCK | H8: 7 | W8: 3 | X8: 7 | Y8: 6 | Z8: 0 | AA8: =SUM(Z8, AVERAGE(5, W8))/1.5-0.67 -> 1.9966667 | AB8: =SUM(X8, AA8, AVERAGE(Y8, W8))/2.25 -> 5.9985185 | AC8: =SUM(AVERAGE(Y8, W8), AVERAGE(Y8, 7))/1.5 -> 7.3333333
B9: 6 | C9: EL PRIMO | H9: 7 | W9: 10 | X9: 1 | Y9: 5 | Z9: 3 | AA9: =SUM(Z9, AVERAGE(7, W9))/1.5-0.67 -> 6.9966667 | AB9: =SUM(X9, AA9, AVERAGE(Y9, W9))/2.25 -> 6.8874074 | AC9: =SUM(AVERAGE(Y9, W9), AVERAGE(Y9, 7))/1.5 -> 9
B10: 7 | C10: BARLEY | H10: 5 | W10: 2 | X10: 6 | Y10: 5 | Z10: 0 | AA10: =SUM(Z10, AVERAGE(5, W10))/1.5-0.67 -> 1.6633333 | AB10: =SUM(X10, AA10, AVERAGE(Y10, W10))/2.25 -> 4.9614815 | AC10: =SUM(AVERAGE(Y10, W10), AVERAGE(Y10, 5))/1.5 -> 5.6666667
B11: 8 | C11: POCO | H11: 9 | W11: 5 | X11: 6 | Y11: 2 | Z11: 0 | AA11: =SUM(Z11, AVERAGE(5, W11))/1.5-0.67 -> 2.6633333 | AB11: =SUM(X11, AA11, AVERAGE(Y11, W11))/2.25 -> 5.4059259 | AC11: =SUM(AVERAGE(Y11, W11), AVERAGE(Y11, 9))/1.5 -> 6
B12: 9 | C12: ROSA | H12: 8 | W12: 7 | X12: 3 | Y12: 4 | Z12: 0 | AA12: =SUM(Z12, AVERAGE(7, W12))/1.5-0.67 -> 3.9966667 | AB12: =SUM(X12, AA12, AVERAGE(Y12, W12))/2.25 -> 5.5540741 | AC12: =SUM(AVERAGE(Y12, W12), AVERAGE(Y12, 8))/1.5 -> 7.6666667
B13: 10 | C13: JESSIE | H13: 8 | W13: 3 | X13: 7 | Y13: 6 | Z13: 0 | AA13: =SUM(Z13, AVERAGE(5, W13))/1.5-0.67 -> 1.9966667 | AB13: =SUM(X13, AA13, AVERAGE(Y13, W13))/2.25 -> 5.9985185 | AC13: =SUM(AVERAGE(Y13, W13), AVERAGE(Y13, 8))/1.5 -> 7.6666667
B14: 11 | C14: DYNAMIKE | H14: 3 | W14: 3 | X14: 6 | Y14: 8 | Z14: 0 | AA14: =SUM(Z14, AVERAGE(7, W14))/1.5-0.67 -> 2.6633333 | AB14: =SUM(X14, AA14, AVERAGE(Y14, W14))/2.25 -> 6.2948148 | AC14: =SUM(AVERAGE(Y14, W14), AVERAGE(Y14, 3))/1.5 -> 7.3333333
B15: 12 | C15: TICK | H15: 4 | W15: 1 | X15: 7 | Y15: 5 | Z15: 0 | AA15: =SUM(Z15, AVERAGE(5, W15))/1.5-0.67 -> 1.33 | AB15: =SUM(X15, AA15, AVERAGE(Y15, W15))/2.25 -> 5.0355556 | AC15: =SUM(AVERAGE(Y15, W15), AVERAGE(Y15, 4))/1.5 -> 5
B16: 13 | C16: 8-BIT | H16: 5 | W16: 7 | X16: 8 | Y16: 6 | Z16: 0 | AA16: =SUM(Z16, AVERAGE(1, W16))/1.5-0.67 -> 1.9966667 | AB16: =SUM(X16, AA16, AVERAGE(Y16, W16))/2.25 -> 7.3318519 | AC16: =SUM(AVERAGE(Y16, W16), AVERAGE(Y16, 5))/1.5 -> 8
B17: 14 | C17: RICO | H17: 6 | W17: 3 | X17: 8 | Y17: 9 | Z17: 0 | AA17: =SUM(Z17, AVERAGE(5, W17))/1.5-0.67 -> 1.9966667 | AB17: =SUM(X17, AA17, AVERAGE(Y17, W17))/2.25 -> 7.1096296 | AC17: =SUM(AVERAGE(Y17, W17), AVERAGE(Y17, 6))/1.5 -> 9
B18: 15 | C18: DARRYL | H18: 7 | W18: 8 | X18: 4 | Y18: 5 | Z18: 6 | AA18: =SUM(Z18, AVERAGE(7, W18))/1.5-0.67 -> 8.33 | AB18: =SUM(X18, AA18, AVERAGE(Y18, W18))/2.25 -> 8.3688889 | AC18: =SUM(AVERAGE(Y18, W18), AVERAGE(Y18, 7))/1.5 -> 8.3333333
B19: 16 | C19: PENNY | H19: 8 | W19: 4 | X19: 6 | Y19: 5 | Z19: 0 | AA19: =SUM(Z19, AVERAGE(5, W19))/1.5-0.67 -> 2.33 | AB19: =SUM(X19, AA19, AVERAGE(Y19, W19))/2.25 -> 5.7022222 | AC19: =SUM(AVERAGE(Y19, W19), AVERAGE(Y19, 8))/1.5 -> 7.3333333
B20: 17 | C20: CARL | H20: 6 | W20: 5 | X20: 7 | Y20: 6 | Z20: 0 | AA20: =SUM(Z20, AVERAGE(5, W20))/1.5-0.67 -> 2.6633333 | AB20: =SUM(X20, AA20, AVERAGE(Y20, W20))/2.25 -> 6.7392593 | AC20: =SUM(AVERAGE(Y20, W20), AVERAGE(Y20, 6))/1.5 -> 7.6666667
B21: 18 | C21: JACKY | H21: 8 | W21: 7 | X21: 3 | Y21: 4 | Z21: 0 | AA21: =SUM(Z21, AVERAGE(7, W21))/1.5-0.67 -> 3.9966667 | AB21: =SUM(X21, AA21, AVERAGE(Y21, W21))/2.25 -> 5.5540741 | AC21: =SUM(AVERAGE(Y21, W21), AVERAGE(Y21, 8))/1.5 -> 7.6666667
B22: 19 | C22: GUS | H22: 8 | W22: 3 | X22: 8 | Y22: 4 | Z22: 0 | AA22: =SUM(Z22, AVERAGE(5, W22))/1.5-0.67 -> 1.9966667 | AB22: =SUM(X22, AA22, AVERAGE(Y22, W22))/2.25 -> 5.9985185 | AC22: =SUM(AVERAGE(Y22, W22), AVERAGE(Y22, 8))/1.5 -> 6.3333333
B23: 20 | C23: BO | H23: 8 | W23: 4 | X23: 7 | Y23: 5 | Z23: 0 | AA23: =SUM(Z23, AVERAGE(5, W23))/1.5-0.67 -> 2.33 | AB23: =SUM(X23, AA23, AVERAGE(Y23, W23))/2.25 -> 6.1466667 | AC23: =SUM(AVERAGE(Y23, W23), AVERAGE(Y23, 8))/1.5 -> 7.3333333
B24: 21 | C24: EMZ | H24: 6 | W24: 4 | X24: 5 | Y24: 6 | Z24: 0 | AA24: =SUM(Z24, AVERAGE(5, W24))/1.5-0.67 -> 2.33 | AB24: =SUM(X24, AA24, AVERAGE(Y24, W24))/2.25 -> 5.48 | AC24: =SUM(AVERAGE(Y24, W24), AVERAGE(Y24, 6))/1.5 -> 7.3333333
B25: 22 | C25: STU | H25: 8 | W25: 4 | X25: 6 | Y25: 4 | Z25: 3 | AA25: =SUM(Z25, AVERAGE(5, W25))/1.5-0.67 -> 4.33 | AB25: =SUM(X25, AA25, AVERAGE(Y25, W25))/2.25 -> 6.3688889 | AC25: =SUM(AVERAGE(Y25, W25), AVERAGE(Y25, 8))/1.5 -> 6.6666667
B26: 23 | C26: PIPER | H26: 4 | W26: 2 | X26: 9 | Y26: 6 | Z26: 1 | AA26: =SUM(Z26, AVERAGE(5, W26))/1.5-0.67 -> 2.33 | AB26: =SUM(X26, AA26, AVERAGE(Y26, W26))/2.25 -> 6.8133333 | AC26: =SUM(AVERAGE(Y26, W26), AVERAGE(Y26, 4))/1.5 -> 6
B27: 24 | C27: PAM | H27: 6 | W27: 7 | X27: 7 | Y27: 5 | Z27: 0 | AA27: =SUM(Z27, AVERAGE(5, W27))/1.5-0.67 -> 3.33 | AB27: =SUM(X27, AA27, AVERAGE(Y27, W27))/2.25 -> 7.2577778 | AC27: =SUM(AVERAGE(Y27, W27), AVERAGE(Y27, 6))/1.5 -> 7.6666667
B28: 25 | C28: FRANK | H28: 8 | W28: 10 | X28: 5 | Y28: 5 | Z28: 0 | AA28: =SUM(Z28, AVERAGE(7, W28))/1.5-0.67 -> 4.9966667 | AB28: =SUM(X28, AA28, AVERAGE(Y28, W28))/2.25 -> 7.7762963 | AC28: =SUM(AVERAGE(Y28, W28), AVERAGE(Y28, 8))/1.5 -> 9.3333333
B29: 26 | C29: BIBI | H29: 8 | W29: 7 | X29: 2 | Y29: 5 | Z29: 0 | AA29: =SUM(Z29, AVERAGE(9, W29))/1.5-0.67 -> 4.6633333 | AB29: =SUM(X29, AA29, AVERAGE(Y29, W29))/2.25 -> 5.6281481 | AC29: =SUM(AVERAGE(Y29, W29), AVERAGE(Y29, 8))/1.5 -> 8.3333333
B30: 27 | C30: BEA | H30: 8 | W30: 3 | X30: 8 | Y30: 6 | Z30: 0 | AA30: =SUM(Z30, AVERAGE(5, W30))/1.5-0.67 -> 1.9966667 | AB30: =SUM(X30, AA30, AVERAGE(Y30, W30))/2.25 -> 6.442963 | AC30: =SUM(AVERAGE(Y30, W30), AVERAGE(Y30, 8))/1.5 -> 7.6666667
B31: 28 | C31: NANI | H31: 8 | W31: 2 | X31: 10 | Y31: 7 | Z31: 0 | AA31: =SUM(Z31, AVERAGE(5, W31))/1.5-0.67 -> 1.6633333 | AB31: =SUM(X31, AA31, AVERAGE(Y31, W31))/2.25 -> 7.1837037 | AC31: =SUM(AVERAGE(Y31, W31), AVERAGE(Y31, 8))/1.5 -> 8
B32: 29 | C32: EDGAR | H32: 7 | W32: 4 | X32: 1 | Y32: 5 | Z32: 6 | AA32: =SUM(Z32, AVERAGE(9, W32))/1.5-0.67 -> 7.6633333 | AB32: =SUM(X32, AA32, AVERAGE(Y32, W32))/2.25 -> 5.8503704 | AC32: =SUM(AVERAGE(Y32, W32), AVERAGE(Y32, 7))/1.5 -> 7
B33: 30 | C33: GRIFF | H33: 8 | W33: 4 | X33: 7 | Y33: 9 | Z33: 0 | AA33: =SUM(Z33, AVERAGE(5, W33))/1.5-0.67 -> 2.33 | AB33: =SUM(X33, AA33, AVERAGE(Y33, W33))/2.25 -> 7.0355556 | AC33: =SUM(AVERAGE(Y33, W33), AVERAGE(Y33, 8))/1.5 -> 10
B34: 31 | C34: GROM | H34: 4 | W34: 3 | X34: 7 | Y34: 4 | Z34: 0 | AA34: =SUM(Z34, AVERAGE(5, W34))/1.5-0.67 -> 1.9966667 | AB34: =SUM(X34, AA34, AVERAGE(Y34, W34))/2.25 -> 5.5540741 | AC34: =SUM(AVERAGE(Y34, W34), AVERAGE(Y34, 4))/1.5 -> 5
B35: 32 | C35: BONNIE | H35: 9 | W35: 6 | X35: 8 | Y35: 5 | Z35: 7 | AA35: =SUM(Z35, AVERAGE(3, W35))/1.5-0.67 -> 6.9966667 | AB35: =SUM(X35, AA35, AVERAGE(Y35, W35))/2.25 -> 9.1096296 | AC35: =SUM(AVERAGE(Y35, W35), AVERAGE(Y35, 9))/1.5 -> 8.3333333
B36: 33 | C36: GALE | H36: 6 | W36: 5 | X36: 7 | Y36: 5 | Z36: 0 | AA36: =SUM(Z36, AVERAGE(5, W36))/1.5-0.67 -> 2.6633333 | AB36: =SUM(X36, AA36, AVERAGE(Y36, W36))/2.25 -> 6.517037 | AC36: =SUM(AVERAGE(Y36, W36), AVERAGE(Y36, 6))/1.5 -> 7
B37: 34 | C37: COLLETE | H37: 9 | W37: 4 | X37: 8 | Y37: 4 | Z37: 0 | AA37: =SUM(Z37, AVERAGE(5, W37))/1.5-0.67 -> 2.33 | AB37: =SUM(X37, AA37, AVERAGE(Y37, W37))/2.25 -> 6.3688889 | AC37: =SUM(AVERAGE(Y37, W37), AVERAGE(Y37, 9))/1.5 -> 7
B38: 35 | C38: BELLE | H38: 8 | W38: 2 | X38: 8 | Y38: 4 | Z38: 0 | AA38: =SUM(Z38, AVERAGE(5, W38))/1.5-0.67 -> 1.6633333 | AB38: =SUM(X38, AA38, AVERAGE(Y38, W38))/2.25 -> 5.6281481 | AC38: =SUM(AVERAGE(Y38, W38), AVERAGE(Y38, 8))/1.5 -> 6
B39: 36 | C39: ASH | H39: 8 | W39: 9 | X39: 4 | Y39: 5 | Z39: 0 | AA39: =SUM(Z39, AVERAGE(5, W39))/1.5-0.67 -> 3.9966667 | AB39: =SUM(X39, AA39, AVERAGE(Y39, W39))/2.25 -> 6.6651852 | AC39: =SUM(AVERAGE(Y39, W39), AVERAGE(Y39, 8))/1.5 -> 9
B40: 37 | C40: LOLA | H40: 7 | W40: 5 | X40: 7 | Y40: 6 | Z40: 0 | AA40: =SUM(Z40, AVERAGE(5, W40))/1.5-0.67 -> 2.6633333 | AB40: =SUM(X40, AA40, AVERAGE(Y40, W40))/2.25 -> 6.7392593 | AC40: =SUM(AVERAGE(Y40, W40), AVERAGE(Y40, 7))/1.5 -> 8
B41: 38 | C41: SAM | H41: 8 | W41: 8 | X41: 3 | Y41: 4 | Z41: 0 | AA41: =SUM(Z41, AVERAGE(7, W41))/1.5-0.67 -> 4.33 | AB41: =SUM(X41, AA41, AVERAGE(Y41, W41))/2.25 -> 5.9244444 | AC41: =SUM(AVERAGE(Y41, W41), AVERAGE(Y41, 8))/1.5 -> 8
...

Sheet DADOS UTEISA
B2: VELOCIDADES RECARGA
B3: MT-RAPIDO | C3: 0.66t p/s
B4: RAPIDO | C4: 0.57t p/s
B5: NORMAL | C5: 0.50t p/s
B6: LENTO | C6: 0.43t p/s
B7: MT-LENTO | C7: 0.33t p/s

Sheet Planilha3
A2: ID | B2: (Tudo)
B4: Nome Brawler | F4: Nome Brawler | G4: NOME ACESSÓRIO | K4: Nome Brawler | L4: NOME ACESSÓRIO | P4: Nome Brawler | Q4: NOME PODER DE ESTRELA | U4: Nome Brawler | V4: NOME PODER DE ESTRELA | Z4: Nome Brawler | AA4: NOME HIPERCARGA
A5: Valores | B5: TICK | C5: Total Geral | F5: TICK | G5: TICK Total | H5: Total Geral | K5: TICK | L5: TICK Total | M5: Total Geral | P5: TICK | Q5: TICK Total | R5: Total Geral | U5: TICK | V5: TICK Total | W5: Total Geral | Z5: TICK | AA5: TICK Total | AB5: Total Geral
A6: Soma de PROJETEIS-PARA-SUPER | B6: 6 | C6: 6 | E6: Valores | F6: MINE MANIA | J6: Valores | K6: LAST HURRAH | O6: Valores | P6: WELL OILED | T6: Valores | U6: AUTOMA-TICK RELOAD | Y6: Valores | Z6: HEADSTRONG
A7: Soma de SUPERS-PARA-HIPERCARGA | B7: 2.3333333 | C7: 2.3333333 | E7: Soma de PROJETEIS-PARA-SUPER | F7: 0 | G7: 0 | H7: 0 | J7: Soma de PROJETEIS-PARA-SUPER | K7: 0 | L7: 0 | M7: 0 | O7: Soma de PROJETEIS-PARA-SUPER | P7: 0 | Q7: 0 | R7: 0 | T7: Soma de PROJETEIS-PARA-SUPER | U7: 0 | V7: 0 | W7: 0 | Y7: Soma de PROJETEIS-PARA-SUPER | Z7: 0 | AA7: 0 | AB7: 0
A8: Soma de DANO-PROJETIL | B8: 1360 | C8: 1360 | E8: Soma de SUPERS-PARA-HIPERCARGA | F8: 0 | G8: 0 | H8: 0 | J8: Soma de SUPERS-PARA-HIPERCARGA | K8: 0 | L8: 0 | M8: 0 | O8: Soma de SUPERS-PARA-HIPERCARGA | P8: 0 | Q8: 0 | R8: 0 | T8: Soma de SUPERS-PARA-HIPERCARGA | U8: 0 | V8: 0 | W8: 0 | Y8: Soma de SUPERS-PARA-HIPERCARGA | Z8: 0 | AA8: 0 | AB8: 0
A9: Soma de TIROS-DADOS-EM-5-SEGUNDOS | B9: 1.65 | C9: 1.65 | E9: Soma de DANO-PROJETIL | F9: 0 | G9: 0 | H9: 0 | J9: Soma de DANO-PROJETIL | K9: 0 | L9: 0 | M9: 0 | O9: Soma de DANO-PROJETIL | P9: 0 | Q9: 0 | R9: 0 | T9: Soma de DANO-PROJETIL | U9: 0 | V9: 0 | W9: 0 | Y9: Soma de DANO-PROJETIL | Z9: 29.142857 | AA9: 29.142857 | AB9: 29.142857
A10: Soma de MÉDIA-PROJETEIS-POR-TIRO | B10: 2 | C10: 2 | E10: Soma de TIROS-DADOS-EM-5-SEGUNDOS | F10: 0 | G10: 0 | H10: 0 | J10: Soma de TIROS-DADOS-EM-5-SEGUNDOS | K10: 0 | L10: 0 | M10: 0 | O10: Soma de TIROS-DADOS-EM-5-SEGUNDOS | P10: 0 | Q10: 0 | R10: 0 | T10: Soma de TIROS-DADOS-EM-5-SEGUNDOS | U10: 0.1485 | V10: 0.1485 | W10: 0.1485 | Y10: Soma de TIROS-DADOS-EM-5-SEGUNDOS | Z10: 0 | AA10: 0 | AB10: 0
A11: Soma de CURTO-ALCANCE-QUANT-PROJETIL-MEDIO | B11: 1 | C11: 1 | E11: Soma de MÉDIA-PROJETEIS-POR-TIRO | F11: 0.66666667 | G11: 0.66666667 | H11: 0.66666667 | J11: Soma de MÉDIA-PROJETEIS-POR-TIRO | K11: 0 | L11: 0 | M11: 0 | O11: Soma de MÉDIA-PROJETEIS-POR-TIRO | P11: 0 | Q11: 0 | R11: 0 | T11: Soma de MÉDIA-PROJETEIS-POR-TIRO | U11: 0 | V11: 0 | W11: 0 | Y11: Soma de MÉDIA-PROJETEIS-POR-TIRO | Z11: 0 | AA11: 0 | AB11: 0
A12: Soma de MEDIO-ALCANCE-QUANT-PROJETIL-MEDIO | B12: 2 | C12: 2 | E12: Soma de CURTO-ALCANCE-QUANT-PROJETIL-MEDIO | F12: 0.33333333 | G12: 0.33333333 | H12: 0.33333333 | J12: Soma de CURTO-ALCANCE-QUANT-PROJETIL-MEDIO | K12: 0 | L12: 0 | M12: 0 | O12: Soma de CURTO-ALCANCE-QUANT-PROJETIL-MEDIO | P12: 0 | Q12: 0 | R12: 0 | T12: Soma de CURTO-ALCANCE-QUANT-PROJETIL-MEDIO | U12: 0 | V12: 0 | W12: 0 | Y12: Soma de CURTO-ALCANCE-QUANT-PROJETIL-MEDIO | Z12: 0 | AA12: 0 | AB12: 0
A13: Soma de LONGO-ALCANCE-QUANT-PROJETIL-MEDIO | B13: 1 | C13: 1 | E13: Soma de MEDIO-ALCANCE-QUANT-PROJETIL-MEDIO | F13: 0.66666667 | G13: 0.66666667 | H13: 0.66666667 | J13: Soma de MEDIO-ALCANCE-QUANT-PROJETIL-MEDIO | K13: 0 | L13: 0 | M13: 0 | O13: Soma de MEDIO-ALCANCE-QUANT-PROJETIL-MEDIO | P13: 0 | Q13: 0 | R13: 0 | T13: Soma de MEDIO-ALCANCE-QUANT-PROJETIL-MEDIO | U13: 0 | V13: 0 | W13: 0 | Y13: Soma de MEDIO-ALCANCE-QUANT-PROJETIL-MEDIO | Z13: 0 | AA13: 0 | AB13: 0
A14: Soma de MTLONGO-ALCANCE-QUANT-PROJETIL-MEDIO | B14: 1 | C14: 1 | E14: Soma de LONGO-ALCANCE-QUANT-PROJETIL-MEDIO | F14: 0.33333333 | G14: 0.33333333 | H14: 0.33333333 | J14: Soma de LONGO-ALCANCE-QUANT-PROJETIL-MEDIO | K14: 0 | L14: 0 | M14: 0 | O14: Soma de LONGO-ALCANCE-QUANT-PROJETIL-MEDIO | P14: 0 | Q14: 0 | R14: 0 | T14: Soma de LONGO-ALCANCE-QUANT-PROJETIL-MEDIO | U14: 0 | V14: 0 | W14: 0 | Y14: Soma de LONGO-ALCANCE-QUANT-PROJETIL-MEDIO | Z14: 0 | AA14: 0 | AB14: 0
A15: Soma de CARREGAMENTO-SUPER-AO-ACERTAR-EM-PROJETEIS | B15: 2 | C15: 2 | E15: Soma de MTLONGO-ALCANCE-QUANT-PROJETIL-MEDIO | F15: 0.33333333 | G15: 0.33333333 | H15: 0.33333333 | J15: Soma de MTLONGO-ALCANCE-QUANT-PROJETIL-MEDIO | K15: 0 | L15: 0 | M15: 0 | O15: Soma de MTLONGO-ALCANCE-QUANT-PROJETIL-MEDIO | P15: 0 | Q15: 0 | R15: 0 | T15: Soma de MTLONGO-ALCANCE-QUANT-PROJETIL-MEDIO | U15: 0 | V15: 0 | W15: 0 | Y15: Soma de MTLONGO-ALCANCE-QUANT-PROJETIL-MEDIO | Z15: 0 | AA15: 0 | AB15: 0
A16: Soma de CURTO-ALCANCE-DANO-SUPER-MEDIO | B16: 4000 | C16: 4000 | E16: Soma de CARREGAMENTO-SUPER-AO-ACERTAR-EM-PROJETEIS | F16: 0 | G16: 0 | H16: 0 | J16: Soma de CARREGAMENTO-SUPER-AO-ACERTAR-EM-PROJETEIS | K16: 0 | L16: 0 | M16: 0 | O16: Soma de CARREGAMENTO-SUPER-AO-ACERTAR-EM-PROJETEIS | P16: 0 | Q16: 0 | R16: 0 | T16: Soma de CARREGAMENTO-SUPER-AO-ACERTAR-EM-PROJETEIS | U16: 0 | V16: 0 | W16: 0 | Y16: Soma de CARREGAMENTO-SUPER-AO-ACERTAR-EM-PROJETEIS | Z16: 0 | AA16: 0 | AB16: 0
A17: Soma de MEDIO-ALCANCE-DANO-SUPER-MEDIO | B17: 3000 | C17: 3000 | E17: Soma de CURTO-ALCANCE-DANO-SUPER-MEDIO | F17: 0 | G17: 0 | H17: 0 | J17: Soma de CURTO-ALCANCE-DANO-SUPER-MEDIO | K17: 0 | L17: 0 | M17: 0 | O17: Soma de CURTO-ALCANCE-DANO-SUPER-MEDIO | P17: 0 | Q17: 0 | R17: 0 | T17: Soma de CURTO-ALCANCE-DANO-SUPER-MEDIO | U17: 0 | V17: 0 | W17: 0 | Y17: Soma de CURTO-ALCANCE-DANO-SUPER-MEDIO | Z17: 1800 | AA17: 1800 | AB17: 1800
A18: Soma de LONGO-ALCANCE-DANO-SUPER-MEDIO | B18: 2000 | C18: 2000 | E18: Soma de MEDIO-ALCANCE-DANO-SUPER-MEDIO | F18: 0 | G18: 0 | H18: 0 | J18: Soma de MEDIO-ALCANCE-DANO-SUPER-MEDIO | K18: 0 | L18: 0 | M18: 0 | O18: Soma de MEDIO-ALCANCE-DANO-SUPER-MEDIO | P18: 0 | Q18: 0 | R18: 0 | T18: Soma de MEDIO-ALCANCE-DANO-SUPER-MEDIO | U18: 0 | V18: 0 | W18: 0 | Y18: Soma de MEDIO-ALCANCE-DANO-SUPER-MEDIO | Z18: 1350 | AA18: 1350 | AB18: 1350
... A63: Soma de COUNTER-CANCELAMENTO-ATAQUES | B63: 7 | C63: 7 | E63: Soma de CANCELAMENTO-ATAQUES | F63: 0 | G63: 0 | H63: 0 | J63: Soma de CANCELAMENTO-ATAQUES | K63: 1 | L63: 1 | M63: 1 | O63: Soma de CANCELAMENTO-ATAQUES | P63: 0 | Q63: 0 | R63: 0 | T63: Soma de CANCELAMENTO-ATAQUES | U63: 0 | V63: 0 | W63: 0 | Y63: Soma de CANCELAMENTO-ATAQUES | Z63: 0 | AA63: 0 | AB63: 0
A64: Contagem de ESPAÇO | E64: Soma de COUNTER-CANCELAMENTO-ATAQUES | F64: 0 | G64: 0 | H64: 0 | J64: Soma de COUNTER-CANCELAMENTO-ATAQUES | K64: 0 | L64: 0 | M64: 0 | O64: Soma de COUNTER-CANCELAMENTO-ATAQUES | P64: 0 | Q64: 0 | R64: 0 | T64: Soma de COUNTER-CANCELAMENTO-ATAQUES | U64: 0 | V64: 0 | W64: 0 | Y64: Soma de COUNTER-CANCELAMENTO-ATAQUES | Z64: 0 | AA64: 0 | AB64: 0
A65: Contagem de ESPAÇO2
A66: Contagem de ESPAÇO3
A67: Contagem de ESPAÇO4
A68: Soma de CURTO-ALCANCE-5-SEC-DANO-TOTAL-1-SUPER | B68: 8488 | C68: 8488
A69: Soma de MEDIO-ALCANCE-5-SEC-DANO-TOTAL-1-SUPER | B69: 7488 | C69: 7488
A70: Soma de LONGO-ALCANCE-5-SEC-DANO-TOTAL-1-SUPER | B70: 6488 | C70: 6488
A71: Soma de MT-LONGO-ALCANCE-5-SEC-DANO-TOTAL-1-SUPER | B71: 5488 | C71: 5488
A72: Soma de CURTO-ALCANCE-5-SEC-DANO-MEDIO | B72: 3118.2222 | C72: 3118.2222
A73: Soma de MEDIO-ALCANCE-5-SEC-DANO-MEDIO | B73: 4297.0667 | C73: 4297.0667
A74: Soma de LONGO-ALCANCE-5-SEC-DANO-MEDIO | B74: 1496 | C74: 1496
A75: Soma de MT-LONGO-ALCANCE-5-SEC-DANO-MEDIO | B75: 1090.4444 | C75: 1090.4444
A76: Soma de CURTO-ALCANCE-DANO-RESISTENCIA | B76: 2672.7619 | C76: 2672.7619
A77: Soma de MEDIO-ALCANCE-DANO-RESISTENCIA | B77: 3683.2 | C77: 3683.2
A78: Soma de LONGO-ALCANCE-DANO-RESISTENCIA | B78: 1282.2857 | C78: 1282.2857
A79: Soma de MT-LONGO-ALCANCE-DANO-RESISTENCIA | B79: 1908.2778 | C79: 1908.2778
... A90: Soma de Punição-Agrupamento | B90: 1.1111111 | C90: 1.1111111

Sheet BRAWLERS OFICIAL
M1: APROX | T1: APROX
B2: ID | C2: name | D2: _necessary_projectiles_to_charge_super | E2: _necessary_supers_to_charge_hipercharge | F2: _projectile_damage | G2: _shots_per_five_seconds | H2: _average_projectiles_per_shot | I2: _projectiles_per_shot_in_short_range | J2: _projectiles_per_shot_in_medium_range | K2: _projectiles_per_shot_in_long_range | L2: _projectiles_per_shot_in_very_long_range | M2: _shotting_time | N2: _auto_charge_super | O2: super_damage_in_short_range | P2: super_damage_in_medium_range | Q2: super_damage_in_long_range | R2: super_damage_in_very_long_range | S2: average_super_damage | T2: _super_time | U2: ocasional_damage | V2: _durability | W2: _attack_distance | X2: retreat_button | Y2: wide_attack | Z2: _indirect_damage_efficiency | AA2: area_denial | AB2: enemy_position_manipulation | AC2: water_walking | AD2: counter_water_walking | AE2: wall_break_efficiency | AF2: grass_break_efficiency | AG2: cover_creation_efficiency | AH2: _movement_speed | AI2: _surprise_attack_power | AJ2: _surprise_attack | AK2: _frequency_of_pets_generation | AL2: _accumulation_of_pets | AM2: _deteriorability_of_pets | AN2: _pets_resistence | AO2: _pets_damage | AP2: _pets_range | AQ2: _pets_speed | AR2: _pets_proximity | AS2: _increased_damage_when_grouped | AT2: grass_vision | AU2: circumstantiality_of_overall_proficiency | AV2: heal_buffing | AW2: counter_heal_buffing | AX2: shield_buffing | AY2: damage_buffing | AZ2: counter_damage_buffing | BA2: speed_buffing | BB2: invisibility_buffing | BC2: positioning_buffing | BD2: poison_debuffing | BE2: counter_poison_debuffing | BF2: stun_debuffing | BG2: counter_stun_debuffing | BH2: slowness_debuffing | BI2: counter_slowness_debuffing | BJ2: attacks_canceling | BK2: counter_attacks_canceling | BL2: block_enemies | BM2: object_burst_damage_in_short_range | BN2: object_burst_damage_in_medium_range | BO2: object_burst_damage_in_long_range | BP2: object_burst_damage_in_very_long_range | BQ2: usual_burst_damage_in_short_range | BR2: usual_burst_damage_in_medium_range | BS2: usual_burst_damage_in_long_range | BT2: usual_burst_damage_in_very_long_range | BU2: ESPAÇO | BV2: balance_between_damage_and_durability_in_short_range | BW2: balance_between_damage_and_durability_in_medium_range | BX2: balance_between_damage_and_durability_in_long_range | BY2: balance_between_damage_and_durability_in_very_long_range | BZ2: ESPAÇO | CA2: surprise_attack_power_in_short_range | CB2: surprise_attack_power_in_medium_range | CC2: surprise_attack_power_in_long_range | CD2: surprise_attack_power_in_very_long_range | CE2: ESPAÇO | CF2: easy_approach | CG2: pressure | CH2: area_control | CI2: indirect_damage | CJ2: multiple_pets_generation | CK2: durable_pets_generation | CL2: groupment_punishment | CM2: ESPAÇO | CO2: primary_class | CP2: secondary_class
B3: 28 | C3: NANI | D3: 5 | E3: =17/D3 -> 3.4 | F3: 1600 | G3: =(2.5-((M3*2.5)/2)) -> 1.5 | H3: 3 | I3: 3 | J3: 2.5 | K3: 1.5 | L3: 1 | M3: =2.4 / 3 -> 0.8 | N3: =1-(1*(T3/2)) -> 0.95 | O3: 3600 | P3: 2700 | Q3: 1800 | R3: 1800 | S3: 3600 | T3: 0.1 | U3: 0 | V3: =5000/1400 -> 3.5714286 | W3: 10 | X3: =(5 + 2 + 3)/3 -> 3.3333333 | Y3: 2 | Z3: 1 | AA3: 0 | AB3: 1 | AC3: 0 | AD3: 6 | AE3: 1 | AF3: 1 | AG3: 0 | AH3: 5 | AI3: 0 | AJ3: =(BH3/5+1)*AI3 -> 0 | AK3: 0 | AL3: 0 | AM3: 0 | AN3: 0 | AO3: 0 | AP3: 0 | AQ3: 0 | AR3: 0 | AS3: 0 | AT3: 0 | AU3: 0 | AV3: 0 | AW3: 0 | AX3: 0 | AY3: 0 | AZ3: 0 | BA3: 0 | BB3: 0 | BC3: 0 | BD3: 0 | BE3: 0 | BF3: 1 | BG3: 0 | BH3: 0 | BI3: 0 | BJ3: 1 | BK3: 3 | BL3: 0 | BM3: =(((H3*G3*F3)+O3+(U3/4))/1500)+((AO3*(AP3/3))/5) -> 7.2 | BN3: =(((H3*G3*F3)+P3+(U3/4))/1500)+((AO3*(AP3/5))/5) -> 6.6 | BO3: =((((H3*(W3/7))*G3*F3)+Q3+(U3/4))/1500)+((AO3*(AP3/7))/5) -> 8.0571429 | BP3: =((((H3*(W3/9))*G3*F3)+R3+(U3/4))/1200)+((AO3*(AP3/9))/5) -> 8.1666667 | BQ3: =(((I3*G3*F3)+(((G3*I3+N3)/D3)*O3))/(1.25-((I3-H3)/4))+(U3/4))/1300 -> 6.8455385 | BR3: =(((J3*G3*F3)+(((G3*J3+N3)/D3)*(P3)))/(1.25-((J3-H3)/4))+(U3/4))/800 -> 7.7618182 | BS3: =(((K3*G3*F3)+(((G3*K3+N3)/D3)*(Q3)))/(1.25-((K3-H3)/4))+(U3/4))/400 -> 7.3107692 | BT3: =(((L3*G3*F3)+(((G3*L3+N3)/D3)*(R3)))/(1.25-((L3-H3)/4))+(U3/4))/250 -> 7.5017143 | BV3: =((BQ3/2)*V3)/2.5 -> 4.8896703 | BW3: =((BR3)*(V3/2))/3.5 -> 3.9601113 | BX3: =((BS3*1.5)*(V3/3))/3 -> 4.3516484 | BY3: =((BT3*2)*(W3/4))/5 -> 7.5017143 | CA3: =(AJ3*BV3)/3 -> 0 | CB3: =(AJ3*BW3)/2.7 -> 0 | CC3: =(AJ3*BX3)/2.5 -> 0 | CD3: =(AJ3*BY3)/1.9 -> 0 | CF3: =SUM(AJ3*4, AH3*2, V3*2, BA3*2)/6 -> 2.8571429 | CG3: =SUM(AVERAGE(Y3, (AVERAGE(BV3, BW3))/1.5)*4, V3*4, W3*2, CF3*2)/9 -> 5.5444283 | CH3: =SUM(AA3*5, (AVERAGE(BV3, BW3, BX3, BY3)/2)*2, BA3*2)/6 -> 0.86263101 | CI3: =IF(Z3<6, (Z3/2)*S3/2000, IF(Z3<7, (Z3/2)*(AVERAGE(BQ3, BR3, BS3, BT3)/2.5), (Z3/2)*(AVERAGE(BQ3, BR3, BS3, BT3)/2.5)+(S3/2000))) -> 0.9 | CJ3: =SUM(AK3*4, AN3*2/(AM3+1), AL3*4)/7.5 -> 0 | CK3: =SUM(AN3*3, AO3*2, AP3*2, AQ3*2, AK3*3)/8 -> 0 | CL3: =(SUM(Y3*2, BH3*1, AS3*3)/4.5)*1.5 -> 1.3333333 | CO3: C | CP3: C
B4: 44 | C4: ANGELO | D4: 3 | E4: =9/D4 -> 3 | F4: 4000 | G4: =1.2 -> 1.2 | H4: 1 | I4: 1 | J4: 0.7 | K4: 0.5 | L4: 0.4 | M4: =12 / 3 -> 4 | N4: =0-(0*(T4/2)) -> 0 | O4: 2000 | P4: 2000 | Q4: 2000 | R4: 2000 | S4: 2000 | T4: 0.1 | U4: 0 | V4: =6200/1400 -> 4.4285714 | W4: 9 | X4: 0 | Y4: 0 | Z4: 0 | AA4: =(3 + 2 + 8 + 0)/4 -> 3.25 | AB4: 0 | AC4: 1 | AD4: 7 | AE4: 0 | AF4: 0 | AG4: 0 | AH4: 9 | AI4: 0 | AJ4: =(BH4/5+1)*AI4 -> 0 | AK4: 0 | AL4: 0 | AM4: 0 | AN4: 0 | AO4: 0 | AP4: 0 | AQ4: 0 | AR4: 0 | AS4: 0 | AT4: 0 | AU4: 2.5 | AV4: 0 | AW4: 0 | AX4: 0 | AY4: 0 | AZ4: 0 | BA4: 0 | BB4: 0 | BC4: 0 | BD4: 4 | BE4: 0 | BF4: 0 | BG4: 0 | BH4: 0 | BI4: 0 | BJ4: 0 | BK4: 5 | BL4: 0 | BM4: =(((H4*G4*F4)+O4+(U4/4))/1500)+((AO4*(AP4/3))/5) -> 4.5333333 | BN4: =(((H4*G4*F4)+P4+(U4/4))/1500)+((AO4*(AP4/5))/5) -> 4.5333333 | BO4: =((((H4*(W4/7))*G4*F4)+Q4+(U4/4))/1500)+((AO4*(AP4/7))/5) -> 5.447619 | BP4: =((((H4*(W4/9))*G4*F4)+R4+(U4/4))/1200)+((AO4*(AP4/9))/5) -> 5.6666667 | BQ4: =(((I4*G4*F4)+(((G4*I4+N4)/D4)*O4))/(1.25-((I4-H4)/4))+(U4/4))/1300 -> 3.4461538 | BR4: =(((J4*G4*F4)+(((G4*J4+N4)/D4)*(P4)))/(1.25-((J4-H4)/4))+(U4/4))/800 -> 3.6981132 | BS4: =(((K4*G4*F4)+(((G4*K4+N4)/D4)*(Q4)))/(1.25-((K4-H4)/4))+(U4/4))/400 -> 5.0909091 | BT4: =(((L4*G4*F4)+(((G4*L4+N4)/D4)*(R4)))/(1.25-((L4-H4)/4))+(U4/4))/250 -> 6.4 | BV4: =((BQ4/2)*V4)/2.5 -> 3.0523077 | BW4: =((BR4)*(V4/2))/3.5 -> 2.3396226 | BX4: =((BS4*1.5)*(V4/3))/3 -> 3.7575758 | BY4: =((BT4*2)*(W4/4))/5 -> 5.76 | CA4: =(AJ4*BV4)/3 -> 0 | CB4: =(AJ4*BW4)/2.7 -> 0 | CC4: =(AJ4*BX4)/2.5 -> 0 | CD4: =(AJ4*BY4)/1.9 -> 0 | CF4: =SUM(AJ4*4, AH4*2, V4*2, BA4*2)/6 -> 4.4761905 | CG4: =SUM(AVERAGE(Y4, (AVERAGE(BV4, BW4))/1.5)*4, V4*4, W4*2, CF4*2)/9 -> 5.3623652 | CH4: =SUM(AA4*5, (AVERAGE(BV4, BW4, BX4, BY4)/2)*2, BA4*2)/6 -> 3.3295628 | CI4: =IF(Z4<6, (Z4/2)*S4/2000, IF(Z4<7, (Z4/2)*(AVERAGE(BQ4, BR4, BS4, BT4)/2.5), (Z4/2)*(AVERAGE(BQ4, BR4, BS4, BT4)/2.5)+(S4/2000))) -> 0 | CJ4: =SUM(AK4*4, AN4*2/(AM4+1), AL4*4)/7.5 -> 0 | CK4: =SUM(AN4*3, AO4*2, AP4*2, AQ4*2, AK4*3)/8 -> 0 | CL4: =(SUM(Y4*2, BH4*1, AS4*3)/4.5)*1.5 -> 0 | CO4: C | CP4: C
B5: 14 | C5: RICO | D5: 16 | E5: =36/D5 -> 2.25 | F5: 600 | G5: =(3.3-((M5*3.3)/2)) -> 1.87 | H5: 5 | I5: 5 | J5: 4 | K5: 2 | L5: 0.8 | M5: =2.6 / 3 -> 0.86666667 | N5: =16-(16*(T5/2)) -> 8 | O5: 8640 | P5: 6480 | Q5: 4320 | R5: 2160 | S5: 8640 | T5: 1 | U5: 0 | V5: =6000/1400 -> 4.2857143 | W5: 8 | X5: 0 | Y5: 3 | Z5: 0 | AA5: 0 | AB5: 0 | AC5: 0 | AD5: 6 | AE5: 0 | AF5: 0 | AG5: 0 | AH5: 5 | AI5: 0 | AJ5: =(BH5/5+1)*AI5 -> 0 | AK5: 0 | AL5: 0 | AM5: 0 | AN5: 0 | AO5: 0 | AP5: 0 | AQ5: 0 | AR5: 0 | AS5: 3 | AT5: 0 | AU5: 0 | AV5: 0 | AW5: 0 | AX5: 0 | AY5: 0 | AZ5: 0 | BA5: 0 | BB5: 0 | BC5: 0 | BD5: 0 | BE5: 0 | BF5: 0 | BG5: 0 | BH5: 0 | BI5: 0 | BJ5: 0 | BK5: 6 | BL5: 0 | BM5: =(((H5*G5*F5)+O5+(U5/4))/1500)+((AO5*(AP5/3))/5) -> 9.5 | BN5: =(((H5*G5*F5)+P5+(U5/4))/1500)+((AO5*(AP5/5))/5) -> 8.06 | BO5: =((((H5*(W5/7))*G5*F5)+Q5+(U5/4))/1500)+((AO5*(AP5/7))/5) -> 7.1542857 | BP5: =((((H5*(W5/9))*G5*F5)+R5+(U5/4))/1200)+((AO5*(AP5/9))/5) -> 5.9555556 | BQ5: =(((I5*G5*F5)+(((G5*I5+N5)/D5)*O5))/(1.25-((I5-H5)/4))+(U5/4))/1300 -> 9.2178462 | BR5: =(((J5*G5*F5)+(((G5*J5+N5)/D5)*(P5)))/(1.25-((J5-H5)/4))+(U5/4))/800 -> 8.9645 | BS5: =(((K5*G5*F5)+(((G5*K5+N5)/D5)*(Q5)))/(1.25-((K5-H5)/4))+(U5/4))/400 -> 6.76725 | BT5: =(((L5*G5*F5)+(((G5*L5+N5)/D5)*(R5)))/(1.25-((L5-H5)/4))+(U5/4))/250 -> 3.7905391 | BV5: =((BQ5/2)*V5)/2.5 -> 7.901011 | BW5: =((BR5)*(V5/2))/3.5 -> 5.4884694 | BX5: =((BS5*1.5)*(V5/3))/3 -> 4.83375 | BY5: =((BT5*2)*(W5/4))/5 -> 3.0324313 | CA5: =(AJ5*BV5)/3 -> 0 | CB5: =(AJ5*BW5)/2.7 -> 0 | CC5: =(AJ5*BX5)/2.5 -> 0 | CD5: =(AJ5*BY5)/1.9 -> 0 | CF5: =SUM(AJ5*4, AH5*2, V5*2, BA5*2)/6 -> 3.0952381 | CG5: =SUM(AVERAGE(Y5, (AVERAGE(BV5, BW5))/1.5)*4, V5*4, W5*2, CF5*2)/9 -> 6.0288504 | CH5: =SUM(AA5*5, (AVERAGE(BV5, BW5, BX5, BY5)/2)*2, BA5*2)/6 -> 0.88565257 | CI5: =IF(Z5<6, (Z5/2)*S5/2000, IF(Z5<7, (Z5/2)*(AVERAGE(BQ5, BR5, BS5, BT5)/2.5), (Z5/2)*(AVERAGE(BQ5, BR5, BS5, BT5)/2.5)+(S5/2000))) -> 0 | CJ5: =SUM(AK5*4, AN5*2/(AM5+1), AL5*4)/7.5 -> 0 | CK5: =SUM(AN5*3, AO5*2, AP5*2, AQ5*2, AK5*3)/8 -> 0 | CL5: =(SUM(Y5*2, BH5*1, AS5*3)/4.5)*1.5 -> 5 | CO5: C | CP5: C
B6: 86 | C6: SPIKE | D6: 8 | E6: =26/D6 -> 3.25 | F6: 980 | G6: =(2.15-((M6*2.15)/2)) -> 1.5408333 | H6: 3 | I6: 4 | J6: 2 | K6: 1.5 | L6: 0.5 | M6: =1.7 / 3 -> 0.56666667 | N6: =2.5-(2.5*(T6/2)) -> 2.125 | O6: 4000 | P6: 3200 | Q6: 1600 | R6: 800 | S6: 4000 | T6: 0.3 | U6: 0 | V6: =6000/1400 -> 4.2857143 | W6: 7 | X6: 0 | Y6: 4 | Z6: 3 | AA6: =(9 + 4 + 5 + 7)/4 -> 6.25 | AB6: 0 | AC6: 0 | AD6: 6 | AE6: 0 | AF6: 0 | AG6: 0 | AH6: 5 | AI6: 0 | AJ6: =(BH6/5+1)*AI6 -> 0 | AK6: 0 | AL6: 0 | AM6: 0 | AN6: 0 | AO6: 0 | AP6: 0 | AQ6: 0 | AR6: 0 | AS6: 4 | AT6: 0 | AU6: 0 | AV6: 0 | AW6: 0 | AX6: 0 | AY6: 0 | AZ6: 0 | BA6: 0 | BB6: 0 | BC6: 0 | BD6: 0 | BE6: 0 | BF6: 0 | BG6: 0 | BH6: =(5 + 5 + 10)/3 -> 6.6666667 | BI6: 0 | BJ6: 0 | BK6: 7 | BL6: 0 | BM6: =(((H6*G6*F6)+O6+(U6/4))/1500)+((AO6*(AP6/3))/5) -> 5.6867 | BN6: =(((H6*G6*F6)+P6+(U6/4))/1500)+((AO6*(AP6/5))/5) -> 5.1533667 | BO6: =((((H6*(W6/7))*G6*F6)+Q6+(U6/4))/1500)+((AO6*(AP6/7))/5) -> 4.0867 | BP6: =((((H6*(W6/9))*G6*F6)+R6+(U6/4))/1200)+((AO6*(AP6/9))/5) -> 3.6028102 | BQ6: =(((I6*G6*F6)+(((G6*I6+N6)/D6)*O6))/(1.25-((I6-H6)/4))+(U6/4))/1300 -> 7.8340256 | BR6: =(((J6*G6*F6)+(((G6*J6+N6)/D6)*(P6)))/(1.25-((J6-H6)/4))+(U6/4))/800 -> 4.25225 | BS6: =(((K6*G6*F6)+(((G6*K6+N6)/D6)*(Q6)))/(1.25-((K6-H6)/4))+(U6/4))/400 -> 4.8496538 | BT6: =(((L6*G6*F6)+(((G6*L6+N6)/D6)*(R6)))/(1.25-((L6-H6)/4))+(U6/4))/250 -> 2.2283733 | BV6: =((BQ6/2)*V6)/2.5 -> 6.7148791 | BW6: =((BR6)*(V6/2))/3.5 -> 2.6034184 | BX6: =((BS6*1.5)*(V6/3))/3 -> 3.4640385 | BY6: =((BT6*2)*(W6/4))/5 -> 1.5598613 | CA6: =(AJ6*BV6)/3 -> 0 | CB6: =(AJ6*BW6)/2.7 -> 0 | CC6: =(AJ6*BX6)/2.5 -> 0 | CD6: =(AJ6*BY6)/1.9 -> 0 | CF6: =SUM(AJ6*4, AH6*2, V6*2, BA6*2)/6 -> 3.0952381 | CG6: =SUM(AVERAGE(Y6, (AVERAGE(BV6, BW6))/1.5)*4, V6*4, W6*2, CF6*2)/9 -> 5.7272813 | CH6: =SUM(AA6*5, (AVERAGE(BV6, BW6, BX6, BY6)/2)*2, BA6*2)/6 -> 5.8059249 | CI6: =IF(Z6<6, (Z6/2)*S6/2000, IF(Z6<7, (Z6/2)*(AVERAGE(BQ6, BR6, BS6, BT6)/2.5), (Z6/2)*(AVERAGE(BQ6, BR6, BS6, BT6)/2.5)+(S6/2000))) -> 3 | CJ6: =SUM(AK6*4, AN6*2/(AM6+1), AL6*4)/7.5 -> 0 | CK6: =SUM(AN6*3, AO6*2, AP6*2, AQ6*2, AK6*3)/8 -> 0 | CL6: =(SUM(Y6*2, BH6*1, AS6*3)/4.5)*1.5 -> 8.8888889 | CO6: C | CP6: C
B7: 88 | C7: LEON | D7: 9 | E7: =31/D7 -> 3.4444444 | F7: 960 | G7: =(2.5-((M7*2.5)/2)) -> 1.6666667 | H7: 4 | I7: 4 | J7: 2.5 | K7: 1.2 | L7: 0.5 | M7: =2 / 3 -> 0.66666667 | N7: =0-(0*(T7/2)) -> 0 | O7: 0 | P7: 0 | Q7: 0 | R7: 0 | S7: 0 | T7: 0.1 | U7: 0 | V7: =6600/1400 -> 4.7142857 | W7: 7 | X7: =(5 + 8 + 5)/3 -> 6 | Y7: 3 | Z7: 0 | AA7: 0 | AB7: 0 | AC7: 0 | AD7: 6 | AE7: 0 | AF7: 0 | AG7: 0 | AH7: 9 | AI7: 7 | AJ7: =(BH7/5+1)*AI7 -> 7 | AK7: 0 | AL7: 0 | AM7: 0 | AN7: 0 | AO7: 0 | AP7: 0 | AQ7: 0 | AR7: 0 | AS7: 0 | AT7: 0 | AU7: 0 | AV7: 0 | AW7: 0 | AX7: 0 | AY7: 0 | AZ7: 0 | BA7: 0 | BB7: 0 | BC7: 0 | BD7: 0 | BE7: 0 | BF7: 0 | BG7: 0 | BH7: 0 | BI7: 0 | BJ7: 0 | BK7: 6 | BL7: 0 | BM7: =(((H7*G7*F7)+O7+(U7/4))/1500)+((AO7*(AP7/3))/5) -> 4.2666667 | BN7: =(((H7*G7*F7)+P7+(U7/4))/1500)+((AO7*(AP7/5))/5) -> 4.2666667 | BO7: =((((H7*(W7/7))*G7*F7)+Q7+(U7/4))/1500)+((AO7*(AP7/7))/5) -> 4.2666667 | BP7: =((((H7*(W7/9))*G7*F7)+R7+(U7/4))/1200)+((AO7*(AP7/9))/5) -> 4.1481481 | BQ7: =(((I7*G7*F7)+(((G7*I7+N7)/D7)*O7))/(1.25-((I7-H7)/4))+(U7/4))/1300 -> 3.9384615 | BR7: =(((J7*G7*F7)+(((G7*J7+N7)/D7)*(P7)))/(1.25-((J7-H7)/4))+(U7/4))/800 -> 3.0769231 | BS7: =(((K7*G7*F7)+(((G7*K7+N7)/D7)*(Q7)))/(1.25-((K7-H7)/4))+(U7/4))/400 -> 2.4615385 | BT7: =(((L7*G7*F7)+(((G7*L7+N7)/D7)*(R7)))/(1.25-((L7-H7)/4))+(U7/4))/250 -> 1.5058824 | BV7: =((BQ7/2)*V7)/2.5 -> 3.7134066 | BW7: =((BR7)*(V7/2))/3.5 -> 2.0722135 | BX7: =((BS7*1.5)*(V7/3))/3 -> 1.9340659 | BY7: =((BT7*2)*(W7/4))/5 -> 1.0541176 | CA7: =(AJ7*BV7)/3 -> 8.6646154 | CB7: =(AJ7*BW7)/2.7 -> 5.3724054 | CC7: =(AJ7*BX7)/2.5 -> 5.4153846 | CD7: =(AJ7*BY7)/1.9 -> 3.8835913 | CF7: =SUM(AJ7*4, AH7*2, V7*2, BA7*2)/6 -> 9.2380952 | CG7: =SUM(AVERAGE(Y7, (AVERAGE(BV7, BW7))/1.5)*4, V7*4, W7*2, CF7*2)/9 -> 6.7989348 | CH7: =SUM(AA7*5, (AVERAGE(BV7, BW7, BX7, BY7)/2)*2, BA7*2)/6 -> 0.36557515 | CI7: =IF(Z7<6, (Z7/2)*S7/2000, IF(Z7<7, (Z7/2)*(AVERAGE(BQ7, BR7, BS7, BT7)/2.5), (Z7/2)*(AVERAGE(BQ7, BR7, BS7, BT7)/2.5)+(S7/2000))) -> 0 | CJ7: =SUM(AK7*4, AN7*2/(AM7+1), AL7*4)/7.5 -> 0 | CK7: =SUM(AN7*3, AO7*2, AP7*2, AQ7*2, AK7*3)/8 -> 0 | CL7: =(SUM(Y7*2, BH7*1, AS7*3)/4.5)*1.5 -> 2 | CO7: C | CP7: C
B8: 33 | C8: GALE | D8: 15 | E8: =60/D8 -> 4 | F8: 600 | G8: =(3.3-((M8*3.3)/2)) -> 2.42 | H8: 4 | I8: 4 | J8: 4 | K8: 2 | L8: 0 | M8: =1.6 / 3 -> 0.53333333 | N8: =3-(3*(T8/2)) -> 2.7 | O8: 1200 | P8: 1200 | Q8: 1200 | R8: 1200 | S8: 1200 | T8: 0.2 | U8: 0 | V8: =8000/1400 -> 5.7142857 | W8: 7 | X8: =(5 + 7 + 4)/3 -> 5.3333333 | Y8: =(4 + 6)/2 -> 5 | Z8: 3 | AA8: 0 | AB8: 10 | AC8: 0 | AD8: 6 | AE8: 0 | AF8: 0 | AG8: 0 | AH8: 5 | AI8: 0 | AJ8: =(BH8/5+1)*AI8 -> 0 | AK8: 0 | AL8: 0 | AM8: 0 | AN8: 0 | AO8: 0 | AP8: 0 | AQ8: 0 | AR8: 0 | AS8: 1 | AT8: 0 | AU8: 0 | AV8: 0 | AW8: 0 | AX8: 0 | AY8: 0 | AZ8: 0 | BA8: 0 | BB8: 0 | BC8: 0 | BD8: 0 | BE8: 0 | BF8: 1 | BG8: 0 | BH8: 0 | BI8: 0 | BJ8: 10 | BK8: 7 | BL8: 0 | BM8: =(((H8*G8*F8)+O8+(U8/4))/1500)+((AO8*(AP8/3))/5) -> 4.672 | BN8: =(((H8*G8*F8)+P8+(U8/4))/1500)+((AO8*(AP8/5))/5) -> 4.672 | BO8: =((((H8*(W8/7))*G8*F8)+Q8+(U8/4))/1500)+((AO8*(AP8/7))/5) -> 4.672 | BP8: =((((H8*(W8/9))*G8*F8)+R8+(U8/4))/1200)+((AO8*(AP8/9))/5) -> 4.7644444 | BQ8: =(((I8*G8*F8)+(((G8*I8+N8)/D8)*O8))/(1.25-((I8-H8)/4))+(U8/4))/1300 -> 4.1836308 | BR8: =(((J8*G8*F8)+(((G8*J8+N8)/D8)*(P8)))/(1.25-((J8-H8)/4))+(U8/4))/800 -> 6.7984 | BS8: =(((K8*G8*F8)+(((G8*K8+N8)/D8)*(Q8)))/(1.25-((K8-H8)/4))+(U8/4))/400 -> 5.0102857 | BT8: =(((L8*G8*F8)+(((G8*L8+N8)/D8)*(R8)))/(1.25-((L8-H8)/4))+(U8/4))/250 -> 0.384 | BV8: =((BQ8/2)*V8)/2.5 -> 4.7812923 | BW8: =((BR8)*(V8/2))/3.5 -> 5.5497143 | BX8: =((BS8*1.5)*(V8/3))/3 -> 4.7717007 | BY8: =((BT8*2)*(W8/4))/5 -> 0.2688 | CA8: =(AJ8*BV8)/3 -> 0 | CB8: =(AJ8*BW8)/2.7 -> 0 | CC8: =(AJ8*BX8)/2.5 -> 0 | CD8: =(AJ8*BY8)/1.9 -> 0 | CF8: =SUM(AJ8*4, AH8*2, V8*2, BA8*2)/6 -> 3.5714286 | CG8: =SUM(AVERAGE(Y8, (AVERAGE(BV8, BW8))/1.5)*4, V8*4, W8*2, CF8*2)/9 -> 6.7652597 | CH8: =SUM(AA8*5, (AVERAGE(BV8, BW8, BX8, BY8)/2)*2, BA8*2)/6 -> 0.64047947 | CI8: =IF(Z8<6, (Z8/2)*S8/2000, IF(Z8<7, (Z8/2)*(AVERAGE(BQ8, BR8, BS8, BT8)/2.5), (Z8/2)*(AVERAGE(BQ8, BR8, BS8, BT8)/2.5)+(S8/2000))) -> 0.9 | CJ8: =SUM(AK8*4, AN8*2/(AM8+1), AL8*4)/7.5 -> 0 | CK8: =SUM(AN8*3, AO8*2, AP8*2, AQ8*2, AK8*3)/8 -> 0 | CL8: =(SUM(Y8*2, BH8*1, AS8*3)/4.5)*1.5 -> 4.3333333 | CO8: C | CP8: C
B9: 1 | C9: SHELLY | D9: 10 | E9: =34/D9 -> 3.4 | F9: 600 | G9: =(2.5-((M9*2.5)/2)) -> 1.8333333 | H9: 5 | I9: 5 | J9: 3 | K9: 1.5 | L9: 0 | M9: =1.6 / 3 -> 0.53333333 | N9: =2-(2*(T9/2)) -> 1.8 | O9: 5760 | P9: 3200 | Q9: 1920 | R9: 0 | S9: 5760 | T9: 0.2 | U9: 0 | V9: =7800/1400 -> 5.5714286 | W9: 6 | X9: =(6 + 5 + 3)/3 -> 4.6666667 | Y9: 4 | Z9: 0 | AA9: 0 | AB9: 3 | AC9: 0 | AD9: 5 | AE9: 5 | AF9: 5 | AG9: 0 | AH9: 7 | AI9: 0 | AJ9: =(BH9/5+1)*AI9 -> 0 | AK9: 0 | AL9: 0 | AM9: 0 | AN9: 0 | AO9: 0 | AP9: 0 | AQ9: 0 | AR9: 0 | AS9: 2 | AT9: 0 | AU9: 0 | AV9: 0 | AW9: 0 | AX9: 0 | AY9: 0 | AZ9: 0 | BA9: 0 | BB9: 0 | BC9: 0 | BD9: 0 | BE9: 0 | BF9: 2 | BG9: 0 | BH9: 0 | BI9: 0 | BJ9: 3 | BK9: 7 | BL9: 0 | BM9: =(((H9*G9*F9)+O9+(U9/4))/1500)+((AO9*(AP9/3))/5) -> 7.5066667 | BN9: =(((H9*G9*F9)+P9+(U9/4))/1500)+((AO9*(AP9/5))/5) -> 5.8 | BO9: =((((H9*(W9/7))*G9*F9)+Q9+(U9/4))/1500)+((AO9*(AP9/7))/5) -> 4.4228571 | BP9: =((((H9*(W9/9))*G9*F9)+R9+(U9/4))/1200)+((AO9*(AP9/9))/5) -> 3.0555556 | BQ9: =(((I9*G9*F9)+(((G9*I9+N9)/D9)*O9))/(1.25-((I9-H9)/4))+(U9/4))/1300 -> 7.2718769 | BR9: =(((J9*G9*F9)+(((G9*J9+N9)/D9)*(P9)))/(1.25-((J9-H9)/4))+(U9/4))/800 -> 4.0257143 | BS9: =(((K9*G9*F9)+(((G9*K9+N9)/D9)*(Q9)))/(1.25-((K9-H9)/4))+(U9/4))/400 -> 2.9689412 | BT9: =(((L9*G9*F9)+(((G9*L9+N9)/D9)*(R9)))/(1.25-((L9-H9)/4))+(U9/4))/250 -> 0 | BV9: =((BQ9/2)*V9)/2.5 -> 8.1029486 | BW9: =((BR9)*(V9/2))/3.5 -> 3.2041399 | BX9: =((BS9*1.5)*(V9/3))/3 -> 2.7568739 | BY9: =((BT9*2)*(W9/4))/5 -> 0 | CA9: =(AJ9*BV9)/3 -> 0 | CB9: =(AJ9*BW9)/2.7 -> 0 | CC9: =(AJ9*BX9)/2.5 -> 0 | CD9: =(AJ9*BY9)/1.9 -> 0 | CF9: =SUM(AJ9*4, AH9*2, V9*2, BA9*2)/6 -> 4.1904762 | CG9: =SUM(AVERAGE(Y9, (AVERAGE(BV9, BW9))/1.5)*4, V9*4, W9*2, CF9*2)/9 -> 6.4671917 | CH9: =SUM(AA9*5, (AVERAGE(BV9, BW9, BX9, BY9)/2)*2, BA9*2)/6 -> 0.58599844 | CI9: =IF(Z9<6, (Z9/2)*S9/2000, IF(Z9<7, (Z9/2)*(AVERAGE(BQ9, BR9, BS9, BT9)/2.5), (Z9/2)*(AVERAGE(BQ9, BR9, BS9, BT9)/2.5)+(S9/2000))) -> 0 | CJ9: =SUM(AK9*4, AN9*2/(AM9+1), AL9*4)/7.5 -> 0 | CK9: =SUM(AN9*3, AO9*2, AP9*2, AQ9*2, AK9*3)/8 -> 0 | CL9: =(SUM(Y9*2, BH9*1, AS9*3)/4.5)*1.5 -> 4.6666667 | CO9: C | CP9: C
B10: 8 | C10: POCO | D10: 4 | E10: =10/D10 -> 2.5 | F10: 1520 | G10: =(2.5-((M10*2.5)/2)) -> 1.8333333 | H10: 1 | I10: 1 | J10: 1 | K10: 0.5 | L10: 0 | M10: =1.6 / 3 -> 0.53333333 | N10: =0-(0*(T10/2)) -> 0 | O10: 0 | P10: 0 | Q10: 0 | R10: 0 | S10: 0 | T10: 0.2 | U10: 0 | V10: =8000/1400+(AV10/3.5) -> 8 | W10: 6 | X10: 0 | Y10: 7 | Z10: 0 | AA10: 0 | AB10: 0 | AC10: 0 | AD10: 6 | AE10: 0 | AF10: 0 | AG10: 0 | AH10: 5 | AI10: 0 | AJ10: =(BH10/5+1)*AI10 -> 0 | AK10: 0 | AL10: 0 | AM10: 0 | AN10: 0 | AO10: 0 | AP10: 0 | AQ10: 0 | AR10: 0 | AS10: 0 | AT10: 0 | AU10: 0 | AV10: =(6 + 9 + 9)/3 -> 8 | AW10: 0 | AX10: 0 | AY10: 0 | AZ10: 0 | BA10: 0 | BB10: 0 | BC10: 0 | BD10: 0 | BE10: 0 | BF10: 0 | BG10: 0 | BH10: 0 | BI10: 0 | BJ10: 0 | BK10: 7 | BL10: 0 | BM10: =(((H10*G10*F10)+O10+(U10/4))/1500)+((AO10*(AP10/3))/5) -> 1.8577778 | BN10: =(((H10*G10*F10)+P10+(U10/4))/1500)+((AO10*(AP10/5))/5) -> 1.8577778 | BO10: =((((H10*(W10/7))*G10*F10)+Q10+(U10/4))/1500)+((AO10*(AP10/7))/5) -> 1.592381 | BP10: =((((H10*(W10/9))*G10*F10)+R10+(U10/4))/1200)+((AO10*(AP10/9))/5) -> 1.5481481 | BQ10: =(((I10*G10*F10)+(((G10*I10+N10)/D10)*O10))/(1.25-((I10-H10)/4))+(U10/4))/1300 -> 1.7148718 | BR10: =(((J10*G10*F10)+(((G10*J10+N10)/D10)*(P10)))/(1.25-((J10-H10)/4))+(U10/4))/800 -> 2.7866667 | BS10: =(((K10*G10*F10)+(((G10*K10+N10)/D10)*(Q10)))/(1.25-((K10-H10)/4))+(U10/4))/400 -> 2.5333333 | BT10: =(((L10*G10*F10)+(((G10*L10+N10)/D10)*(R10)))/(1.25-((L10-H10)/4))+(U10/4))/250 -> 0 | BV10: =((BQ10/2)*V10)/2.5 -> 2.7437949 | BW10: =((BR10)*(V10/2))/3.5 -> 3.1847619 | BX10: =((BS10*1.5)*(V10/3))/3 -> 3.3777778 | BY10: =((BT10*2)*(W10/4))/5 -> 0 | CA10: =(AJ10*BV10)/3 -> 0 | CB10: =(AJ10*BW10)/2.7 -> 0 | CC10: =(AJ10*BX10)/2.5 -> 0 | CD10: =(AJ10*BY10)/1.9 -> 0 | CF10: =SUM(AJ10*4, AH10*2, V10*2, BA10*2)/6 -> 4.3333333 | CG10: =SUM(AVERAGE(Y10, (AVERAGE(BV10, BW10))/1.5)*4, V10*4, W10*2, CF10*2)/9 -> 7.8465598 | CH10: =SUM(AA10*5, (AVERAGE(BV10, BW10, BX10, BY10)/2)*2, BA10*2)/6 -> 0.38776394 | CI10: =IF(Z10<6, (Z10/2)*S10/2000, IF(Z10<7, (Z10/2)*(AVERAGE(BQ10, BR10, BS10, BT10)/2.5), (Z10/2)*(AVERAGE(BQ10, BR10, BS10, BT10)/2.5)+(S10/2000))) -> 0 | CJ10: =SUM(AK10*4, AN10*2/(AM10+1), AL10*4)/7.5 -> 0 | CK10: =SUM(AN10*3, AO10*2, AP10*2, AQ10*2, AK10*3)/8 -> 0 | CL10: =(SUM(Y10*2, BH10*1, AS10*3)/4.5)*1.5 -> 4.6666667 | CO10: C | CP10: C
B11: 45 | C11: BERRY | D11: 9 | E11: =21/D11 -> 2.3333333 | F11: 1320 | G11: =(1.65-((M11*1.65)/2)) -> 1.265 | H11: 6 | I11: 2 | J11: 1.5 | K11: 0.8 | L11: 0 | M11: =1.4 / 3 -> 0.46666667 | N11: =2.5-(2.5*(T11/2)) -> 2.375 | O11: 4360 | P11: 4360 | Q11: 2180 | R11: 0 | S11: 4360 | T11: 0.1 | U11: 0 | V11: =5200/1400+(AV11/3.5) -> 5.7142857 | W11: 5 | X11: =(6 + 7 + 6)/3 -> 6.3333333 | Y11: 1 | Z11: 6 | AA11: =(6 + 1 + 6 + 5)/4 -> 4.5 | AB11: 0 | AC11: 0 | AD11: 6 | AE11: 0 | AF11: 0 | AG11: 0 | AH11: 5 | AI11: 5 | AJ11: =(BH11/5+1)*AI11 -> 5 | AK11: 0 | AL11: 0 | AM11: 0 | AN11: 0 | AO11: 0 | AP11: 0 | AQ11: 0 | AR11: 0 | AS11: 1 | AT11: 0 | AU11: 0 | AV11: =(10 + 8 + 3)/3 -> 7 | AW11: 0 | AX11: 0 | AY11: 0 | AZ11: 0 | BA11: 0 | BB11: 0 | BC11: 0 | BD11: 0 | BE11: 0 | BF11: 0 | BG11: 0 | BH11: 0 | BI11: 0 | BJ11: 0 | BK11: 7 | BL11: 0 | BM11: =(((H11*G11*F11)+O11+(U11/4))/1500)+((AO11*(AP11/3))/5) -> 9.5858667 | BN11: =(((H11*G11*F11)+P11+(U11/4))/1500)+((AO11*(AP11/5))/5) -> 9.5858667 | BO11: =((((H11*(W11/7))*G11*F11)+Q11+(U11/4))/1500)+((AO11*(AP11/7))/5) -> 6.2241905 | BP11: =((((H11*(W11/9))*G11*F11)+R11+(U11/4))/1200)+((AO11*(AP11/9))/5) -> 4.6383333 | BQ11: =(((I11*G11*F11)+(((G11*I11+N11)/D11)*O11))/(1.25-((I11-H11)/4))+(U11/4))/1300 -> 1.9541197 | BR11: =(((J11*G11*F11)+(((G11*J11+N11)/D11)*(P11)))/(1.25-((J11-H11)/4))+(U11/4))/800 -> 2.4076257 | BS11: =(((K11*G11*F11)+(((G11*K11+N11)/D11)*(Q11)))/(1.25-((K11-H11)/4))+(U11/4))/400 -> 2.1139673 | BT11: =(((L11*G11*F11)+(((G11*L11+N11)/D11)*(R11)))/(1.25-((L11-H11)/4))+(U11/4))/250 -> 0 | BV11: =((BQ11/2)*V11)/2.5 -> 2.2332796 | BW11: =((BR11)*(V11/2))/3.5 -> 1.9654088 | BX11: =((BS11*1.5)*(V11/3))/3 -> 2.0133022 | BY11: =((BT11*2)*(W11/4))/5 -> 0 | CA11: =(AJ11*BV11)/3 -> 3.7221327 | CB11: =(AJ11*BW11)/2.7 -> 3.6396459 | CC11: =(AJ11*BX11)/2.5 -> 4.0266044 | CD11: =(AJ11*BY11)/1.9 -> 0 | CF11: =SUM(AJ11*4, AH11*2, V11*2, BA11*2)/6 -> 6.9047619 | CG11: =SUM(AVERAGE(Y11, (AVERAGE(BV11, BW11))/1.5)*4, V11*4, W11*2, CF11*2)/9 -> 5.7184214 | CH11: =SUM(AA11*5, (AVERAGE(BV11, BW11, BX11, BY11)/2)*2, BA11*2)/6 -> 4.0088329 | CI11: =IF(Z11<6, (Z11/2)*S11/2000, IF(Z11<7, (Z11/2)*(AVERAGE(BQ11, BR11, BS11, BT11)/2.5), (Z11/2)*(AVERAGE(BQ11, BR11, BS11, BT11)/2.5)+(S11/2000))) -> 1.9427138 | CJ11: =SUM(AK11*4, AN11*2/(AM11+1), AL11*4)/7.5 -> 0 | CK11: =SUM(AN11*3, AO11*2, AP11*2, AQ11*2, AK11*3)/8 -> 0 | CL11: =(SUM(Y11*2, BH11*1, AS11*3)/4.5)*1.5 -> 1.6666667 | CO11: C | CP11: C
B12: 25 | C12: FRANK | D12: 3 | E12: =10/D12 -> 3.3333333 | F12: 2320 | G12: =(3.3-((M12*3.3)/2)) -> 2.0075 | H12: 1 | I12: 1 | J12: 1 | K12: 0 | L12: 0 | M12: =AVERAGE(3, 1.7) / 3 -> 0.78333333 | N12: =1-(1*(T12/2)) -> 0.25 | O12: 2480 | P12: 2480 | Q12: 1240 | R12: 0 | S12: 2480 | T12: 1.5 | U12: 0 | V12: =13600/1400 -> 9.7142857 | W12: 5 | X12: 0 | Y12: 7 | Z12: 0 | AA12: 0 | AB12: 0 | AC12: 0 | AD12: 6 | AE12: 9 | AF12: 8 | AG12: 0 | AH12: 6 | AI12: 0 | AJ12: =(BH12/5+1)*AI12 -> 0 | AK12: 0 | AL12: 0 | AM12: 0 | AN12: 0 | AO12: 0 | AP12: 0 | AQ12: 0 | AR12: 0 | AS12: 2 | AT12: 0 | AU12: 0 | AV12: 0 | AW12: 0 | AX12: 0 | AY12: 0 | AZ12: 0 | BA12: 0 | BB12: 0 | BC12: 0 | BD12: 0 | BE12: 0 | BF12: 5 | BG12: 0 | BH12: 0 | BI12: 0 | BJ12: 0 | BK12: 1 | BL12: 0 | BM12: =(((H12*G12*F12)+O12+(U12/4))/1500)+((AO12*(AP12/3))/5) -> 4.7582667 | BN12: =(((H12*G12*F12)+P12+(U12/4))/1500)+((AO12*(AP12/5))/5) -> 4.7582667 | BO12: =((((H12*(W12/7))*G12*F12)+Q12+(U12/4))/1500)+((AO12*(AP12/7))/5) -> 3.0444762 | BP12: =((((H12*(W12/9))*G12*F12)+R12+(U12/4))/1200)+((AO12*(AP12/9))/5) -> 2.1562037 | BQ12: =(((I12*G12*F12)+(((G12*I12+N12)/D12)*O12))/(1.25-((I12-H12)/4))+(U12/4))/1300 -> 4.0145231 | BR12: =(((J12*G12*F12)+(((G12*J12+N12)/D12)*(P12)))/(1.25-((J12-H12)/4))+(U12/4))/800 -> 6.5236 | BS12: =(((K12*G12*F12)+(((G12*K12+N12)/D12)*(Q12)))/(1.25-((K12-H12)/4))+(U12/4))/400 -> 0.17222222 | BT12: =(((L12*G12*F12)+(((G12*L12+N12)/D12)*(R12)))/(1.25-((L12-H12)/4))+(U12/4))/250 -> 0 | BV12: =((BQ12/2)*V12)/2.5 -> 7.7996448 | BW12: =((BR12)*(V12/2))/3.5 -> 9.0531592 | BX12: =((BS12*1.5)*(V12/3))/3 -> 0.27883598 | BY12: =((BT12*2)*(W12/4))/5 -> 0 | CA12: =(AJ12*BV12)/3 -> 0 | CB12: =(AJ12*BW12)/2.7 -> 0 | CC12: =(AJ12*BX12)/2.5 -> 0 | CD12: =(AJ12*BY12)/1.9 -> 0 | CF12: =SUM(AJ12*4, AH12*2, V12*2, BA12*2)/6 -> 5.2380952 | CG12: =SUM(AVERAGE(Y12, (AVERAGE(BV12, BW12))/1.5)*4, V12*4, W12*2, CF12*2)/9 -> 9.396504 | CH12: =SUM(AA12*5, (AVERAGE(BV12, BW12, BX12, BY12)/2)*2, BA12*2)/6 -> 0.71381833 | CI12: =IF(Z12<6, (Z12/2)*S12/2000, IF(Z12<7, (Z12/2)*(AVERAGE(BQ12, BR12, BS12, BT12)/2.5), (Z12/2)*(AVERAGE(BQ12, BR12, BS12, BT12)/2.5)+(S12/2000))) -> 0 | CJ12: =SUM(AK12*4, AN12*2/(AM12+1), AL12*4)/7.5 -> 0 | CK12: =SUM(AN12*3, AO12*2, AP12*2, AQ12*2, AK12*3)/8 -> 0 | CL12: =(SUM(Y12*2, BH12*1, AS12*3)/4.5)*1.5 -> 6.6666667 | CO12: C | CP12: C
B13: 89 | C13: SANDY | D13: 6 | E13: =15/D13 -> 2.5 | F13: 1800 | G13: =(2.5-((M13*2.5)/2)) -> 1.8333333 | H13: 1 | I13: 1 | J13: 1 | K13: 0 | L13: 0 | M13: =1.6 / 3 -> 0.53333333 | N13: =0-(0*(T13/2)) -> 0 | O13: 0 | P13: 0 | Q13: 0 | R13: 0 | S13: 0 | T13: 0.1 | U13: 0 | V13: =8200/1400 -> 5.8571429 | W13: 4 | X13: 2 | Y13: 5 | Z13: 0 | AA13: =(9 + 10 + 9 + 5)/4 -> 8.25 | AB13: 0 | AC13: 0 | AD13: 6 | AE13: 0 | AF13: 0 | AG13: 0 | AH13: 6 | AI13: 0 | AJ13: =(BH13/5+1)*AI13 -> 0 | AK13: 0 | AL13: 0 | AM13: 0 | AN13: 0 | AO13: 0 | AP13: 0 | AQ13: 0 | AR13: 0 | AS13: 0 | AT13: 0 | AU13: 0 | AV13: 0 | AW13: 0 | AX13: 0 | AY13: 0 | AZ13: 0 | BA13: 0 | BB13: =(5 + 9 + 10)/3 -> 8 | BC13: 0 | BD13: 0 | BE13: 0 | BF13: 0 | BG13: 0 | BH13: 0 | BI13: 0 | BJ13: 0 | BK13: 7 | BL13: 0 | BM13: =(((H13*G13*F13)+O13+(U13/4))/1500)+((AO13*(AP13/3))/5) -> 2.2 | BN13: =(((H13*G13*F13)+P13+(U13/4))/1500)+((AO13*(AP13/5))/5) -> 2.2 | BO13: =((((H13*(W13/7))*G13*F13)+Q13+(U13/4))/1500)+((AO13*(AP13/7))/5) -> 1.2571429 | BP13: =((((H13*(W13/9))*G13*F13)+R13+(U13/4))/1200)+((AO13*(AP13/9))/5) -> 1.2222222 | BQ13: =(((I13*G13*F13)+(((G13*I13+N13)/D13)*O13))/(1.25-((I13-H13)/4))+(U13/4))/1300 -> 2.0307692 | BR13: =(((J13*G13*F13)+(((G13*J13+N13)/D13)*(P13)))/(1.25-((J13-H13)/4))+(U13/4))/800 -> 3.3 | BS13: =(((K13*G13*F13)+(((G13*K13+N13)/D13)*(Q13)))/(1.25-((K13-H13)/4))+(U13/4))/400 -> 0 | BT13: =(((L13*G13*F13)+(((G13*L13+N13)/D13)*(R13)))/(1.25-((L13-H13)/4))+(U13/4))/250 -> 0 | BV13: =((BQ13/2)*V13)/2.5 -> 2.3789011 | BW13: =((BR13)*(V13/2))/3.5 -> 2.7612245 | BX13: =((BS13*1.5)*(V13/3))/3 -> 0 | BY13: =((BT13*2)*(W13/4))/5 -> 0 | CA13: =(AJ13*BV13)/3 -> 0 | CB13: =(AJ13*BW13)/2.7 -> 0 | CC13: =(AJ13*BX13)/2.5 -> 0 | CD13: =(AJ13*BY13)/1.9 -> 0 | CF13: =SUM(AJ13*4, AH13*2, V13*2, BA13*2)/6 -> 3.952381 | CG13: =SUM(AVERAGE(Y13, (AVERAGE(BV13, BW13))/1.5)*4, V13*4, W13*2, CF13*2)/9 -> 5.8622315 | CH13: =SUM(AA13*5, (AVERAGE(BV13, BW13, BX13, BY13)/2)*2, BA13*2)/6 -> 7.0891719 | CI13: =IF(Z13<6, (Z13/2)*S13/2000, IF(Z13<7, (Z13/2)*(AVERAGE(BQ13, BR13, BS13, BT13)/2.5), (Z13/2)*(AVERAGE(BQ13, BR13, BS13, BT13)/2.5)+(S13/2000))) -> 0 | CJ13: =SUM(AK13*4, AN13*2/(AM13+1), AL13*4)/7.5 -> 0 | CK13: =SUM(AN13*3, AO13*2, AP13*2, AQ13*2, AK13*3)/8 -> 0 | CL13: =(SUM(Y13*2, BH13*1, AS13*3)/4.5)*1.5 -> 3.3333333 | CO13: C | CP13: C
B14: 18 | C14: JACKY | D14: 4 | E14: =10/D14 -> 2.5 | F14: 2480 | G14: =(2.5-((M14*2.5)/2)) -> 1.8333333 | H14: 1 | I14: 1 | J14: 0.5 | K14: 0 | L14: 0 | M14: =1.6 / 3 -> 0.53333333 | N14: =0-(0*(T14/2)) -> 0 | O14: 0 | P14: 0 | Q14: 0 | R14: 0 | S14: 0 | T14: 0.1 | U14: 0 | V14: =10000/1400 -> 7.1428571 | W14: 3 | X14: 0 | Y14: 9 | Z14: 6 | AA14: 0 | AB14: 4 | AC14: 0 | AD14: 3 | AE14: 0 | AF14: 0 | AG14: 0 | AH14: 6 | AI14: 0 | AJ14: =(BH14/5+1)*AI14 -> 0 | AK14: 0 | AL14: 0 | AM14: 0 | AN14: 0 | AO14: 0 | AP14: 0 | AQ14: 0 | AR14: 0 | AS14: 2 | AT14: 0 | AU14: 0 | AV14: 0 | AW14: 0 | AX14: 0 | AY14: 0 | AZ14: 0 | BA14: 0 | BB14: 0 | BC14: 0 | BD14: 0 | BE14: 0 | BF14: 1 | BG14: 0 | BH14: 0 | BI14: 0 | BJ14: 3 | BK14: 7 | BL14: 0 | BM14: =(((H14*G14*F14)+O14+(U14/4))/1500)+((AO14*(AP14/3))/5) -> 3.0311111 | BN14: =(((H14*G14*F14)+P14+(U14/4))/1500)+((AO14*(AP14/5))/5) -> 3.0311111 | BO14: =((((H14*(W14/7))*G14*F14)+Q14+(U14/4))/1500)+((AO14*(AP14/7))/5) -> 1.2990476 | BP14: =((((H14*(W14/9))*G14*F14)+R14+(U14/4))/1200)+((AO14*(AP14/9))/5) -> 1.262963 | BQ14: =(((I14*G14*F14)+(((G14*I14+N14)/D14)*O14))/(1.25-((I14-H14)/4))+(U14/4))/1300 -> 2.7979487 | BR14: =(((J14*G14*F14)+(((G14*J14+N14)/D14)*(P14)))/(1.25-((J14-H14)/4))+(U14/4))/800 -> 2.0666667 | BS14: =(((K14*G14*F14)+(((G14*K14+N14)/D14)*(Q14)))/(1.25-((K14-H14)/4))+(U14/4))/400 -> 0 | BT14: =(((L14*G14*F14)+(((G14*L14+N14)/D14)*(R14)))/(1.25-((L14-H14)/4))+(U14/4))/250 -> 0 | BV14: =((BQ14/2)*V14)/2.5 -> 3.9970696 | BW14: =((BR14)*(V14/2))/3.5 -> 2.1088435 | BX14: =((BS14*1.5)*(V14/3))/3 -> 0 | BY14: =((BT14*2)*(W14/4))/5 -> 0 | CA14: =(AJ14*BV14)/3 -> 0 | CB14: =(AJ14*BW14)/2.7 -> 0 | CC14: =(AJ14*BX14)/2.5 -> 0 | CD14: =(AJ14*BY14)/1.9 -> 0 | CF14: =SUM(AJ14*4, AH14*2, V14*2, BA14*2)/6 -> 4.3809524 | CG14: =SUM(AVERAGE(Y14, (AVERAGE(BV14, BW14))/1.5)*4, V14*4, W14*2, CF14*2)/9 -> 7.2671047 | CH14: =SUM(AA14*5, (AVERAGE(BV14, BW14, BX14, BY14)/2)*2, BA14*2)/6 -> 0.25441305 | CI14: =IF(Z14<6, (Z14/2)*S14/2000, IF(Z14<7, (Z14/2)*(AVERAGE(BQ14, BR14, BS14, BT14)/2.5), (Z14/2)*(AVERAGE(BQ14, BR14, BS14, BT14)/2.5)+(S14/2000))) -> 1.4593846 | CJ14: =SUM(AK14*4, AN14*2/(AM14+1), AL14*4)/7.5 -> 0 | CK14: =SUM(AN14*3, AO14*2, AP14*2, AQ14*2, AK14*3)/8 -> 0 | CL14: =(SUM(Y14*2, BH14*1, AS14*3)/4.5)*1.5 -> 8 | CO14: C | CP14: C
B15: 16 | C15: PENNY | D15: 5 | E15: =16/D15 -> 3.2 | F15: 1960 | G15: =(2.15-((M15*2.15)/2)) -> 1.5408333 | H15: 1 | I15: 1 | J15: 1 | K15: 0.5 | L15: 0 | M15: =1.7 / 3 -> 0.56666667 | N15: =2.5-(2.5*(T15/2)) -> 2.25 | O15: 1200 | P15: 1200 | Q15: 2400 | R15: 2400 | S15: 7200 | T15: 0.2 | U15: 0 | V15: =7000/1400 -> 5 | W15: 6 | X15: 0 | Y15: 1 | Z15: 2 | AA15: =(3 + 2 + 3 + 9)/4 -> 4.25 | AB15: 0 | AC15: 0 | AD15: 6 | AE15: 0 | AF15: 0 | AG15: 0 | AH15: 5 | AI15: 0 | AJ15: =(BH15/5+1)*AI15 -> 0 | AK15: 4 | AL15: 1 | AM15: 0 | AN15: 6 | AO15: 7 | AP15: 10 | AQ15: 0 | AR15: 0 | AS15: 9 | AT15: 0 | AU15: 0 | AV15: 0 | AW15: 0 | AX15: 0 | AY15: 0 | AZ15: 0 | BA15: 0 | BB15: 0 | BC15: 0 | BD15: 0 | BE15: 0 | BF15: 0 | BG15: 0 | BH15: 0 | BI15: 0 | BJ15: 0 | BK15: 7 | BL15: 0 | BM15: =(((H15*G15*F15)+O15+(U15/4))/1500)+((AO15*(AP15/3))/5) -> 7.4800222 | BN15: =(((H15*G15*F15)+P15+(U15/4))/1500)+((AO15*(AP15/5))/5) -> 5.6133556 | BO15: =((((H15*(W15/7))*G15*F15)+Q15+(U15/4))/1500)+((AO15*(AP15/7))/5) -> 5.3257333 | BP15: =((((H15*(W15/9))*G15*F15)+R15+(U15/4))/1200)+((AO15*(AP15/9))/5) -> 5.2333519 | BQ15: =(((I15*G15*F15)+(((G15*I15+N15)/D15)*O15))/(1.25-((I15-H15)/4))+(U15/4))/1300 -> 2.418359 | BR15: =(((J15*G15*F15)+(((G15*J15+N15)/D15)*(P15)))/(1.25-((J15-H15)/4))+(U15/4))/800 -> 3.9298333 | BS15: =(((K15*G15*F15)+(((G15*K15+N15)/D15)*(Q15)))/(1.25-((K15-H15)/4))+(U15/4))/400 -> 5.3814848 | BT15: =(((L15*G15*F15)+(((G15*L15+N15)/D15)*(R15)))/(1.25-((L15-H15)/4))+(U15/4))/250 -> 2.88 | BV15: =((BQ15/2)*V15)/2.5 -> 2.418359 | BW15: =((BR15)*(V15/2))/3.5 -> 2.8070238 | BX15: =((BS15*1.5)*(V15/3))/3 -> 4.4845707 | BY15: =((BT15*2)*(W15/4))/5 -> 1.728 | CA15: =(AJ15*BV15)/3 -> 0 | CB15: =(AJ15*BW15)/2.7 -> 0 | CC15: =(AJ15*BX15)/2.5 -> 0 | CD15: =(AJ15*BY15)/1.9 -> 0 | CF15: =SUM(AJ15*4, AH15*2, V15*2, BA15*2)/6 -> 3.3333333 | CG15: =SUM(AVERAGE(Y15, (AVERAGE(BV15, BW15))/1.5)*4, V15*4, W15*2, CF15*2)/9 -> 4.9055839 | CH15: =SUM(AA15*5, (AVERAGE(BV15, BW15, BX15, BY15)/2)*2, BA15*2)/6 -> 4.0182481 | CI15: =IF(Z15<6, (Z15/2)*S15/2000, IF(Z15<7, (Z15/2)*(AVERAGE(BQ15, BR15, BS15, BT15)/2.5), (Z15/2)*(AVERAGE(BQ15, BR15, BS15, BT15)/2.5)+(S15/2000))) -> 3.6 | CJ15: =SUM(AK15*4, AN15*2/(AM15+1), AL15*4)/7.5 -> 4.2666667 | CK15: =SUM(AN15*3, AO15*2, AP15*2, AQ15*2, AK15*3)/8 -> 8 | CL15: =(SUM(Y15*2, BH15*1, AS15*3)/4.5)*1.5 -> 9.6666667 | CO15: C | CP15: C
B16: 49 | C16: MORTIS | D16: 5 | E16: =16/D16 -> 3.2 | F16: 2000 | G16: =(1.65-((M16*1.65)/2)) -> 1.1 | H16: 1 | I16: 1 | J16: 0 | K16: 0 | L16: 0 | M16: =2 / 3 -> 0.66666667 | N16: =1-(1*(T16/2)) -> 0.95 | O16: 1800 | P16: 1800 | Q16: 1800 | R16: 1800 | S16: 1800 | T16: 0.1 | U16: 0 | V16: =8000/1400 + (5 + 6 + 6)/3/3.5 -> 7.3333333 | W16: 1 | X16: =(8.5 + 3 + 6)/3 -> 5.8333333 | Y16: 1 | Z16: 3 | AA16: 0 | AB16: 0 | AC16: 0 | AD16: 1 | AE16: 0 | AF16: 0 | AG16: 0 | AH16: 9 | AI16: 6 | AJ16: =(BH16/5+1)*AI16 -> 6 | AK16: 0 | AL16: 0 | AM16: 0 | AN16: 0 | AO16: 0 | AP16: 0 | AQ16: 0 | AR16: 0 | AS16: 7 | AT16: 0 | AU16: 0 | AV16: 0 | AW16: 0 | AX16: 0 | AY16: 0 | AZ16: 0 | BA16: 0 | BB16: 0 | BC16: 0 | BD16: 0 | BE16: 0 | BF16: 0 | BG16: 0 | BH16: 0 | BI16: 0 | BJ16: 0 | BK16: 6 | BL16: 0 | BM16: =(((H16*G16*F16)+O16+(U16/4))/1500)+((AO16*(AP16/3))/5) -> 2.6666667 | BN16: =(((H16*G16*F16)+P16+(U16/4))/1500)+((AO16*(AP16/5))/5) -> 2.6666667 | BO16: =((((H16*(W16/7))*G16*F16)+Q16+(U16/4))/1500)+((AO16*(AP16/7))/5) -> 1.4095238 | BP16: =((((H16*(W16/9))*G16*F16)+R16+(U16/4))/1200)+((AO16*(AP16/9))/5) -> 1.7037037 | BQ16: =(((I16*G16*F16)+(((G16*I16+N16)/D16)*O16))/(1.25-((I16-H16)/4))+(U16/4))/1300 -> 1.808 | BR16: =(((J16*G16*F16)+(((G16*J16+N16)/D16)*(P16)))/(1.25-((J16-H16)/4))+(U16/4))/800 -> 0.285 | BS16: =(((K16*G16*F16)+(((G16*K16+N16)/D16)*(Q16)))/(1.25-((K16-H16)/4))+(U16/4))/400 -> 0.57 | BT16: =(((L16*G16*F16)+(((G16*L16+N16)/D16)*(R16)))/(1.25-((L16-H16)/4))+(U16/4))/250 -> 0.912 | BV16: =((BQ16/2)*V16)/2.5 -> 2.6517333 | BW16: =((BR16)*(V16/2))/3.5 -> 0.29857143 | BX16: =((BS16*1.5)*(V16/3))/3 -> 0.69666667 | BY16: =((BT16*2)*(W16/4))/5 -> 0.0912 | CA16: =(AJ16*BV16)/3 -> 5.3034667 | CB16: =(AJ16*BW16)/2.7 -> 0.66349206 | CC16: =(AJ16*BX16)/2.5 -> 1.672 | CD16: =(AJ16*BY16)/1.9 -> 0.288 | CF16: =SUM(AJ16*4, AH16*2, V16*2, BA16*2)/6 -> 9.4444444 | CG16: =SUM(AVERAGE(Y16, (AVERAGE(BV16, BW16))/1.5)*4, V16*4, W16*2, CF16*2)/9 -> 6.0210102 | CH16: =SUM(AA16*5, (AVERAGE(BV16, BW16, BX16, BY16)/2)*2, BA16*2)/6 -> 0.15575714 | CI16: =IF(Z16<6, (Z16/2)*S16/2000, IF(Z16<7, (Z16/2)*(AVERAGE(BQ16, BR16, BS16, BT16)/2.5), (Z16/2)*(AVERAGE(BQ16, BR16, BS16, BT16)/2.5)+(S16/2000))) -> 1.35 | CJ16: =SUM(AK16*4, AN16*2/(AM16+1), AL16*4)/7.5 -> 0 | CK16: =SUM(AN16*3, AO16*2, AP16*2, AQ16*2, AK16*3)/8 -> 0 | CL16: =(SUM(Y16*2, BH16*1, AS16*3)/4.5)*1.5 -> 7.6666667 | CO16: C | CP16: C
B17: 12 | C17: TICK | D17: 6 | E17: =14/D17 -> 2.3333333 | F17: 1360 | G17: =(1.65-((M17*1.65)/2)) -> 0.9625 | H17: 1.5 | I17: 0.6 | J17: 1.2 | K17: 1.8 | L17: 0.6 | M17: =2.5 / 3 -> 0.83333333 | N17: =2-(2*(T17/2)) -> 1.9 | O17: 4000 | P17: 3000 | Q17: 2000 | R17: 1000 | S17: 4000 | T17: 0.1 | U17: 0 | V17: =4800/1400 -> 3.4285714 | W17: 7 | X17: 0 | Y17: 1 | Z17: 7 | AA17: =(6 + 2 + 3 + 8)/4 -> 4.75 | AB17: 1 | AC17: 0 | AD17: 6 | AE17: 0 | AF17: 0 | AG17: 0 | AH17: 5 | AI17: 0 | AJ17: =(BH17/5+1)*AI17 -> 0 | AK17: 4 | AL17: 1 | AM17: 0 | AN17: 2 | AO17: 6 | AP17: 1 | AQ17: 10 | AR17: 5 | AS17: 1 | AT17: =(3 + 5 + 5 + 5)/4 -> 4.5 | AU17: 0 | AV17: 0 | AW17: 0 | AX17: 0 | AY17: 0 | AZ17: 0 | BA17: 0 | BB17: 0 | BC17: 0 | BD17: 0 | BE17: 0 | BF17: 0 | BG17: 0 | BH17: 0 | BI17: 0 | BJ17: 0.5 | BK17: 7 | BL17: 0 | BM17: =(((H17*G17*F17)+O17+(U17/4))/1500)+((AO17*(AP17/3))/5) -> 4.3756667 | BN17: =(((H17*G17*F17)+P17+(U17/4))/1500)+((AO17*(AP17/5))/5) -> 3.549 | BO17: =((((H17*(W17/7))*G17*F17)+Q17+(U17/4))/1500)+((AO17*(AP17/7))/5) -> 2.8137619 | BP17: =((((H17*(W17/9))*G17*F17)+R17+(U17/4))/1200)+((AO17*(AP17/9))/5) -> 2.2393056 | BQ17: =(((I17*G17*F17)+(((G17*I17+N17)/D17)*O17))/(1.25-((I17-H17)/4))+(U17/4))/1300 -> 1.2709605 | BR17: =(((J17*G17*F17)+(((G17*J17+N17)/D17)*(P17)))/(1.25-((J17-H17)/4))+(U17/4))/800 -> 2.9229245 | BS17: =(((K17*G17*F17)+(((G17*K17+N17)/D17)*(Q17)))/(1.25-((K17-H17)/4))+(U17/4))/400 -> 7.5894326 | BT17: =(((L17*G17*F17)+(((G17*L17+N17)/D17)*(R17)))/(1.25-((L17-H17)/4))+(U17/4))/250 -> 3.2496723 | BV17: =((BQ17/2)*V17)/2.5 -> 0.87151574 | BW17: =((BR17)*(V17/2))/3.5 -> 1.4316365 | BX17: =((BS17*1.5)*(V17/3))/3 -> 4.3368186 | BY17: =((BT17*2)*(W17/4))/5 -> 2.2747706 | CA17: =(AJ17*BV17)/3 -> 0 | CB17: =(AJ17*BW17)/2.7 -> 0 | CC17: =(AJ17*BX17)/2.5 -> 0 | CD17: =(AJ17*BY17)/1.9 -> 0 | CF17: =SUM(AJ17*4, AH17*2, V17*2, BA17*2)/6 -> 2.8095238 | CG17: =SUM(AVERAGE(Y17, (AVERAGE(BV17, BW17))/1.5)*4, V17*4, W17*2, CF17*2)/9 -> 4.0965298 | CH17: =SUM(AA17*5, (AVERAGE(BV17, BW17, BX17, BY17)/2)*2, BA17*2)/6 -> 4.3297809 | CI17: =IF(Z17<6, (Z17/2)*S17/2000, IF(Z17<7, (Z17/2)*(AVERAGE(BQ17, BR17, BS17, BT17)/2.5), (Z17/2)*(AVERAGE(BQ17, BR17, BS17, BT17)/2.5)+(S17/2000))) -> 7.2615465 | CJ17: =SUM(AK17*4, AN17*2/(AM17+1), AL17*4)/7.5 -> 3.2 | CK17: =SUM(AN17*3, AO17*2, AP17*2, AQ17*2, AK17*3)/8 -> 6.5 | CL17: =(SUM(Y17*2, BH17*1, AS17*3)/4.5)*1.5 -> 1.6666667 | CO17: C | CP17: C
B18: 76 | C18: JUJU | D18: 7 | E18: =16/D18 -> 2.2857143 | F18: 1800 | G18: =(2.5-((M18*2.5)/2)) -> 1.9166667 | H18: 1 | I18: 1 | J18: 0.8 | K18: 0.4 | L18: 0.2 | M18: =1.4 / 3 -> 0.46666667 | N18: =2.5-(2.5*(T18/2)) -> 2.25 | O18: 1600 | P18: 3200 | Q18: 2400 | R18: 0 | S18: 6400 | T18: 0.2 | U18: 0 | V18: =6200/1400 -> 4.4285714 | W18: 7 | X18: 0 | Y18: 1 | Z18: 6 | AA18: 0 | AB18: 0 | AC18: 1 | AD18: 7 | AE18: 0 | AF18: 0 | AG18: 0 | AH18: 5 | AI18: 0 | AJ18: =(BH18/5+1)*AI18 -> 0 | AK18: 4 | AL18: 1 | AM18: 0 | AN18: 7 | AO18: 4 | AP18: 4 | AQ18: 4 | AR18: 7.5 | AS18: 0 | AT18: =(3 + 5 + 5 + 5)/4 -> 4.5 | AU18: 5 | AV18: 0 | AW18: 0 | AX18: 0 | AY18: 0 | AZ18: 0 | BA18: 0 | BB18: 0 | BC18: 0 | BD18: 0 | BE18: 0 | BF18: 0 | BG18: 0 | BH18: =(5 + 5 + 10)/3 -> 6.6666667 | BI18: 0 | BJ18: 0 | BK18: 7 | BL18: 0 | BM18: =(((H18*G18*F18)+O18+(U18/4))/1500)+((AO18*(AP18/3))/5) -> 4.4333333 | BN18: =(((H18*G18*F18)+P18+(U18/4))/1500)+((AO18*(AP18/5))/5) -> 5.0733333 | BO18: =((((H18*(W18/7))*G18*F18)+Q18+(U18/4))/1500)+((AO18*(AP18/7))/5) -> 4.3571429 | BP18: =((((H18*(W18/9))*G18*F18)+R18+(U18/4))/1200)+((AO18*(AP18/9))/5) -> 2.5916667 | BQ18: =(((I18*G18*F18)+(((G18*I18+N18)/D18)*O18))/(1.25-((I18-H18)/4))+(U18/4))/1300 -> 2.7091575 | BR18: =(((J18*G18*F18)+(((G18*J18+N18)/D18)*(P18)))/(1.25-((J18-H18)/4))+(U18/4))/800 -> 4.3168498 | BS18: =(((K18*G18*F18)+(((G18*K18+N18)/D18)*(Q18)))/(1.25-((K18-H18)/4))+(U18/4))/400 -> 4.3112245 | BT18: =(((L18*G18*F18)+(((G18*L18+N18)/D18)*(R18)))/(1.25-((L18-H18)/4))+(U18/4))/250 -> 1.9034483 | BV18: =((BQ18/2)*V18)/2.5 -> 2.3995395 | BW18: =((BR18)*(V18/2))/3.5 -> 2.7310683 | BX18: =((BS18*1.5)*(V18/3))/3 -> 3.1820943 | BY18: =((BT18*2)*(W18/4))/5 -> 1.3324138 | CA18: =(AJ18*BV18)/3 -> 0 | CB18: =(AJ18*BW18)/2.7 -> 0 | CC18: =(AJ18*BX18)/2.5 -> 0 | CD18: =(AJ18*BY18)/1.9 -> 0 | CF18: =SUM(AJ18*4, AH18*2, V18*2, BA18*2)/6 -> 3.1428571 | CG18: =SUM(AVERAGE(Y18, (AVERAGE(BV18, BW18))/1.5)*4, V18*4, W18*2, CF18*2)/9 -> 4.8244895 | CH18: =SUM(AA18*5, (AVERAGE(BV18, BW18, BX18, BY18)/2)*2, BA18*2)/6 -> 0.40187983 | CI18: =IF(Z18<6, (Z18/2)*S18/2000, IF(Z18<7, (Z18/2)*(AVERAGE(BQ18, BR18, BS18, BT18)/2.5), (Z18/2)*(AVERAGE(BQ18, BR18, BS18, BT18)/2.5)+(S18/2000))) -> 3.972204 | CJ18: =SUM(AK18*4, AN18*2/(AM18+1), AL18*4)/7.5 -> 4.5333333 | CK18: =SUM(AN18*3, AO18*2, AP18*2, AQ18*2, AK18*3)/8 -> 7.125 | CL18: =(SUM(Y18*2, BH18*1, AS18*3)/4.5)*1.5 -> 2.8888889 | CO18: C | CP18: C
