Workbook

Sheet Planilha2
A9: Nome Brawler | B9: Soma de Durability | C9: Soma de Distância-Ataque | D9: Soma de C Durability | E9: Soma de Ataque-Surpresa | F9: Soma de Aproximação-Fácil | G9: Soma de C Distância-ataque
A10: 8-BIT | B10: 7 | C10: 8 | D10: 6 | E10: 0 | F10: 1.9966667 | G10: 7.3318519
A11: ALLI | B11: 4 | C11: 1 | D11: 5 | E11: 6 | F11: 6.9966667 | G11: 5.5540741
A12: AMBER | B12: 3 | C12: 7 | D12: 6 | E12: 0 | F12: 1.9966667 | G12: 5.9985185
A13: ANGELO | B13: 3 | C13: 9 | D13: 6 | E13: 0 | F13: 3.33 | G13: 7.48
A14: ASH | B14: 9 | C14: 4 | D14: 5 | E14: 0 | F14: 3.9966667 | G14: 6.6651852
A15: BARLEY | B15: 2 | C15: 6 | D15: 5 | E15: 0 | F15: 1.6633333 | G15: 4.9614815
A16: BEA | B16: 3 | C16: 8 | D16: 6 | E16: 0 | F16: 1.9966667 | G16: 6.442963
A17: BELLE | B17: 2 | C17: 8 | D17: 4 | E17: 0 | F17: 1.6633333 | G17: 5.6281481
A18: BERRY | B18: 2 | C18: 5 | D18: 5 | E18: 7 | F18: 6.33 | G18: 6.5911111
A19: BIBI | B19: 7 | C19: 2 | D19: 5 | E19: 0 | F19: 4.6633333 | G19: 5.6281481
A20: BO | B20: 4 | C20: 7 | D20: 5 | E20: 0 | F20: 2.33 | G20: 6.1466667
A21: BONNIE | B21: 6 | C21: 8 | D21: 5 | E21: 7 | F21: 6.9966667 | G21: 9.1096296
... A109: Total Geral | B109: 442 | C109: 570 | D109: 514 | E109: 169 | F109: 394.33667 | G109: 641.03852

Sheet Planilha1
W1: durabilidade, (suporte-cura, suporte-escudo) | AA1: ataque-surpresa, (durabilidade, velocidade-movimento) | AB1: distancia-ataque, (durabilidade, aproximação-facil, counter-durabilidade) | AC1: durabilidade (C-durabilidade, potencial-dano-curto-alcance)
B3: ID | C3: Nome Brawler | H3: POT-DAN-CUR-ALC | J3: PODER-DE-STUN | P3: DANO-PETS | W3: Durability | X3: Distância-Ataque | Y3: C Durability | Z3: Ataque-Surpresa | AA3: Aproximação-Fácil | AB3: C Distância-ataque | AC3: Botão-de-Fuga
B4: 1 | C4: SHELLY | H4: 7 | W4: 4 | X4: 6 | Y4: 8 | Z4: 0 | AA4: =SUM(Z4, AVERAGE(7, W4))/1.5-0.67 -> 2.9966667 | AB4: =SUM(X4, AA4, AVERAGE(Y4, W4))/2.25 -> 6.6651852 | AC4: =SUM(AVERAGE(Y4, W4), AVERAGE(Y4, 7))/1.5 -> 9
B5: 2 | C5: NITA | H5: 9 | W5: 5 | X5: 5 | Y5: 6 | Z5: 0 | AA5: =SUM(Z5, AVERAGE(5, W5))/1.5-0.67 -> 2.6633333 | AB5: =SUM(X5, AA5, AVERAGE(Y5, W5))/2.25 -> 5.8503704 | AC5: =SUM(AVERAGE(Y5, W5), AVERAGE(Y5, 9))/1.5 -> 8.6666667
B6: 3 | C6: COLT | H6: 6 | W6: 3 | X6: 8 | Y6: 9 | Z6: 0 | AA6: =SUM(Z6, AVERAGE(5, W6))/1.5-0.67 -> 1.9966667 | AB6: =SUM(X6, AA6, AVERAGE(Y6, W6))/2.25 -> 7.1096296 | AC6: =SUM(AVERAGE(Y6, W6), AVERAGE(Y6, 6))/1.5 -> 9
B7: 4 | C7: BULL | H7: 7 | W7: 7 | X7: 2 | Y7: 8 | Z7: 4 | AA7: =SUM(Z7, AVERAGE(7, W7))/1.5-0.67 -> 6.6633333 | AB7: =SUM(X7, AA7, AVERAGE(Y7, W7))/2.25 -> 7.1837037 | AC7: =SUM(AVERAGE(Y7, W7), AVERAGE(Y7, 7))/1.5 -> 10
B8: 5 | C8: BROCK | H8: 7 | W8: 3 | X8: 7 | Y8: 6 | Z8: 0 | AA8: =SUM(Z8, AVERAGE(5, W8))/1.5-0.67 -> 1.9966667 | AB8: =SUM(X8, AA8, AVERAGE(Y8, W8))/2.25 -> 5.9985185 | AC8: =SUM(AVERAGE(Y8, W8), AVERAGE(Y8, 7))/1.5 -> 7.3333333
B9: 6 | C9: EL PRIMO | H9: 7 | W9: 10 | X9: 1 | Y9: 5 | Z9: 3 | AA9: =SUM(Z9, AVERAGE(7, W9))/1.5-0.67 -> 6.9966667 | AB9: =SUM(X9, AA9, AVERAGE(Y9, W9))/2.25 -> 6.8874074 | AC9: =SUM(AVERAGE(Y9, W9), AVERAGE(Y9, 7))/1.5 -> 9
B10: 7 | C10: BARLEY | H10: 5 | W10: 2 | X10: 6 | Y10: 5 | Z10: 0 | AA10: =SUM(Z10, AVERAGE(5, W10))/1.5-0.67 -> 1.6633333 | AB10: =SUM(X10, AA10, AVERAGE(Y10, W10))/2.25 -> 4.9614815 | AC10: =SUM(AVERAGE(Y10, W10), AVERAGE(Y10, 5))/1.5 -> 5.6666667
B11: 8 | C11: POCO | H11: 9 | W11: 5 | X11: 6 | Y11: 2 | Z11: 0 | AA11: =SUM(Z11, AVERAGE(5, W11))/1.5-0.67 -> 2.6633333 | AB11: =SUM(X11, AA11, AVERAGE(Y11, W11))/2.25 -> 5.4059259 | AC11: =SUM(AVERAGE(Y11, W11), AVERAGE(Y11, 9))/1.5 -> 6
B12: 9 | C12: ROSA | H12: 8 | W12: 7 | X12: 3 | Y12: 4 | Z12: 0 | AA12: =SUM(Z12, AVERAGE(7, W12))/1.5-0.67 -> 3.9966667 | AB12: =SUM(X12, AA12, AVERAGE(Y12, W12))/2.25 -> 5.5540741 | AC12: =SUM(AVERAGE(Y12, W12), AVERAGE(Y12, 8))/1.5 -> 7.6666667
B13: 10 | C13: JESSIE | H13: 8 | W13: 3 | X13: 7 | Y13: 6 | Z13: 0 | AA13: =SUM(Z13, AVERAGE(5, W13))/1.5-0.67 -> 1.9966667 | AB13: =SUM(X13, AA13, AVERAGE(Y13, W13))/2.25 -> 5.9985185 | AC13: =SUM(AVERAGE(Y13, W13), AVERAGE(Y13, 8))/1.5 -> 7.6666667
B14: 11 | C14: DYNAMIKE | H14: 3 | W14: 3 | X14: 6 | Y14: 8 | Z14: 0 | AA14: =SUM(Z14, AVERAGE(7, W14))/1.5-0.67 -> 2.6633333 | AB14: =SUM(X14, AA14, AVERAGE(Y14, W14))/2.25 -> 6.2948148 | AC14: =SUM(AVERAGE(Y14, W14), AVERAGE(Y14, 3))/1.5 -> 7.3333333
B15: 12 | C15: TICK | H15: 4 | W15: 1 | X15: 7 | Y15: 5 | Z15: 0 | AA15: =SUM(Z15, AVERAGE(5, W15))/1.5-0.67 -> 1.33 | AB15: =SUM(X15, AA15, AVERAGE(Y15, W15))/2.25 -> 5.0355556 | AC15: =SUM(AVERAGE(Y15, W15), AVERAGE(Y15, 4))/1.5 -> 5
B16: 13 | C16: 8-BIT | H16: 5 | W16: 7 | X16: 8 | Y16: 6 | Z16: 0 | AA16: =SUM(Z16, AVERAGE(1, W16))/1.5-0.67 -> 1.9966667 | AB16: =SUM(X16, AA16, AVERAGE(Y16, W16))/2.25 -> 7.3318519 | AC16: =SUM(AVERAGE(Y16, W16), AVERAGE(Y16, 5))/1.5 -> 8
B17: 14 | C17: RICO | H17: 6 | W17: 3 | X17: 8 | Y17: 9 | Z17: 0 | AA17: =SUM(Z17, AVERAGE(5, W17))/1.5-0.67 -> 1.9966667 | AB17: =SUM(X17, AA17, AVERAGE(Y17, W17))/2.25 -> 7.1096296 | AC17: =SUM(AVERAGE(Y17, W17), AVERAGE(Y17, 6))/1.5 -> 9
B18: 15 | C18: DARRYL | H18: 7 | W18: 8 | X18: 4 | Y18: 5 | Z18: 6 | AA18: =SUM(Z18, AVERAGE(7, W18))/1.5-0.67 -> 8.33 | AB18: =SUM(X18, AA18, AVERAGE(Y18, W18))/2.25 -> 8.3688889 | AC18: =SUM(AVERAGE(Y18, W18), AVERAGE(Y18, 7))/1.5 -> 8.3333333
B19: 16 | C19: PENNY | H19: 8 | W19: 4 | X19: 6 | Y19: 5 | Z19: 0 | AA19: =SUM(Z19, AVERAGE(5, W19))/1.5-0.67 -> 2.33 | AB19: =SUM(X19, AA19, AVERAGE(Y19, W19))/2.25 -> 5.7022222 | AC19: =SUM(AVERAGE(Y19, W19), AVERAGE(Y19, 8))/1.5 -> 7.3333333
B20: 17 | C20: CARL | H20: 6 | W20: 5 | X20: 7 | Y20: 6 | Z20: 0 | AA20: =SUM(Z20, AVERAGE(5, W20))/1.5-0.67 -> 2.6633333 | AB20: =SUM(X20, AA20, AVERAGE(Y20, W20))/2.25 -> 6.7392593 | AC20: =SUM(AVERAGE(Y20, W20), AVERAGE(Y20, 6))/1.5 -> 7.6666667
B21: 18 | C21: JACKY | H21: 8 | W21: 7 | X21: 3 | Y21: 4 | Z21: 0 | AA21: =SUM(Z21, AVERAGE(7, W21))/1.5-0.67 -> 3.9966667 | AB21: =SUM(X21, AA21, AVERAGE(Y21, W21))/2.25 -> 5.5540741 | AC21: =SUM(AVERAGE(Y21, W21), AVERAGE(Y21, 8))/1.5 -> 7.6666667
B22: 19 | C22: GUS | H22: 8 | W22: 3 | X22: 8 | Y22: 4 | Z22: 0 | AA22: =SUM(Z22, AVERAGE(5, W22))/1.5-0.67 -> 1.9966667 | AB22: =SUM(X22, AA22, AVERAGE(Y22, W22))/2.25 -> 5.9985185 | AC22: =SUM(AVERAGE(Y22, W22), AVERAGE(Y22, 8))/1.5 -> 6.3333333
B23: 20 | C23: BO | H23: 8 | W23: 4 | X23: 7 | Y23: 5 | Z23: 0 | AA23: =SUM(Z23, AVERAGE(5, W23))/1.5-0.67 -> 2.33 | AB23: =SUM(X23, AA23, AVERAGE(Y23, W23))/2.25 -> 6.1466667 | AC23: =SUM(AVERAGE(Y23, W23), AVERAGE(Y23, 8))/1.5 -> 7.3333333
B24: 21 | C24: EMZ | H24: 6 | W24: 4 | X24: 5 | Y24: 6 | Z24: 0 | AA24: =SUM(Z24, AVERAGE(5, W24))/1.5-0.67 -> 2.33 | AB24: =SUM(X24, AA24, AVERAGE(Y24, W24))/2.25 -> 5.48 | AC24: =SUM(AVERAGE(Y24, W24), AVERAGE(Y24, 6))/1.5 -> 7.3333333
B25: 22 | C25: STU | H25: 8 | W25: 4 | X25: 6 | Y25: 4 | Z25: 3 | AA25: =SUM(Z25, AVERAGE(5, W25))/1.5-0.67 -> 4.33 | AB25: =SUM(X25, AA25, AVERAGE(Y25, W25))/2.25 -> 6.3688889 | AC25: =SUM(AVERAGE(Y25, W25), AVERAGE(Y25, 8))/1.5 -> 6.6666667
B26: 23 | C26: PIPER | H26: 4 | W26: 2 | X26: 9 | Y26: 6 | Z26: 1 | AA26: =SUM(Z26, AVERAGE(5, W26))/1.5-0.67 -> 2.33 | AB26: =SUM(X26, AA26, AVERAGE(Y26, W26))/2.25 -> 6.8133333 | AC26: =SUM(AVERAGE(Y26, W26), AVERAGE(Y26, 4))/1.5 -> 6
B27: 24 | C27: PAM | H27: 6 | W27: 7 | X27: 7 | Y27: 5 | Z27: 0 | AA27: =SUM(Z27, AVERAGE(5, W27))/1.5-0.67 -> 3.33 | AB27: =SUM(X27, AA27, AVERAGE(Y27, W27))/2.25 -> 7.2577778 | AC27: =SUM(AVERAGE(Y27, W27), AVERAGE(Y27, 6))/1.5 -> 7.6666667
B28: 25 | C28: FRANK | H28: 8 | W28: 10 | X28: 5 | Y28: 5 | Z28: 0 | AA28: =SUM(Z28, AVERAGE(7, W28))/1.5-0.67 -> 4.9966667 | AB28: =SUM(X28, AA28, AVERAGE(Y28, W28))/2.25 -> 7.7762963 | AC28: =SUM(AVERAGE(Y28, W28), AVERAGE(Y28, 8))/1.5 -> 9.3333333
B29: 26 | C29: BIBI | H29: 8 | W29: 7 | X29: 2 | Y29: 5 | Z29: 0 | AA29: =SUM(Z29, AVERAGE(9, W29))/1.5-0.67 -> 4.6633333 | AB29: =SUM(X29, AA29, AVERAGE(Y29, W29))/2.25 -> 5.6281481 | AC29: =SUM(AVERAGE(Y29, W29), AVERAGE(Y29, 8))/1.5 -> 8.3333333
B30: 27 | C30: BEA | H30: 8 | W30: 3 | X30: 8 | Y30: 6 | Z30: 0 | AA30: =SUM(Z30, AVERAGE(5, W30))/1.5-0.67 -> 1.9966667 | AB30: =SUM(X30, AA30, AVERAGE(Y30, W30))/2.25 -> 6.442963 | AC30: =SUM(AVERAGE(Y30, W30), AVERAGE(Y30, 8))/1.5 -> 7.6666667
B31: 28 | C31: NANI | H31: 8 | W31: 2 | X31: 10 | Y31: 7 | Z31: 0 | AA31: =SUM(Z31, AVERAGE(5, W31))/1.5-0.67 -> 1.6633333 | AB31: =SUM(X31, AA31, AVERAGE(Y31, W31))/2.25 -> 7.1837037 | AC31: =SUM(AVERAGE(Y31, W31), AVERAGE(Y31, 8))/1.5 -> 8
B32: 29 | C32: EDGAR | H32: 7 | W32: 4 | X32: 1 | Y32: 5 | Z32: 6 | AA32: =SUM(Z32, AVERAGE(9, W32))/1.5-0.67 -> 7.6633333 | AB32: =SUM(X32, AA32, AVERAGE(Y32, W32))/2.25 -> 5.8503704 | AC32: =SUM(AVERAGE(Y32, W32), AVERAGE(Y32, 7))/1.5 -> 7
B33: 30 | C33: GRIFF | H33: 8 | W33: 4 | X33: 7 | Y33: 9 | Z33: 0 | AA33: =SUM(Z33, AVERAGE(5, W33))/1.5-0.67 -> 2.33 | AB33: =SUM(X33, AA33, AVERAGE(Y33, W33))/2.25 -> 7.0355556 | AC33: =SUM(AVERAGE(Y33, W33), AVERAGE(Y33, 8))/1.5 -> 10
B34: 31 | C34: GROM | H34: 4 | W34: 3 | X34: 7 | Y34: 4 | Z34: 0 | AA34: =SUM(Z34, AVERAGE(5, W34))/1.5-0.67 -> 1.9966667 | AB34: =SUM(X34, AA34, AVERAGE(Y34, W34))/2.25 -> 5.5540741 | AC34: =SUM(AVERAGE(Y34, W34), AVERAGE(Y34, 4))/1.5 -> 5
B35: 32 | C35: BONNIE | H35: 9 | W35: 6 | X35: 8 | Y35: 5 | Z35: 7 | AA35: =SUM(Z35, AVERAGE(3, W35))/1.5-0.67 -> 6.9966667 | AB35: =SUM(X35, AA35, AVERAGE(Y35, W35))/2.25 -> 9.1096296 | AC35: =SUM(AVERAGE(Y35, W35), AVERAGE(Y35, 9))/1.5 -> 8.3333333
B36: 33 | C36: GALE | H36: 6 | W36: 5 | X36: 7 | Y36: 5 | Z36: 0 | AA36: =SUM(Z36, AVERAGE(5, W36))/1.5-0.67 -> 2.6633333 | AB36: =SUM(X36, AA36, AVERAGE(Y36, W36))/2.25 -> 6.517037 | AC36: =SUM(AVERAGE(Y36, W36), AVERAGE(Y36, 6))/1.5 -> 7
B37: 34 | C37: COLLETE | H37: 9 | W37: 4 | X37: 8 | Y37: 4 | Z37: 0 | AA37: =SUM(Z37, AVERAGE(5, W37))/1.5-0.67 -> 2.33 | AB37: =SUM(X37, AA37, AVERAGE(Y37, W37))/2.25 -> 6.3688889 | AC37: =SUM(AVERAGE(Y37, W37), AVERAGE(Y37, 9))/1.5 -> 7
B38: 35 | C38: BELLE | H38: 8 | W38: 2 | X38: 8 | Y38: 4 | Z38: 0 | AA38: =SUM(Z38, AVERAGE(5, W38))/1.5-0.67 -> 1.6633333 | AB38: =SUM(X38, AA38, AVERAGE(Y38, W38))/2.25 -> 5.6281481 | AC38: =SUM(AVERAGE(Y38, W38), AVERAGE(Y38, 8))/1.5 -> 6
B39: 36 | C39: ASH | H39: 8 | W39: 9 | X39: 4 | Y39: 5 | Z39: 0 | AA39: =SUM(Z39, AVERAGE(5, W39))/1.5-0.67 -> 3.9966667 | AB39: =SUM(X39, AA39, AVERAGE(Y39, W39))/2.25 -> 6.6651852 | AC39: =SUM(AVERAGE(Y39, W39), AVERAGE(Y39, 8))/1.5 -> 9
B40: 37 | C40: LOLA | H40: 7 | W40: 5 | X40: 7 | Y40: 6 | Z40: 0 | AA40: =SUM(Z40, AVERAGE(5, W40))/1.5-0.67 -> 2.6633333 | AB40: =SUM(X40, AA40, AVERAGE(Y40, W40))/2.25 -> 6.7392593 | AC40: =SUM(AVERAGE(Y40, W40), AVERAGE(Y40, 7))/1.5 -> 8
B41: 38 | C41: SAM | H41: 8 | W41: 8 | X41: 3 | Y41: 4 | Z41: 0 | AA41: =SUM(Z41, AVERAGE(7, W41))/1.5-0.67 -> 4.33 | AB41: =SUM(X41, AA41, AVERAGE(Y41, W41))/2.25 -> 5.9244444 | AC41: =SUM(AVERAGE(Y41, W41), AVERAGE(Y41, 8))/1.5 -> 8
...

Sheet DADOS UTEISA
B2: VELOCIDADES RECARGA
B3: MT-RAPIDO | C3: 0.66t p/s
B4: RAPIDO | C4: 0.57t p/s
B5: NORMAL | C5: 0.50t p/s
B6: LENTO | C6: 0.43t p/s
B7: MT-LENTO | C7: 0.33t p/s

Sheet Planilha3
A2: ID | B2: (Tudo)
B4: Nome Brawler | F4: Nome Brawler | G4: NOME ACESSÓRIO | K4: Nome Brawler | L4: NOME ACESSÓRIO | P4: Nome Brawler | Q4: NOME PODER DE ESTRELA | U4: Nome Brawler | V4: NOME PODER DE ESTRELA | Z4: Nome Brawler | AA4: NOME HIPERCARGA
A5: Valores | B5: TICK | C5: Total Geral | F5: TICK | G5: TICK Total | H5: Total Geral | K5: TICK | L5: TICK Total | M5: Total Geral | P5: TICK | Q5: TICK Total | R5: Total Geral | U5: TICK | V5: TICK Total | W5: Total Geral | Z5: TICK | AA5: TICK Total | AB5: Total Geral
A6: Soma de PROJETEIS-PARA-SUPER | B6: 6 | C6: 6 | E6: Valores | F6: MINE MANIA | J6: Valores | K6: LAST HURRAH | O6: Valores | P6: WELL OILED | T6: Valores | U6: AUTOMA-TICK RELOAD | Y6: Valores | Z6: HEADSTRONG
A7: Soma de SUPERS-PARA-HIPERCARGA | B7: 2.3333333 | C7: 2.3333333 | E7: Soma de PROJETEIS-PARA-SUPER | F7: 0 | G7: 0 | H7: 0 | J7: Soma de PROJETEIS-PARA-SUPER | K7: 0 | L7: 0 | M7: 0 | O7: Soma de PROJETEIS-PARA-SUPER | P7: 0 | Q7: 0 | R7: 0 | T7: Soma de PROJETEIS-PARA-SUPER | U7: 0 | V7: 0 | W7: 0 | Y7: Soma de PROJETEIS-PARA-SUPER | Z7: 0 | AA7: 0 | AB7: 0
A8: Soma de DANO-PROJETIL | B8: 1360 | C8: 1360 | E8: Soma de SUPERS-PARA-HIPERCARGA | F8: 0 | G8: 0 | H8: 0 | J8: Soma de SUPERS-PARA-HIPERCARGA | K8: 0 | L8: 0 | M8: 0 | O8: Soma de SUPERS-PARA-HIPERCARGA | P8: 0 | Q8: 0 | R8: 0 | T8: Soma de SUPERS-PARA-HIPERCARGA | U8: 0 | V8: 0 | W8: 0 | Y8: Soma de SUPERS-PARA-HIPERCARGA | Z8: 0 | AA8: 0 | AB8: 0
A9: Soma de TIROS-DADOS-EM-5-SEGUNDOS | B9: 1.65 | C9: 1.65 | E9: Soma de DANO-PROJETIL | F9: 0 | G9: 0 | H9: 0 | J9: Soma de DANO-PROJETIL | K9: 0 | L9: 0 | M9: 0 | O9: Soma de DANO-PROJETIL | P9: 0 | Q9: 0 | R9: 0 | T9: Soma de DANO-PROJETIL | U9: 0 | V9: 0 | W9: 0 | Y9: Soma de DANO-PROJETIL | Z9: 29.142857 | AA9: 29.142857 | AB9: 29.142857
A10: Soma de MÉDIA-PROJETEIS-POR-TIRO | B10: 2 | C10: 2 | E10: Soma de TIROS-DADOS-EM-5-SEGUNDOS | F10: 0 | G10: 0 | H10: 0 | J10: Soma de TIROS-DADOS-EM-5-SEGUNDOS | K10: 0 | L10: 0 | M10: 0 | O10: Soma de TIROS-DADOS-EM-5-SEGUNDOS | P10: 0 | Q10: 0 | R10: 0 | T10: Soma de TIROS-DADOS-EM-5-SEGUNDOS | U10: 0.1485 | V10: 0.1485 | W10: 0.1485 | Y10: Soma de TIROS-DADOS-EM-5-SEGUNDOS | Z10: 0 | AA10: 0 | AB10: 0
A11: Soma de CURTO-ALCANCE-QUANT-PROJETIL-MEDIO | B11: 1 | C11: 1 | E11: Soma de MÉDIA-PROJETEIS-POR-TIRO | F11: 0.66666667 | G11: 0.66666667 | H11: 0.66666667 | J11: Soma de MÉDIA-PROJETEIS-POR-TIRO | K11: 0 | L11: 0 | M11: 0 | O11: Soma de MÉDIA-PROJETEIS-POR-TIRO | P11: 0 | Q11: 0 | R11: 0 | T11: Soma de MÉDIA-PROJETEIS-POR-TIRO | U11: 0 | V11: 0 | W11: 0 | Y11: Soma de MÉDIA-PROJETEIS-POR-TIRO | Z11: 0 | AA11: 0 | AB11: 0
A12: Soma de MEDIO-ALCANCE-QUANT-PROJETIL-MEDIO | B12: 2 | C12: 2 | E12: Soma de CURTO-ALCANCE-QUANT-PROJETIL-MEDIO | F12: 0.33333333 | G12: 0.33333333 | H12: 0.33333333 | J12: Soma de CURTO-ALCANCE-QUANT-PROJETIL-MEDIO | K12: 0 | L12: 0 | M12: 0 | O12: Soma de CURTO-ALCANCE-QUANT-PROJETIL-MEDIO | P12: 0 | Q12: 0 | R12: 0 | T12: Soma de CURTO-ALCANCE-QUANT-PROJETIL-MEDIO | U12: 0 | V12: 0 | W12: 0 | Y12: Soma de CURTO-ALCANCE-QUANT-PROJETIL-MEDIO | Z12: 0 | AA12: 0 | AB12: 0
A13: Soma de LONGO-ALCANCE-QUANT-PROJETIL-MEDIO | B13: 1 | C13: 1 | E13: Soma de MEDIO-ALCANCE-QUANT-PROJETIL-MEDIO | F13: 0.66666667 | G13: 0.66666667 | H13: 0.66666667 | J13: Soma de MEDIO-ALCANCE-QUANT-PROJETIL-MEDIO | K13: 0 | L13: 0 | M13: 0 | O13: Soma de MEDIO-ALCANCE-QUANT-PROJETIL-MEDIO | P13: 0 | Q13: 0 | R13: 0 | T13: Soma de MEDIO-ALCANCE-QUANT-PROJETIL-MEDIO | U13: 0 | V13: 0 | W13: 0 | Y13: Soma de MEDIO-ALCANCE-QUANT-PROJETIL-MEDIO | Z13: 0 | AA13: 0 | AB13: 0
A14: Soma de MTLONGO-ALCANCE-QUANT-PROJETIL-MEDIO | B14: 1 | C14: 1 | E14: Soma de LONGO-ALCANCE-QUANT-PROJETIL-MEDIO | F14: 0.33333333 | G14: 0.33333333 | H14: 0.33333333 | J14: Soma de LONGO-ALCANCE-QUANT-PROJETIL-MEDIO | K14: 0 | L14: 0 | M14: 0 | O14: Soma de LONGO-ALCANCE-QUANT-PROJETIL-MEDIO | P14: 0 | Q14: 0 | R14: 0 | T14: Soma de LONGO-ALCANCE-QUANT-PROJETIL-MEDIO | U14: 0 | V14: 0 | W14: 0 | Y14: Soma de LONGO-ALCANCE-QUANT-PROJETIL-MEDIO | Z14: 0 | AA14: 0 | AB14: 0
A15: Soma de CARREGAMENTO-SUPER-AO-ACERTAR-EM-PROJETEIS | B15: 2 | C15: 2 | E15: Soma de MTLONGO-ALCANCE-QUANT-PROJETIL-MEDIO | F15: 0.33333333 | G15: 0.33333333 | H15: 0.33333333 | J15: Soma de MTLONGO-ALCANCE-QUANT-PROJETIL-MEDIO | K15: 0 | L15: 0 | M15: 0 | O15: Soma de MTLONGO-ALCANCE-QUANT-PROJETIL-MEDIO | P15: 0 | Q15: 0 | R15: 0 | T15: Soma de MTLONGO-ALCANCE-QUANT-PROJETIL-MEDIO | U15: 0 | V15: 0 | W15: 0 | Y15: Soma de MTLONGO-ALCANCE-QUANT-PROJETIL-MEDIO | Z15: 0 | AA15: 0 | AB15: 0
A16: Soma de CURTO-ALCANCE-DANO-SUPER-MEDIO | B16: 4000 | C16: 4000 | E16: Soma de CARREGAMENTO-SUPER-AO-ACERTAR-EM-PROJETEIS | F16: 0 | G16: 0 | H16: 0 | J16: Soma de CARREGAMENTO-SUPER-AO-ACERTAR-EM-PROJETEIS | K16: 0 | L16: 0 | M16: 0 | O16: Soma de CARREGAMENTO-SUPER-AO-ACERTAR-EM-PROJETEIS | P16: 0 | Q16: 0 | R16: 0 | T16: Soma de CARREGAMENTO-SUPER-AO-ACERTAR-EM-PROJETEIS | U16: 0 | V16: 0 | W16: 0 | Y16: Soma de CARREGAMENTO-SUPER-AO-ACERTAR-EM-PROJETEIS | Z16: 0 | AA16: 0 | AB16: 0
A17: Soma de MEDIO-ALCANCE-DANO-SUPER-MEDIO | B17: 3000 | C17: 3000 | E17: Soma de CURTO-ALCANCE-DANO-SUPER-MEDIO | F17: 0 | G17: 0 | H17: 0 | J17: Soma de CURTO-ALCANCE-DANO-SUPER-MEDIO | K17: 0 | L17: 0 | M17: 0 | O17: Soma de CURTO-ALCANCE-DANO-SUPER-MEDIO | P17: 0 | Q17: 0 | R17: 0 | T17: Soma de CURTO-ALCANCE-DANO-SUPER-MEDIO | U17: 0 | V17: 0 | W17: 0 | Y17: Soma de CURTO-ALCANCE-DANO-SUPER-MEDIO | Z17: 1800 | AA17: 1800 | AB17: 1800
A18: Soma de LONGO-ALCANCE-DANO-SUPER-MEDIO | B18: 2000 | C18: 2000 | E18: Soma de MEDIO-ALCANCE-DANO-SUPER-MEDIO | F18: 0 | G18: 0 | H18: 0 | J18: Soma de MEDIO-ALCANCE-DANO-SUPER-MEDIO | K18: 0 | L18: 0 | M18: 0 | O18: Soma de MEDIO-ALCANCE-DANO-SUPER-MEDIO | P18: 0 | Q18: 0 | R18: 0 | T18: Soma de MEDIO-ALCANCE-DANO-SUPER-MEDIO | U18: 0 | V18: 0 | W18: 0 | Y18: Soma de MEDIO-ALCANCE-DANO-SUPER-MEDIO | Z18: 1350 | AA18: 1350 | AB18: 1350
... A63: Soma de COUNTER-CANCELAMENTO-ATAQUES | B63: 7 | C63: 7 | E63: Soma de CANCELAMENTO-ATAQUES | F63: 0 | G63: 0 | H63: 0 | J63: Soma de CANCELAMENTO-ATAQUES | K63: 1 | L63: 1 | M63: 1 | O63: Soma de CANCELAMENTO-ATAQUES | P63: 0 | Q63: 0 | R63: 0 | T63: Soma de CANCELAMENTO-ATAQUES | U63: 0 | V63: 0 | W63: 0 | Y63: Soma de CANCELAMENTO-ATAQUES | Z63: 0 | AA63: 0 | AB63: 0
A64: Contagem de ESPAÇO | E64: Soma de COUNTER-CANCELAMENTO-ATAQUES | F64: 0 | G64: 0 | H64: 0 | J64: Soma de COUNTER-CANCELAMENTO-ATAQUES | K64: 0 | L64: 0 | M64: 0 | O64: Soma de COUNTER-CANCELAMENTO-ATAQUES | P64: 0 | Q64: 0 | R64: 0 | T64: Soma de COUNTER-CANCELAMENTO-ATAQUES | U64: 0 | V64: 0 | W64: 0 | Y64: Soma de COUNTER-CANCELAMENTO-ATAQUES | Z64: 0 | AA64: 0 | AB64: 0
A65: Contagem de ESPAÇO2
A66: Contagem de ESPAÇO3
A67: Contagem de ESPAÇO4
A68: Soma de CURTO-ALCANCE-5-SEC-DANO-TOTAL-1-SUPER | B68: 8488 | C68: 8488
A69: Soma de MEDIO-ALCANCE-5-SEC-DANO-TOTAL-1-SUPER | B69: 7488 | C69: 7488
A70: Soma de LONGO-ALCANCE-5-SEC-DANO-TOTAL-1-SUPER | B70: 6488 | C70: 6488
A71: Soma de MT-LONGO-ALCANCE-5-SEC-DANO-TOTAL-1-SUPER | B71: 5488 | C71: 5488
A72: Soma de CURTO-ALCANCE-5-SEC-DANO-MEDIO | B72: 3118.2222 | C72: 3118.2222
A73: Soma de MEDIO-ALCANCE-5-SEC-DANO-MEDIO | B73: 4297.0667 | C73: 4297.0667
A74: Soma de LONGO-ALCANCE-5-SEC-DANO-MEDIO | B74: 1496 | C74: 1496
A75: Soma de MT-LONGO-ALCANCE-5-SEC-DANO-MEDIO | B75: 1090.4444 | C75: 1090.4444
A76: Soma de CURTO-ALCANCE-DANO-RESISTENCIA | B76: 2672.7619 | C76: 2672.7619
A77: Soma de MEDIO-ALCANCE-DANO-RESISTENCIA | B77: 3683.2 | C77: 3683.2
A78: Soma de LONGO-ALCANCE-DANO-RESISTENCIA | B78: 1282.2857 | C78: 1282.2857
A79: Soma de MT-LONGO-ALCANCE-DANO-RESISTENCIA | B79: 1908.2778 | C79: 1908.2778
... A90: Soma de Punição-Agrupamento | B90: 1.1111111 | C90: 1.1111111

Sheet BRAWLERS OFICIAL
O1: APROX | V1: APROX
B2: ID | C2: name | D2: main_specific_weakness | E2: specific_weakness | F2: _necessary_projectiles_to_charge_super | G2: _necessary_supers_to_charge_hipercharge | H2: _projectile_damage | I2: _shots_per_five_seconds | J2: _average_projectiles_per_shot | K2: _projectiles_per_shot_in_short_range | L2: _projectiles_per_shot_in_medium_range | M2: _projectiles_per_shot_in_long_range | N2: _projectiles_per_shot_in_very_long_range | O2: _shotting_time | P2: _auto_charge_super | Q2: super_damage_in_short_range | R2: super_damage_in_medium_range | S2: super_damage_in_long_range | T2: super_damage_in_very_long_range | U2: average_super_damage | V2: _super_time | W2: ocasional_damage | X2: _durability | Y2: _attack_distance | Z2: retreat_button | AA2: wide_attack | AB2: _indirect_damage_efficiency | AC2: area_denial | AD2: enemy_position_manipulation | AE2: water_walking | AF2: counter_water_walking | AG2: wall_break_efficiency | AH2: grass_break_efficiency | AI2: cover_creation_efficiency | AJ2: _movement_speed | AK2: _surprise_attack_power | AL2: _surprise_attack | AM2: _frequency_of_pets_generation | AN2: _accumulation_of_pets | AO2: _deteriorability_of_pets | AP2: _pets_resistence | AQ2: _pets_damage | AR2: _pets_range | AS2: _pets_speed | AT2: _pets_proximity | AU2: _increased_damage_when_grouped | AV2: grass_vision | AW2: circumstantiality_of_overall_proficiency | AX2: explanation_for_circumstantiality | AY2: heal_buffing | AZ2: counter_heal_buffing | BA2: shield_buffing | BB2: damage_buffing | BC2: counter_damage_buffing | BD2: speed_buffing | BE2: invisibility_buffing | BF2: positioning_buffing | BG2: poison_debuffing | BH2: counter_poison_debuffing | BI2: stun_debuffing | BJ2: counter_stun_debuffing | BK2: slowness_debuffing | BL2: counter_slowness_debuffing | BM2: attacks_canceling | BN2: counter_attacks_canceling | BO2: block_enemies | BP2: object_burst_damage_in_short_range | BQ2: object_burst_damage_in_medium_range | BR2: object_burst_damage_in_long_range | BS2: object_burst_damage_in_very_long_range | BT2: usual_burst_damage_in_short_range | BU2: usual_burst_damage_in_medium_range | BV2: usual_burst_damage_in_long_range | BW2: usual_burst_damage_in_very_long_range | BX2: ESPAÇO | BY2: balance_between_damage_and_durability_in_short_range | BZ2: balance_between_damage_and_durability_in_medium_range | CA2: balance_between_damage_and_durability_in_long_range | CB2: balance_between_damage_and_durability_in_very_long_range | CC2: ESPAÇO | CD2: surprise_attack_power_in_short_range | CE2: surprise_attack_power_in_medium_range | CF2: surprise_attack_power_in_long_range | CG2: surprise_attack_power_in_very_long_range | CH2: ESPAÇO | CI2: easy_approach | CJ2: pressure | CK2: area_control | CL2: indirect_damage | CM2: multiple_pets_generation | CN2: durable_pets_generation | CO2: groupment_punishment | CP2: none
B3: 28 | C3: NANI | D3: usual_burst_damage_in_very_long_range | E3: usual_burst_damage_in_long_range | F3: 5 | G3: =17/F3 -> 3.4 | H3: 1600 | I3: =(2.5-((O3*2.5)/2)) -> 1.5 | J3: 3 | K3: 3 | L3: 2.5 | M3: 1.5 | N3: 1 | O3: =2.4 / 3 -> 0.8 | P3: =1-(1*(V3/2)) -> 0.95 | Q3: 3600 | R3: 2700 | S3: 1800 | T3: 1800 | U3: 3600 | V3: 0.1 | W3: 0 | X3: =5000/1400 -> 3.5714286 | Y3: 10 | Z3: =(5 + 2 + 3)/3 -> 3.3333333 | AA3: 2 | AB3: 1 | AC3: 0 | AD3: 1 | AE3: 0 | AF3: 6 | AG3: 1 | AH3: 1 | AI3: 0 | AJ3: 5 | AK3: 0 | AL3: =(BK3/5+1)*AK3 -> 0 | AM3: 0 | AN3: 0 | AO3: 0 | AP3: 0 | AQ3: 0 | AR3: 0 | AS3: 0 | AT3: 0 | AU3: 0 | AV3: 0 | AW3: 0 | AX3: none | AY3: 0 | AZ3: 0 | BA3: 0 | BB3: 0 | BC3: 0 | BD3: 0 | BE3: 0 | BF3: 0 | BG3: 0 | BH3: 0 | BI3: 1 | BJ3: 0 | BK3: 0 | BL3: 0 | BM3: 1 | BN3: 3 | BO3: 0 | BP3: =(((J3*I3*H3)+Q3+(W3/4))/1500)+((AQ3*(AR3/3))/5) -> 7.2 | BQ3: =(((J3*I3*H3)+R3+(W3/4))/1500)+((AQ3*(AR3/5))/5) -> 6.6 | BR3: =((((J3*(Y3/7))*I3*H3)+S3+(W3/4))/1500)+((AQ3*(AR3/7))/5) -> 8.0571429 | BS3: =((((J3*(Y3/9))*I3*H3)+T3+(W3/4))/1200)+((AQ3*(AR3/9))/5) -> 8.1666667 | BT3: =(((K3*I3*H3)+(((I3*K3+P3)/F3)*Q3))/(1.25-((K3-J3)/4))+(W3/4))/1300 -> 6.8455385 | BU3: =(((L3*I3*H3)+(((I3*L3+P3)/F3)*(R3)))/(1.25-((L3-J3)/4))+(W3/4))/800 -> 7.7618182 | BV3: =(((M3*I3*H3)+(((I3*M3+P3)/F3)*(S3)))/(1.25-((M3-J3)/4))+(W3/4))/400 -> 7.3107692 | BW3: =(((N3*I3*H3)+(((I3*N3+P3)/F3)*(T3)))/(1.25-((N3-J3)/4))+(W3/4))/250 -> 7.5017143 | BY3: =((BT3/2)*X3)/2.5 -> 4.8896703 | BZ3: =((BU3)*(X3/2))/3.5 -> 3.9601113 | CA3: =((BV3*1.5)*(X3/3))/3 -> 4.3516484 | CB3: =((BW3*2)*(X3/4))/5 -> 2.6791837 | CD3: =(AL3*BY3)/3 -> 0 | CE3: =(AL3*BZ3)/2.7 -> 0 | CF3: =(AL3*CA3)/2.5 -> 0 | CG3: =(AL3*CB3)/1.9 -> 0 | CI3: =SUM(AL3*4, AJ3*2, X3*2, BD3*2)/6 -> 2.8571429 | CJ3: =SUM(AVERAGE(AA3, (AVERAGE(BY3, BZ3))/1.5)*4, X3*4, Y3*2, CI3*2)/9 -> 5.5444283 | CK3: =SUM(AC3*5, (AVERAGE(BY3, BZ3, CA3, CB3)/2)*2, BD3*2)/6 -> 0.66169224 | CL3: =IF(AB3<6, (AB3/2)*U3/2000, IF(AB3<7, (AB3/2)*(AVERAGE(BT3, BU3, BV3, BW3)/2.5), (AB3/2)*(AVERAGE(BT3, BU3, BV3, BW3)/2.5)+(U3/2000))) -> 0.9 | CM3: =SUM(AM3*4, AP3*2/(AO3+1), AN3*4)/7.5 -> 0 | CN3: =SUM(AP3*3, AQ3*2, AR3*2, AS3*2, AM3*3)/8 -> 0 | CO3: =(SUM(AA3*2, BK3*1, AU3*3)/4.5)*1.5 -> 1.3333333
B4: 44 | C4: ANGELO | D4: surprise_attack_power_in_long_range | E4: surprise_attack_power_in_medium_range | F4: 3 | G4: =9/F4 -> 3 | H4: 4000 | I4: =1.2 -> 1.2 | J4: 1 | K4: 1 | L4: 0.7 | M4: 0.5 | N4: 0.4 | O4: =12 / 3 -> 4 | P4: =0-(0*(V4/2)) -> 0 | Q4: 2000 | R4: 2000 | S4: 2000 | T4: 2000 | U4: 2000 | V4: 0.1 | W4: 0 | X4: =6200/1400 -> 4.4285714 | Y4: 9 | Z4: 0 | AA4: 0 | AB4: 0 | AC4: =(3 + 2 + 8 + 0)/4 -> 3.25 | AD4: 0 | AE4: 1 | AF4: 7 | AG4: 0 | AH4: 0 | AI4: 0 | AJ4: 9 | AK4: 0 | AL4: =(BK4/5+1)*AK4 -> 0 | AM4: 0 | AN4: 0 | AO4: 0 | AP4: 0 | AQ4: 0 | AR4: 0 | AS4: 0 | AT4: 0 | AU4: 0 | AV4: 0 | AW4: 2.5 | AX4: Some of this brawler's abilities are only available on maps with water. | AY4: 0 | AZ4: 0 | BA4: 0 | BB4: 0 | BC4: 0 | BD4: 0 | BE4: 0 | BF4: 0 | BG4: 4 | BH4: 0 | BI4: 0 | BJ4: 0 | BK4: 0 | BL4: 0 | BM4: 0 | BN4: 5 | BO4: 0 | BP4: =(((J4*I4*H4)+Q4+(W4/4))/1500)+((AQ4*(AR4/3))/5) -> 4.5333333 | BQ4: =(((J4*I4*H4)+R4+(W4/4))/1500)+((AQ4*(AR4/5))/5) -> 4.5333333 | BR4: =((((J4*(Y4/7))*I4*H4)+S4+(W4/4))/1500)+((AQ4*(AR4/7))/5) -> 5.447619 | BS4: =((((J4*(Y4/9))*I4*H4)+T4+(W4/4))/1200)+((AQ4*(AR4/9))/5) -> 5.6666667 | BT4: =(((K4*I4*H4)+(((I4*K4+P4)/F4)*Q4))/(1.25-((K4-J4)/4))+(W4/4))/1300 -> 3.4461538 | BU4: =(((L4*I4*H4)+(((I4*L4+P4)/F4)*(R4)))/(1.25-((L4-J4)/4))+(W4/4))/800 -> 3.6981132 | BV4: =(((M4*I4*H4)+(((I4*M4+P4)/F4)*(S4)))/(1.25-((M4-J4)/4))+(W4/4))/400 -> 5.0909091 | BW4: =(((N4*I4*H4)+(((I4*N4+P4)/F4)*(T4)))/(1.25-((N4-J4)/4))+(W4/4))/250 -> 6.4 | BY4: =((BT4/2)*X4)/2.5 -> 3.0523077 | BZ4: =((BU4)*(X4/2))/3.5 -> 2.3396226 | CA4: =((BV4*1.5)*(X4/3))/3 -> 3.7575758 | CB4: =((BW4*2)*(X4/4))/5 -> 2.8342857 | CD4: =(AL4*BY4)/3 -> 0 | CE4: =(AL4*BZ4)/2.7 -> 0 | CF4: =(AL4*CA4)/2.5 -> 0 | CG4: =(AL4*CB4)/1.9 -> 0 | CI4: =SUM(AL4*4, AJ4*2, X4*2, BD4*2)/6 -> 4.4761905 | CJ4: =SUM(AVERAGE(AA4, (AVERAGE(BY4, BZ4))/1.5)*4, X4*4, Y4*2, CI4*2)/9 -> 5.3623652 | CK4: =SUM(AC4*5, (AVERAGE(BY4, BZ4, CA4, CB4)/2)*2, BD4*2)/6 -> 3.207658 | CL4: =IF(AB4<6, (AB4/2)*U4/2000, IF(AB4<7, (AB4/2)*(AVERAGE(BT4, BU4, BV4, BW4)/2.5), (AB4/2)*(AVERAGE(BT4, BU4, BV4, BW4)/2.5)+(U4/2000))) -> 0 | CM4: =SUM(AM4*4, AP4*2/(AO4+1), AN4*4)/7.5 -> 0 | CN4: =SUM(AP4*3, AQ4*2, AR4*2, AS4*2, AM4*3)/8 -> 0 | CO4: =(SUM(AA4*2, BK4*1, AU4*3)/4.5)*1.5 -> 0
B5: 14 | C5: RICO | D5: wall_break_efficiency | E5: easy_approach | F5: 16 | G5: =36/F5 -> 2.25 | H5: 600 | I5: =(3.3-((O5*3.3)/2)) -> 1.87 | J5: 5 | K5: 5 | L5: 4 | M5: 2 | N5: 0.8 | O5: =2.6 / 3 -> 0.86666667 | P5: =16-(16*(V5/2)) -> 8 | Q5: 4320 | R5: 6480 | S5: 4320 | T5: 2160 | U5: 8640 | V5: 1 | W5: 0 | X5: =6000/1400 -> 4.2857143 | Y5: 8 | Z5: 0 | AA5: 3 | AB5: 0 | AC5: 0 | AD5: 0 | AE5: 0 | AF5: 6 | AG5: 0 | AH5: 0 | AI5: 0 | AJ5: 5 | AK5: 0 | AL5: =(BK5/5+1)*AK5 -> 0 | AM5: 0 | AN5: 0 | AO5: 0 | AP5: 0 | AQ5: 0 | AR5: 0 | AS5: 0 | AT5: 0 | AU5: 3 | AV5: 0 | AW5: 0 | AX5: none | AY5: 0 | AZ5: 0 | BA5: 0 | BB5: 0 | BC5: 0 | BD5: 0 | BE5: 0 | BF5: 0 | BG5: 0 | BH5: 0 | BI5: 0 | BJ5: 0 | BK5: 0 | BL5: 0 | BM5: 0 | BN5: 6 | BO5: 0 | BP5: =(((J5*I5*H5)+Q5+(W5/4))/1500)+((AQ5*(AR5/3))/5) -> 6.62 | BQ5: =(((J5*I5*H5)+R5+(W5/4))/1500)+((AQ5*(AR5/5))/5) -> 8.06 | BR5: =((((J5*(Y5/7))*I5*H5)+S5+(W5/4))/1500)+((AQ5*(AR5/7))/5) -> 7.1542857 | BS5: =((((J5*(Y5/9))*I5*H5)+T5+(W5/4))/1200)+((AQ5*(AR5/9))/5) -> 5.9555556 | BT5: =(((K5*I5*H5)+(((I5*K5+P5)/F5)*Q5))/(1.25-((K5-J5)/4))+(W5/4))/1300 -> 6.3350769 | BU5: =(((L5*I5*H5)+(((I5*L5+P5)/F5)*(R5)))/(1.25-((L5-J5)/4))+(W5/4))/800 -> 8.9645 | BV5: =(((M5*I5*H5)+(((I5*M5+P5)/F5)*(S5)))/(1.25-((M5-J5)/4))+(W5/4))/400 -> 6.76725 | BW5: =(((N5*I5*H5)+(((I5*N5+P5)/F5)*(T5)))/(1.25-((N5-J5)/4))+(W5/4))/250 -> 3.7905391 | BY5: =((BT5/2)*X5)/2.5 -> 5.4300659 | BZ5: =((BU5)*(X5/2))/3.5 -> 5.4884694 | CA5: =((BV5*1.5)*(X5/3))/3 -> 4.83375 | CB5: =((BW5*2)*(X5/4))/5 -> 1.6245168 | CD5: =(AL5*BY5)/3 -> 0 | CE5: =(AL5*BZ5)/2.7 -> 0 | CF5: =(AL5*CA5)/2.5 -> 0 | CG5: =(AL5*CB5)/1.9 -> 0 | CI5: =SUM(AL5*4, AJ5*2, X5*2, BD5*2)/6 -> 3.0952381 | CJ5: =SUM(AVERAGE(AA5, (AVERAGE(BY5, BZ5))/1.5)*4, X5*4, Y5*2, CI5*2)/9 -> 5.8458174 | CK5: =SUM(AC5*5, (AVERAGE(BY5, BZ5, CA5, CB5)/2)*2, BD5*2)/6 -> 0.72403342 | CL5: =IF(AB5<6, (AB5/2)*U5/2000, IF(AB5<7, (AB5/2)*(AVERAGE(BT5, BU5, BV5, BW5)/2.5), (AB5/2)*(AVERAGE(BT5, BU5, BV5, BW5)/2.5)+(U5/2000))) -> 0 | CM5: =SUM(AM5*4, AP5*2/(AO5+1), AN5*4)/7.5 -> 0 | CN5: =SUM(AP5*3, AQ5*2, AR5*2, AS5*2, AM5*3)/8 -> 0 | CO5: =(SUM(AA5*2, BK5*1, AU5*3)/4.5)*1.5 -> 5
B6: 86 | C6: SPIKE | D6: indirect_damage | E6: balance_between_damage_and_durability_in_very_long_range | F6: 8 | G6: =26/F6 -> 3.25 | H6: 980 | I6: =(2.15-((O6*2.15)/2)) -> 1.5408333 | J6: 3 | K6: 4 | L6: 2 | M6: 1.5 | N6: 0.5 | O6: =1.7 / 3 -> 0.56666667 | P6: =2.5-(2.5*(V6/2)) -> 2.125 | Q6: 4000 | R6: 3200 | S6: 1600 | T6: 800 | U6: 4000 | V6: 0.3 | W6: 0 | X6: =6000/1400 -> 4.2857143 | Y6: 7 | Z6: 0 | AA6: 4 | AB6: 3 | AC6: =(9 + 4 + 5 + 7)/4 -> 6.25 | AD6: 0 | AE6: 0 | AF6: 6 | AG6: 0 | AH6: 0 | AI6: 0 | AJ6: 5 | AK6: 0 | AL6: =(BK6/5+1)*AK6 -> 0 | AM6: 0 | AN6: 0 | AO6: 0 | AP6: 0 | AQ6: 0 | AR6: 0 | AS6: 0 | AT6: 0 | AU6: 4 | AV6: 0 | AW6: 0 | AX6: none | AY6: 0 | AZ6: 0 | BA6: 0 | BB6: 0 | BC6: 0 | BD6: 0 | BE6: 0 | BF6: 0 | BG6: 0 | BH6: 0 | BI6: 0 | BJ6: 0 | BK6: =(5 + 5 + 10)/3 -> 6.6666667 | BL6: 0 | BM6: 0 | BN6: 7 | BO6: 0 | BP6: =(((J6*I6*H6)+Q6+(W6/4))/1500)+((AQ6*(AR6/3))/5) -> 5.6867 | BQ6: =(((J6*I6*H6)+R6+(W6/4))/1500)+((AQ6*(AR6/5))/5) -> 5.1533667 | BR6: =((((J6*(Y6/7))*I6*H6)+S6+(W6/4))/1500)+((AQ6*(AR6/7))/5) -> 4.0867 | BS6: =((((J6*(Y6/9))*I6*H6)+T6+(W6/4))/1200)+((AQ6*(AR6/9))/5) -> 3.6028102 | BT6: =(((K6*I6*H6)+(((I6*K6+P6)/F6)*Q6))/(1.25-((K6-J6)/4))+(W6/4))/1300 -> 7.8340256 | BU6: =(((L6*I6*H6)+(((I6*L6+P6)/F6)*(R6)))/(1.25-((L6-J6)/4))+(W6/4))/800 -> 4.25225 | BV6: =(((M6*I6*H6)+(((I6*M6+P6)/F6)*(S6)))/(1.25-((M6-J6)/4))+(W6/4))/400 -> 4.8496538 | BW6: =(((N6*I6*H6)+(((I6*N6+P6)/F6)*(T6)))/(1.25-((N6-J6)/4))+(W6/4))/250 -> 2.2283733 | BY6: =((BT6/2)*X6)/2.5 -> 6.7148791 | BZ6: =((BU6)*(X6/2))/3.5 -> 2.6034184 | CA6: =((BV6*1.5)*(X6/3))/3 -> 3.4640385 | CB6: =((BW6*2)*(X6/4))/5 -> 0.95501714 | CD6: =(AL6*BY6)/3 -> 0 | CE6: =(AL6*BZ6)/2.7 -> 0 | CF6: =(AL6*CA6)/2.5 -> 0 | CG6: =(AL6*CB6)/1.9 -> 0 | CI6: =SUM(AL6*4, AJ6*2, X6*2, BD6*2)/6 -> 3.0952381 | CJ6: =SUM(AVERAGE(AA6, (AVERAGE(BY6, BZ6))/1.5)*4, X6*4, Y6*2, CI6*2)/9 -> 5.7272813 | CK6: =SUM(AC6*5, (AVERAGE(BY6, BZ6, CA6, CB6)/2)*2, BD6*2)/6 -> 5.780723 | CL6: =IF(AB6<6, (AB6/2)*U6/2000, IF(AB6<7, (AB6/2)*(AVERAGE(BT6, BU6, BV6, BW6)/2.5), (AB6/2)*(AVERAGE(BT6, BU6, BV6, BW6)/2.5)+(U6/2000))) -> 3 | CM6: =SUM(AM6*4, AP6*2/(AO6+1), AN6*4)/7.5 -> 0 | CN6: =SUM(AP6*3, AQ6*2, AR6*2, AS6*2, AM6*3)/8 -> 0 | CO6: =(SUM(AA6*2, BK6*1, AU6*3)/4.5)*1.5 -> 8.8888889
B7: 88 | C7: LEON | D7: balance_between_damage_and_durability_in_short_range | E7: poison_debuffing | F7: 9 | G7: =31/F7 -> 3.4444444 | H7: 960 | I7: =(2.5-((O7*2.5)/2)) -> 1.6666667 | J7: 4 | K7: 4 | L7: 2.5 | M7: 1.2 | N7: 0.5 | O7: =2 / 3 -> 0.66666667 | P7: =0-(0*(V7/2)) -> 0 | Q7: 0 | R7: 0 | S7: 0 | T7: 0 | U7: 0 | V7: 0.1 | W7: 0 | X7: =6600/1400 -> 4.7142857 | Y7: 7 | Z7: =(5 + 8 + 5)/3 -> 6 | AA7: 3 | AB7: 0 | AC7: 0 | AD7: 0 | AE7: 0 | AF7: 6 | AG7: 0 | AH7: 0 | AI7: 0 | AJ7: 9 | AK7: 7 | AL7: =(BK7/5+1)*AK7 -> 7 | AM7: 0 | AN7: 0 | AO7: 0 | AP7: 0 | AQ7: 0 | AR7: 0 | AS7: 0 | AT7: 0 | AU7: 0 | AV7: 0 | AW7: 0 | AX7: none | AY7: 0 | AZ7: 0 | BA7: 0 | BB7: 0 | BC7: 0 | BD7: 0 | BE7: 0 | BF7: 0 | BG7: 0 | BH7: 0 | BI7: 0 | BJ7: 0 | BK7: 0 | BL7: 0 | BM7: 0 | BN7: 6 | BO7: 0 | BP7: =(((J7*I7*H7)+Q7+(W7/4))/1500)+((AQ7*(AR7/3))/5) -> 4.2666667 | BQ7: =(((J7*I7*H7)+R7+(W7/4))/1500)+((AQ7*(AR7/5))/5) -> 4.2666667 | BR7: =((((J7*(Y7/7))*I7*H7)+S7+(W7/4))/1500)+((AQ7*(AR7/7))/5) -> 4.2666667 | BS7: =((((J7*(Y7/9))*I7*H7)+T7+(W7/4))/1200)+((AQ7*(AR7/9))/5) -> 4.1481481 | BT7: =(((K7*I7*H7)+(((I7*K7+P7)/F7)*Q7))/(1.25-((K7-J7)/4))+(W7/4))/1300 -> 3.9384615 | BU7: =(((L7*I7*H7)+(((I7*L7+P7)/F7)*(R7)))/(1.25-((L7-J7)/4))+(W7/4))/800 -> 3.0769231 | BV7: =(((M7*I7*H7)+(((I7*M7+P7)/F7)*(S7)))/(1.25-((M7-J7)/4))+(W7/4))/400 -> 2.4615385 | BW7: =(((N7*I7*H7)+(((I7*N7+P7)/F7)*(T7)))/(1.25-((N7-J7)/4))+(W7/4))/250 -> 1.5058824 | BY7: =((BT7/2)*X7)/2.5 -> 3.7134066 | BZ7: =((BU7)*(X7/2))/3.5 -> 2.0722135 | CA7: =((BV7*1.5)*(X7/3))/3 -> 1.9340659 | CB7: =((BW7*2)*(X7/4))/5 -> 0.70991597 | CD7: =(AL7*BY7)/3 -> 8.6646154 | CE7: =(AL7*BZ7)/2.7 -> 5.3724054 | CF7: =(AL7*CA7)/2.5 -> 5.4153846 | CG7: =(AL7*CB7)/1.9 -> 2.6154799 | CI7: =SUM(AL7*4, AJ7*2, X7*2, BD7*2)/6 -> 9.2380952 | CJ7: =SUM(AVERAGE(AA7, (AVERAGE(BY7, BZ7))/1.5)*4, X7*4, Y7*2, CI7*2)/9 -> 6.7989348 | CK7: =SUM(AC7*5, (AVERAGE(BY7, BZ7, CA7, CB7)/2)*2, BD7*2)/6 -> 0.35123342 | CL7: =IF(AB7<6, (AB7/2)*U7/2000, IF(AB7<7, (AB7/2)*(AVERAGE(BT7, BU7, BV7, BW7)/2.5), (AB7/2)*(AVERAGE(BT7, BU7, BV7, BW7)/2.5)+(U7/2000))) -> 0 | CM7: =SUM(AM7*4, AP7*2/(AO7+1), AN7*4)/7.5 -> 0 | CN7: =SUM(AP7*3, AQ7*2, AR7*2, AS7*2, AM7*3)/8 -> 0 | CO7: =(SUM(AA7*2, BK7*1, AU7*3)/4.5)*1.5 -> 2
B8: 33 | C8: GALE | D8: usual_burst_damage_in_long_range | E8: indirect_damage | F8: 15 | G8: =60/F8 -> 4 | H8: 600 | I8: =(3.3-((O8*3.3)/2)) -> 2.42 | J8: 4 | K8: 4 | L8: 4 | M8: 2 | N8: 0 | O8: =1.6 / 3 -> 0.53333333 | P8: =3-(3*(V8/2)) -> 2.7 | Q8: 1200 | R8: 1200 | S8: 1200 | T8: 1200 | U8: 1200 | V8: 0.2 | W8: 0 | X8: =8000/1400 -> 5.7142857 | Y8: 7 | Z8: =(5 + 7 + 4)/3 -> 5.3333333 | AA8: =(4 + 6)/2 -> 5 | AB8: 3 | AC8: 0 | AD8: 10 | AE8: 0 | AF8: 6 | AG8: 0 | AH8: 0 | AI8: 0 | AJ8: 5 | AK8: 0 | AL8: =(BK8/5+1)*AK8 -> 0 | AM8: 0 | AN8: 0 | AO8: 0 | AP8: 0 | AQ8: 0 | AR8: 0 | AS8: 0 | AT8: 0 | AU8: 1 | AV8: 0 | AW8: 0 | AX8: none | AY8: 0 | AZ8: 0 | BA8: 0 | BB8: 0 | BC8: 0 | BD8: 0 | BE8: 0 | BF8: 0 | BG8: 0 | BH8: 0 | BI8: 1 | BJ8: 0 | BK8: 0 | BL8: 0 | BM8: 10 | BN8: 7 | BO8: 0 | BP8: =(((J8*I8*H8)+Q8+(W8/4))/1500)+((AQ8*(AR8/3))/5) -> 4.672 | BQ8: =(((J8*I8*H8)+R8+(W8/4))/1500)+((AQ8*(AR8/5))/5) -> 4.672 | BR8: =((((J8*(Y8/7))*I8*H8)+S8+(W8/4))/1500)+((AQ8*(AR8/7))/5) -> 4.672 | BS8: =((((J8*(Y8/9))*I8*H8)+T8+(W8/4))/1200)+((AQ8*(AR8/9))/5) -> 4.7644444 | BT8: =(((K8*I8*H8)+(((I8*K8+P8)/F8)*Q8))/(1.25-((K8-J8)/4))+(W8/4))/1300 -> 4.1836308 | BU8: =(((L8*I8*H8)+(((I8*L8+P8)/F8)*(R8)))/(1.25-((L8-J8)/4))+(W8/4))/800 -> 6.7984 | BV8: =(((M8*I8*H8)+(((I8*M8+P8)/F8)*(S8)))/(1.25-((M8-J8)/4))+(W8/4))/400 -> 5.0102857 | BW8: =(((N8*I8*H8)+(((I8*N8+P8)/F8)*(T8)))/(1.25-((N8-J8)/4))+(W8/4))/250 -> 0.384 | BY8: =((BT8/2)*X8)/2.5 -> 4.7812923 | BZ8: =((BU8)*(X8/2))/3.5 -> 5.5497143 | CA8: =((BV8*1.5)*(X8/3))/3 -> 4.7717007 | CB8: =((BW8*2)*(X8/4))/5 -> 0.21942857 | CD8: =(AL8*BY8)/3 -> 0 | CE8: =(AL8*BZ8)/2.7 -> 0 | CF8: =(AL8*CA8)/2.5 -> 0 | CG8: =(AL8*CB8)/1.9 -> 0 | CI8: =SUM(AL8*4, AJ8*2, X8*2, BD8*2)/6 -> 3.5714286 | CJ8: =SUM(AVERAGE(AA8, (AVERAGE(BY8, BZ8))/1.5)*4, X8*4, Y8*2, CI8*2)/9 -> 6.7652597 | CK8: =SUM(AC8*5, (AVERAGE(BY8, BZ8, CA8, CB8)/2)*2, BD8*2)/6 -> 0.63842233 | CL8: =IF(AB8<6, (AB8/2)*U8/2000, IF(AB8<7, (AB8/2)*(AVERAGE(BT8, BU8, BV8, BW8)/2.5), (AB8/2)*(AVERAGE(BT8, BU8, BV8, BW8)/2.5)+(U8/2000))) -> 0.9 | CM8: =SUM(AM8*4, AP8*2/(AO8+1), AN8*4)/7.5 -> 0 | CN8: =SUM(AP8*3, AQ8*2, AR8*2, AS8*2, AM8*3)/8 -> 0 | CO8: =(SUM(AA8*2, BK8*1, AU8*3)/4.5)*1.5 -> 4.3333333
B9: 1 | C9: SHELLY | D9: wall_break_efficiency | E9: usual_burst_damage_in_very_long_range | F9: 10 | G9: =34/F9 -> 3.4 | H9: 600 | I9: =(2.5-((O9*2.5)/2)) -> 1.8333333 | J9: 5 | K9: 5 | L9: 3 | M9: 1.5 | N9: 0 | O9: =1.6 / 3 -> 0.53333333 | P9: =2-(2*(V9/2)) -> 1.8 | Q9: 5760 | R9: 3200 | S9: 1920 | T9: 0 | U9: 5760 | V9: 0.2 | W9: 0 | X9: =7800/1400 -> 5.5714286 | Y9: 6 | Z9: =(6 + 5 + 3)/3 -> 4.6666667 | AA9: 4 | AB9: 0 | AC9: 0 | AD9: 3 | AE9: 0 | AF9: 5 | AG9: 5 | AH9: 5 | AI9: 0 | AJ9: 7 | AK9: 0 | AL9: =(BK9/5+1)*AK9 -> 0 | AM9: 0 | AN9: 0 | AO9: 0 | AP9: 0 | AQ9: 0 | AR9: 0 | AS9: 0 | AT9: 0 | AU9: 2 | AV9: 0 | AW9: 0 | AX9: none | AY9: 0 | AZ9: 0 | BA9: 0 | BB9: 0 | BC9: 0 | BD9: 0 | BE9: 0 | BF9: 0 | BG9: 0 | BH9: 0 | BI9: 2 | BJ9: 0 | BK9: 0 | BL9: 0 | BM9: 3 | BN9: 7 | BO9: 0 | BP9: =(((J9*I9*H9)+Q9+(W9/4))/1500)+((AQ9*(AR9/3))/5) -> 7.5066667 | BQ9: =(((J9*I9*H9)+R9+(W9/4))/1500)+((AQ9*(AR9/5))/5) -> 5.8 | BR9: =((((J9*(Y9/7))*I9*H9)+S9+(W9/4))/1500)+((AQ9*(AR9/7))/5) -> 4.4228571 | BS9: =((((J9*(Y9/9))*I9*H9)+T9+(W9/4))/1200)+((AQ9*(AR9/9))/5) -> 3.0555556 | BT9: =(((K9*I9*H9)+(((I9*K9+P9)/F9)*Q9))/(1.25-((K9-J9)/4))+(W9/4))/1300 -> 7.2718769 | BU9: =(((L9*I9*H9)+(((I9*L9+P9)/F9)*(R9)))/(1.25-((L9-J9)/4))+(W9/4))/800 -> 4.0257143 | BV9: =(((M9*I9*H9)+(((I9*M9+P9)/F9)*(S9)))/(1.25-((M9-J9)/4))+(W9/4))/400 -> 2.9689412 | BW9: =(((N9*I9*H9)+(((I9*N9+P9)/F9)*(T9)))/(1.25-((N9-J9)/4))+(W9/4))/250 -> 0 | BY9: =((BT9/2)*X9)/2.5 -> 8.1029486 | BZ9: =((BU9)*(X9/2))/3.5 -> 3.2041399 | CA9: =((BV9*1.5)*(X9/3))/3 -> 2.7568739 | CB9: =((BW9*2)*(X9/4))/5 -> 0 | CD9: =(AL9*BY9)/3 -> 0 | CE9: =(AL9*BZ9)/2.7 -> 0 | CF9: =(AL9*CA9)/2.5 -> 0 | CG9: =(AL9*CB9)/1.9 -> 0 | CI9: =SUM(AL9*4, AJ9*2, X9*2, BD9*2)/6 -> 4.1904762 | CJ9: =SUM(AVERAGE(AA9, (AVERAGE(BY9, BZ9))/1.5)*4, X9*4, Y9*2, CI9*2)/9 -> 6.4671917 | CK9: =SUM(AC9*5, (AVERAGE(BY9, BZ9, CA9, CB9)/2)*2, BD9*2)/6 -> 0.58599844 | CL9: =IF(AB9<6, (AB9/2)*U9/2000, IF(AB9<7, (AB9/2)*(AVERAGE(BT9, BU9, BV9, BW9)/2.5), (AB9/2)*(AVERAGE(BT9, BU9, BV9, BW9)/2.5)+(U9/2000))) -> 0 | CM9: =SUM(AM9*4, AP9*2/(AO9+1), AN9*4)/7.5 -> 0 | CN9: =SUM(AP9*3, AQ9*2, AR9*2, AS9*2, AM9*3)/8 -> 0 | CO9: =(SUM(AA9*2, BK9*1, AU9*3)/4.5)*1.5 -> 4.6666667
B10: 8 | C10: POCO | D10: counter_heal_buffing | E10: pressure | F10: 4 | G10: =10/F10 -> 2.5 | H10: 1520 | I10: =(2.5-((O10*2.5)/2)) -> 1.8333333 | J10: 1 | K10: 1 | L10: 1 | M10: 0.5 | N10: 0 | O10: =1.6 / 3 -> 0.53333333 | P10: =0-(0*(V10/2)) -> 0 | Q10: 0 | R10: 0 | S10: 0 | T10: 0 | U10: 0 | V10: 0.2 | W10: 0 | X10: =8000/1400+(AY10/3.5) -> 8 | Y10: 6 | Z10: 0 | AA10: 7 | AB10: 0 | AC10: 0 | AD10: 0 | AE10: 0 | AF10: 6 | AG10: 0 | AH10: 0 | AI10: 0 | AJ10: 5 | AK10: 0 | AL10: =(BK10/5+1)*AK10 -> 0 | AM10: 0 | AN10: 0 | AO10: 0 | AP10: 0 | AQ10: 0 | AR10: 0 | AS10: 0 | AT10: 0 | AU10: 0 | AV10: 0 | AW10: 0 | AX10: none | AY10: =(6 + 9 + 9)/3 -> 8 | AZ10: 0 | BA10: 0 | BB10: 0 | BC10: 0 | BD10: 0 | BE10: 0 | BF10: 0 | BG10: 0 | BH10: 0 | BI10: 0 | BJ10: 0 | BK10: 0 | BL10: 0 | BM10: 0 | BN10: 7 | BO10: 0 | BP10: =(((J10*I10*H10)+Q10+(W10/4))/1500)+((AQ10*(AR10/3))/5) -> 1.8577778 | BQ10: =(((J10*I10*H10)+R10+(W10/4))/1500)+((AQ10*(AR10/5))/5) -> 1.8577778 | BR10: =((((J10*(Y10/7))*I10*H10)+S10+(W10/4))/1500)+((AQ10*(AR10/7))/5) -> 1.592381 | BS10: =((((J10*(Y10/9))*I10*H10)+T10+(W10/4))/1200)+((AQ10*(AR10/9))/5) -> 1.5481481 | BT10: =(((K10*I10*H10)+(((I10*K10+P10)/F10)*Q10))/(1.25-((K10-J10)/4))+(W10/4))/1300 -> 1.7148718 | BU10: =(((L10*I10*H10)+(((I10*L10+P10)/F10)*(R10)))/(1.25-((L10-J10)/4))+(W10/4))/800 -> 2.7866667 | BV10: =(((M10*I10*H10)+(((I10*M10+P10)/F10)*(S10)))/(1.25-((M10-J10)/4))+(W10/4))/400 -> 2.5333333 | BW10: =(((N10*I10*H10)+(((I10*N10+P10)/F10)*(T10)))/(1.25-((N10-J10)/4))+(W10/4))/250 -> 0 | BY10: =((BT10/2)*X10)/2.5 -> 2.7437949 | BZ10: =((BU10)*(X10/2))/3.5 -> 3.1847619 | CA10: =((BV10*1.5)*(X10/3))/3 -> 3.3777778 | CB10: =((BW10*2)*(X10/4))/5 -> 0 | CD10: =(AL10*BY10)/3 -> 0 | CE10: =(AL10*BZ10)/2.7 -> 0 | CF10: =(AL10*CA10)/2.5 -> 0 | CG10: =(AL10*CB10)/1.9 -> 0 | CI10: =SUM(AL10*4, AJ10*2, X10*2, BD10*2)/6 -> 4.3333333 | CJ10: =SUM(AVERAGE(AA10, (AVERAGE(BY10, BZ10))/1.5)*4, X10*4, Y10*2, CI10*2)/9 -> 7.8465598 | CK10: =SUM(AC10*5, (AVERAGE(BY10, BZ10, CA10, CB10)/2)*2, BD10*2)/6 -> 0.38776394 | CL10: =IF(AB10<6, (AB10/2)*U10/2000, IF(AB10<7, (AB10/2)*(AVERAGE(BT10, BU10, BV10, BW10)/2.5), (AB10/2)*(AVERAGE(BT10, BU10, BV10, BW10)/2.5)+(U10/2000))) -> 0 | CM10: =SUM(AM10*4, AP10*2/(AO10+1), AN10*4)/7.5 -> 0 | CN10: =SUM(AP10*3, AQ10*2, AR10*2, AS10*2, AM10*3)/8 -> 0 | CO10: =(SUM(AA10*2, BK10*1, AU10*3)/4.5)*1.5 -> 4.6666667
B11: 45 | C11: BERRY | D11: counter_heal_buffing | E11: surprise_attack_power_in_medium_range | F11: 9 | G11: =21/F11 -> 2.3333333 | H11: 1320 | I11: =(1.65-((O11*1.65)/2)) -> 1.265 | J11: 6 | K11: 2 | L11: 1.5 | M11: 0.8 | N11: 0 | O11: =1.4 / 3 -> 0.46666667 | P11: =2.5-(2.5*(V11/2)) -> 2.375 | Q11: 4360 | R11: 4360 | S11: 2180 | T11: 0 | U11: 4360 | V11: 0.1 | W11: 0 | X11: =5200/1400+(AY11/3.5) -> 5.7142857 | Y11: 5 | Z11: =(6 + 7 + 6)/3 -> 6.3333333 | AA11: 1 | AB11: 6 | AC11: =(6 + 1 + 6 + 5)/4 -> 4.5 | AD11: 0 | AE11: 0 | AF11: 6 | AG11: 0 | AH11: 0 | AI11: 0 | AJ11: 5 | AK11: 5 | AL11: =(BK11/5+1)*AK11 -> 5 | AM11: 0 | AN11: 0 | AO11: 0 | AP11: 0 | AQ11: 0 | AR11: 0 | AS11: 0 | AT11: 0 | AU11: 1 | AV11: 0 | AW11: 0 | AX11: none | AY11: =(10 + 8 + 3)/3 -> 7 | AZ11: 0 | BA11: 0 | BB11: 0 | BC11: 0 | BD11: 0 | BE11: 0 | BF11: 0 | BG11: 0 | BH11: 0 | BI11: 0 | BJ11: 0 | BK11: 0 | BL11: 0 | BM11: 0 | BN11: 7 | BO11: 0 | BP11: =(((J11*I11*H11)+Q11+(W11/4))/1500)+((AQ11*(AR11/3))/5) -> 9.5858667 | BQ11: =(((J11*I11*H11)+R11+(W11/4))/1500)+((AQ11*(AR11/5))/5) -> 9.5858667 | BR11: =((((J11*(Y11/7))*I11*H11)+S11+(W11/4))/1500)+((AQ11*(AR11/7))/5) -> 6.2241905 | BS11: =((((J11*(Y11/9))*I11*H11)+T11+(W11/4))/1200)+((AQ11*(AR11/9))/5) -> 4.6383333 | BT11: =(((K11*I11*H11)+(((I11*K11+P11)/F11)*Q11))/(1.25-((K11-J11)/4))+(W11/4))/1300 -> 1.9541197 | BU11: =(((L11*I11*H11)+(((I11*L11+P11)/F11)*(R11)))/(1.25-((L11-J11)/4))+(W11/4))/800 -> 2.4076257 | BV11: =(((M11*I11*H11)+(((I11*M11+P11)/F11)*(S11)))/(1.25-((M11-J11)/4))+(W11/4))/400 -> 2.1139673 | BW11: =(((N11*I11*H11)+(((I11*N11+P11)/F11)*(T11)))/(1.25-((N11-J11)/4))+(W11/4))/250 -> 0 | BY11: =((BT11/2)*X11)/2.5 -> 2.2332796 | BZ11: =((BU11)*(X11/2))/3.5 -> 1.9654088 | CA11: =((BV11*1.5)*(X11/3))/3 -> 2.0133022 | CB11: =((BW11*2)*(X11/4))/5 -> 0 | CD11: =(AL11*BY11)/3 -> 3.7221327 | CE11: =(AL11*BZ11)/2.7 -> 3.6396459 | CF11: =(AL11*CA11)/2.5 -> 4.0266044 | CG11: =(AL11*CB11)/1.9 -> 0 | CI11: =SUM(AL11*4, AJ11*2, X11*2, BD11*2)/6 -> 6.9047619 | CJ11: =SUM(AVERAGE(AA11, (AVERAGE(BY11, BZ11))/1.5)*4, X11*4, Y11*2, CI11*2)/9 -> 5.7184214 | CK11: =SUM(AC11*5, (AVERAGE(BY11, BZ11, CA11, CB11)/2)*2, BD11*2)/6 -> 4.0088329 | CL11: =IF(AB11<6, (AB11/2)*U11/2000, IF(AB11<7, (AB11/2)*(AVERAGE(BT11, BU11, BV11, BW11)/2.5), (AB11/2)*(AVERAGE(BT11, BU11, BV11, BW11)/2.5)+(U11/2000))) -> 1.9427138 | CM11: =SUM(AM11*4, AP11*2/(AO11+1), AN11*4)/7.5 -> 0 | CN11: =SUM(AP11*3, AQ11*2, AR11*2, AS11*2, AM11*3)/8 -> 0 | CO11: =(SUM(AA11*2, BK11*1, AU11*3)/4.5)*1.5 -> 1.6666667
B12: 25 | C12: FRANK | D12: usual_burst_damage_in_long_range | E12: attacks_canceling | F12: 3 | G12: =10/F12 -> 3.3333333 | H12: 2320 | I12: =(3.3-((O12*3.3)/2)) -> 2.0075 | J12: 1 | K12: 1 | L12: 1 | M12: 0 | N12: 0 | O12: =AVERAGE(3, 1.7) / 3 -> 0.78333333 | P12: =1-(1*(V12/2)) -> 0.25 | Q12: 2480 | R12: 2480 | S12: 1240 | T12: 0 | U12: 2480 | V12: 1.5 | W12: 0 | X12: =13600/1400 -> 9.7142857 | Y12: 5 | Z12: 0 | AA12: 7 | AB12: 0 | AC12: 0 | AD12: 0 | AE12: 0 | AF12: 6 | AG12: 9 | AH12: 8 | AI12: 0 | AJ12: 6 | AK12: 0 | AL12: =(BK12/5+1)*AK12 -> 0 | AM12: 0 | AN12: 0 | AO12: 0 | AP12: 0 | AQ12: 0 | AR12: 0 | AS12: 0 | AT12: 0 | AU12: 2 | AV12: 0 | AW12: 0 | AX12: none | AY12: 0 | AZ12: 0 | BA12: 0 | BB12: 0 | BC12: 0 | BD12: 0 | BE12: 0 | BF12: 0 | BG12: 0 | BH12: 0 | BI12: 5 | BJ12: 0 | BK12: 0 | BL12: 0 | BM12: 0 | BN12: 1 | BO12: 0 | BP12: =(((J12*I12*H12)+Q12+(W12/4))/1500)+((AQ12*(AR12/3))/5) -> 4.7582667 | BQ12: =(((J12*I12*H12)+R12+(W12/4))/1500)+((AQ12*(AR12/5))/5) -> 4.7582667 | BR12: =((((J12*(Y12/7))*I12*H12)+S12+(W12/4))/1500)+((AQ12*(AR12/7))/5) -> 3.0444762 | BS12: =((((J12*(Y12/9))*I12*H12)+T12+(W12/4))/1200)+((AQ12*(AR12/9))/5) -> 2.1562037 | BT12: =(((K12*I12*H12)+(((I12*K12+P12)/F12)*Q12))/(1.25-((K12-J12)/4))+(W12/4))/1300 -> 4.0145231 | BU12: =(((L12*I12*H12)+(((I12*L12+P12)/F12)*(R12)))/(1.25-((L12-J12)/4))+(W12/4))/800 -> 6.5236 | BV12: =(((M12*I12*H12)+(((I12*M12+P12)/F12)*(S12)))/(1.25-((M12-J12)/4))+(W12/4))/400 -> 0.17222222 | BW12: =(((N12*I12*H12)+(((I12*N12+P12)/F12)*(T12)))/(1.25-((N12-J12)/4))+(W12/4))/250 -> 0 | BY12: =((BT12/2)*X12)/2.5 -> 7.7996448 | BZ12: =((BU12)*(X12/2))/3.5 -> 9.0531592 | CA12: =((BV12*1.5)*(X12/3))/3 -> 0.27883598 | CB12: =((BW12*2)*(X12/4))/5 -> 0 | CD12: =(AL12*BY12)/3 -> 0 | CE12: =(AL12*BZ12)/2.7 -> 0 | CF12: =(AL12*CA12)/2.5 -> 0 | CG12: =(AL12*CB12)/1.9 -> 0 | CI12: =SUM(AL12*4, AJ12*2, X12*2, BD12*2)/6 -> 5.2380952 | CJ12: =SUM(AVERAGE(AA12, (AVERAGE(BY12, BZ12))/1.5)*4, X12*4, Y12*2, CI12*2)/9 -> 9.396504 | CK12: =SUM(AC12*5, (AVERAGE(BY12, BZ12, CA12, CB12)/2)*2, BD12*2)/6 -> 0.71381833 | CL12: =IF(AB12<6, (AB12/2)*U12/2000, IF(AB12<7, (AB12/2)*(AVERAGE(BT12, BU12, BV12, BW12)/2.5), (AB12/2)*(AVERAGE(BT12, BU12, BV12, BW12)/2.5)+(U12/2000))) -> 0 | CM12: =SUM(AM12*4, AP12*2/(AO12+1), AN12*4)/7.5 -> 0 | CN12: =SUM(AP12*3, AQ12*2, AR12*2, AS12*2, AM12*3)/8 -> 0 | CO12: =(SUM(AA12*2, BK12*1, AU12*3)/4.5)*1.5 -> 6.6666667
B13: 89 | C13: SANDY | D13: pressure | E13: poison_debuffing | F13: 6 | G13: =15/F13 -> 2.5 | H13: 1800 | I13: =(2.5-((O13*2.5)/2)) -> 1.8333333 | J13: 1 | K13: 1 | L13: 1 | M13: 0 | N13: 0 | O13: =1.6 / 3 -> 0.53333333 | P13: =0-(0*(V13/2)) -> 0 | Q13: 0 | R13: 0 | S13: 0 | T13: 0 | U13: 0 | V13: 0.1 | W13: 0 | X13: =8200/1400 -> 5.8571429 | Y13: 4 | Z13: 2 | AA13: 5 | AB13: 0 | AC13: =(9 + 10 + 9 + 5)/4 -> 8.25 | AD13: 0 | AE13: 0 | AF13: 6 | AG13: 0 | AH13: 0 | AI13: 0 | AJ13: 6 | AK13: 0 | AL13: =(BK13/5+1)*AK13 -> 0 | AM13: 0 | AN13: 0 | AO13: 0 | AP13: 0 | AQ13: 0 | AR13: 0 | AS13: 0 | AT13: 0 | AU13: 0 | AV13: 0 | AW13: 0 | AX13: none | AY13: 0 | AZ13: 0 | BA13: 0 | BB13: 0 | BC13: 0 | BD13: 0 | BE13: =(5 + 9 + 10)/3 -> 8 | BF13: 0 | BG13: 0 | BH13: 0 | BI13: 0 | BJ13: 0 | BK13: 0 | BL13: 0 | BM13: 0 | BN13: 7 | BO13: 0 | BP13: =(((J13*I13*H13)+Q13+(W13/4))/1500)+((AQ13*(AR13/3))/5) -> 2.2 | BQ13: =(((J13*I13*H13)+R13+(W13/4))/1500)+((AQ13*(AR13/5))/5) -> 2.2 | BR13: =((((J13*(Y13/7))*I13*H13)+S13+(W13/4))/1500)+((AQ13*(AR13/7))/5) -> 1.2571429 | BS13: =((((J13*(Y13/9))*I13*H13)+T13+(W13/4))/1200)+((AQ13*(AR13/9))/5) -> 1.2222222 | BT13: =(((K13*I13*H13)+(((I13*K13+P13)/F13)*Q13))/(1.25-((K13-J13)/4))+(W13/4))/1300 -> 2.0307692 | BU13: =(((L13*I13*H13)+(((I13*L13+P13)/F13)*(R13)))/(1.25-((L13-J13)/4))+(W13/4))/800 -> 3.3 | BV13: =(((M13*I13*H13)+(((I13*M13+P13)/F13)*(S13)))/(1.25-((M13-J13)/4))+(W13/4))/400 -> 0 | BW13: =(((N13*I13*H13)+(((I13*N13+P13)/F13)*(T13)))/(1.25-((N13-J13)/4))+(W13/4))/250 -> 0 | BY13: =((BT13/2)*X13)/2.5 -> 2.3789011 | BZ13: =((BU13)*(X13/2))/3.5 -> 2.7612245 | CA13: =((BV13*1.5)*(X13/3))/3 -> 0 | CB13: =((BW13*2)*(X13/4))/5 -> 0 | CD13: =(AL13*BY13)/3 -> 0 | CE13: =(AL13*BZ13)/2.7 -> 0 | CF13: =(AL13*CA13)/2.5 -> 0 | CG13: =(AL13*CB13)/1.9 -> 0 | CI13: =SUM(AL13*4, AJ13*2, X13*2, BD13*2)/6 -> 3.952381 | CJ13: =SUM(AVERAGE(AA13, (AVERAGE(BY13, BZ13))/1.5)*4, X13*4, Y13*2, CI13*2)/9 -> 5.8622315 | CK13: =SUM(AC13*5, (AVERAGE(BY13, BZ13, CA13, CB13)/2)*2, BD13*2)/6 -> 7.0891719 | CL13: =IF(AB13<6, (AB13/2)*U13/2000, IF(AB13<7, (AB13/2)*(AVERAGE(BT13, BU13, BV13, BW13)/2.5), (AB13/2)*(AVERAGE(BT13, BU13, BV13, BW13)/2.5)+(U13/2000))) -> 0 | CM13: =SUM(AM13*4, AP13*2/(AO13+1), AN13*4)/7.5 -> 0 | CN13: =SUM(AP13*3, AQ13*2, AR13*2, AS13*2, AM13*3)/8 -> 0 | CO13: =(SUM(AA13*2, BK13*1, AU13*3)/4.5)*1.5 -> 3.3333333
B14: 18 | C14: JACKY | D14: usual_burst_damage_in_long_range | E14: retreat_button | F14: 4 | G14: =10/F14 -> 2.5 | H14: 2480 | I14: =(2.5-((O14*2.5)/2)) -> 1.8333333 | J14: 1 | K14: 1 | L14: 0.5 | M14: 0 | N14: 0 | O14: =1.6 / 3 -> 0.53333333 | P14: =0-(0*(V14/2)) -> 0 | Q14: 0 | R14: 0 | S14: 0 | T14: 0 | U14: 0 | V14: 0.1 | W14: 0 | X14: =10000/1400 -> 7.1428571 | Y14: 3 | Z14: 0 | AA14: 9 | AB14: 6 | AC14: 0 | AD14: 4 | AE14: 0 | AF14: 3 | AG14: 0 | AH14: 0 | AI14: 0 | AJ14: 6 | AK14: 0 | AL14: =(BK14/5+1)*AK14 -> 0 | AM14: 0 | AN14: 0 | AO14: 0 | AP14: 0 | AQ14: 0 | AR14: 0 | AS14: 0 | AT14: 0 | AU14: 2 | AV14: 0 | AW14: 0 | AX14: none | AY14: 0 | AZ14: 0 | BA14: 0 | BB14: 0 | BC14: 0 | BD14: 0 | BE14: 0 | BF14: 0 | BG14: 0 | BH14: 0 | BI14: 1 | BJ14: 0 | BK14: 0 | BL14: 0 | BM14: 3 | BN14: 7 | BO14: 0 | BP14: =(((J14*I14*H14)+Q14+(W14/4))/1500)+((AQ14*(AR14/3))/5) -> 3.0311111 | BQ14: =(((J14*I14*H14)+R14+(W14/4))/1500)+((AQ14*(AR14/5))/5) -> 3.0311111 | BR14: =((((J14*(Y14/7))*I14*H14)+S14+(W14/4))/1500)+((AQ14*(AR14/7))/5) -> 1.2990476 | BS14: =((((J14*(Y14/9))*I14*H14)+T14+(W14/4))/1200)+((AQ14*(AR14/9))/5) -> 1.262963 | BT14: =(((K14*I14*H14)+(((I14*K14+P14)/F14)*Q14))/(1.25-((K14-J14)/4))+(W14/4))/1300 -> 2.7979487 | BU14: =(((L14*I14*H14)+(((I14*L14+P14)/F14)*(R14)))/(1.25-((L14-J14)/4))+(W14/4))/800 -> 2.0666667 | BV14: =(((M14*I14*H14)+(((I14*M14+P14)/F14)*(S14)))/(1.25-((M14-J14)/4))+(W14/4))/400 -> 0 | BW14: =(((N14*I14*H14)+(((I14*N14+P14)/F14)*(T14)))/(1.25-((N14-J14)/4))+(W14/4))/250 -> 0 | BY14: =((BT14/2)*X14)/2.5 -> 3.9970696 | BZ14: =((BU14)*(X14/2))/3.5 -> 2.1088435 | CA14: =((BV14*1.5)*(X14/3))/3 -> 0 | CB14: =((BW14*2)*(X14/4))/5 -> 0 | CD14: =(AL14*BY14)/3 -> 0 | CE14: =(AL14*BZ14)/2.7 -> 0 | CF14: =(AL14*CA14)/2.5 -> 0 | CG14: =(AL14*CB14)/1.9 -> 0 | CI14: =SUM(AL14*4, AJ14*2, X14*2, BD14*2)/6 -> 4.3809524 | CJ14: =SUM(AVERAGE(AA14, (AVERAGE(BY14, BZ14))/1.5)*4, X14*4, Y14*2, CI14*2)/9 -> 7.2671047 | CK14: =SUM(AC14*5, (AVERAGE(BY14, BZ14, CA14, CB14)/2)*2, BD14*2)/6 -> 0.25441305 | CL14: =IF(AB14<6, (AB14/2)*U14/2000, IF(AB14<7, (AB14/2)*(AVERAGE(BT14, BU14, BV14, BW14)/2.5), (AB14/2)*(AVERAGE(BT14, BU14, BV14, BW14)/2.5)+(U14/2000))) -> 1.4593846 | CM14: =SUM(AM14*4, AP14*2/(AO14+1), AN14*4)/7.5 -> 0 | CN14: =SUM(AP14*3, AQ14*2, AR14*2, AS14*2, AM14*3)/8 -> 0 | CO14: =(SUM(AA14*2, BK14*1, AU14*3)/4.5)*1.5 -> 8
B15: 16 | C15: PENNY | D15: indirect_damage | E15: easy_approach | F15: 5 | G15: =16/F15 -> 3.2 | H15: 1960 | I15: =(2.15-((O15*2.15)/2)) -> 1.5408333 | J15: 1 | K15: 1 | L15: 1 | M15: 0.5 | N15: 0 | O15: =1.7 / 3 -> 0.56666667 | P15: =2.5-(2.5*(V15/2)) -> 2.25 | Q15: 1200 | R15: 1200 | S15: 2400 | T15: 2400 | U15: 7200 | V15: 0.2 | W15: 0 | X15: =7000/1400 -> 5 | Y15: 6 | Z15: 0 | AA15: 1 | AB15: 2 | AC15: =(3 + 2 + 3 + 9)/4 -> 4.25 | AD15: 0 | AE15: 0 | AF15: 6 | AG15: 0 | AH15: 0 | AI15: 0 | AJ15: 5 | AK15: 0 | AL15: =(BK15/5+1)*AK15 -> 0 | AM15: 4 | AN15: 1 | AO15: 0 | AP15: 6 | AQ15: 7 | AR15: 10 | AS15: 0 | AT15: 0 | AU15: 9 | AV15: 0 | AW15: 0 | AX15: none | AY15: 0 | AZ15: 0 | BA15: 0 | BB15: 0 | BC15: 0 | BD15: 0 | BE15: 0 | BF15: 0 | BG15: 0 | BH15: 0 | BI15: 0 | BJ15: 0 | BK15: 0 | BL15: 0 | BM15: 0 | BN15: 7 | BO15: 0 | BP15: =(((J15*I15*H15)+Q15+(W15/4))/1500)+((AQ15*(AR15/3))/5) -> 7.4800222 | BQ15: =(((J15*I15*H15)+R15+(W15/4))/1500)+((AQ15*(AR15/5))/5) -> 5.6133556 | BR15: =((((J15*(Y15/7))*I15*H15)+S15+(W15/4))/1500)+((AQ15*(AR15/7))/5) -> 5.3257333 | BS15: =((((J15*(Y15/9))*I15*H15)+T15+(W15/4))/1200)+((AQ15*(AR15/9))/5) -> 5.2333519 | BT15: =(((K15*I15*H15)+(((I15*K15+P15)/F15)*Q15))/(1.25-((K15-J15)/4))+(W15/4))/1300 -> 2.418359 | BU15: =(((L15*I15*H15)+(((I15*L15+P15)/F15)*(R15)))/(1.25-((L15-J15)/4))+(W15/4))/800 -> 3.9298333 | BV15: =(((M15*I15*H15)+(((I15*M15+P15)/F15)*(S15)))/(1.25-((M15-J15)/4))+(W15/4))/400 -> 5.3814848 | BW15: =(((N15*I15*H15)+(((I15*N15+P15)/F15)*(T15)))/(1.25-((N15-J15)/4))+(W15/4))/250 -> 2.88 | BY15: =((BT15/2)*X15)/2.5 -> 2.418359 | BZ15: =((BU15)*(X15/2))/3.5 -> 2.8070238 | CA15: =((BV15*1.5)*(X15/3))/3 -> 4.4845707 | CB15: =((BW15*2)*(X15/4))/5 -> 1.44 | CD15: =(AL15*BY15)/3 -> 0 | CE15: =(AL15*BZ15)/2.7 -> 0 | CF15: =(AL15*CA15)/2.5 -> 0 | CG15: =(AL15*CB15)/1.9 -> 0 | CI15: =SUM(AL15*4, AJ15*2, X15*2, BD15*2)/6 -> 3.3333333 | CJ15: =SUM(AVERAGE(AA15, (AVERAGE(BY15, BZ15))/1.5)*4, X15*4, Y15*2, CI15*2)/9 -> 4.9055839 | CK15: =SUM(AC15*5, (AVERAGE(BY15, BZ15, CA15, CB15)/2)*2, BD15*2)/6 -> 4.0062481 | CL15: =IF(AB15<6, (AB15/2)*U15/2000, IF(AB15<7, (AB15/2)*(AVERAGE(BT15, BU15, BV15, BW15)/2.5), (AB15/2)*(AVERAGE(BT15, BU15, BV15, BW15)/2.5)+(U15/2000))) -> 3.6 | CM15: =SUM(AM15*4, AP15*2/(AO15+1), AN15*4)/7.5 -> 4.2666667 | CN15: =SUM(AP15*3, AQ15*2, AR15*2, AS15*2, AM15*3)/8 -> 8 | CO15: =(SUM(AA15*2, BK15*1, AU15*3)/4.5)*1.5 -> 9.6666667
B16: 49 | C16: MORTIS | D16: balance_between_damage_and_durability_in_short_range | E16: retreat_button | F16: 5 | G16: =16/F16 -> 3.2 | H16: 2000 | I16: =(1.65-((O16*1.65)/2)) -> 1.1 | J16: 1 | K16: 1 | L16: 0 | M16: 0 | N16: 0 | O16: =2 / 3 -> 0.66666667 | P16: =1-(1*(V16/2)) -> 0.95 | Q16: 1800 | R16: 1800 | S16: 1800 | T16: 1800 | U16: 1800 | V16: 0.1 | W16: 0 | X16: =8000/1400 + (5 + 6 + 6)/3/3.5 -> 7.3333333 | Y16: 1 | Z16: =(8.5 + 3 + 6)/3 -> 5.8333333 | AA16: 1 | AB16: 3 | AC16: 0 | AD16: 0 | AE16: 0 | AF16: 1 | AG16: 0 | AH16: 0 | AI16: 0 | AJ16: 9 | AK16: 6 | AL16: =(BK16/5+1)*AK16 -> 6 | AM16: 0 | AN16: 0 | AO16: 0 | AP16: 0 | AQ16: 0 | AR16: 0 | AS16: 0 | AT16: 0 | AU16: 7 | AV16: 0 | AW16: 0 | AX16: none | AY16: 0 | AZ16: 0 | BA16: 0 | BB16: 0 | BC16: 0 | BD16: 0 | BE16: 0 | BF16: 0 | BG16: 0 | BH16: 0 | BI16: 0 | BJ16: 0 | BK16: 0 | BL16: 0 | BM16: 0 | BN16: 6 | BO16: 0 | BP16: =(((J16*I16*H16)+Q16+(W16/4))/1500)+((AQ16*(AR16/3))/5) -> 2.6666667 | BQ16: =(((J16*I16*H16)+R16+(W16/4))/1500)+((AQ16*(AR16/5))/5) -> 2.6666667 | BR16: =((((J16*(Y16/7))*I16*H16)+S16+(W16/4))/1500)+((AQ16*(AR16/7))/5) -> 1.4095238 | BS16: =((((J16*(Y16/9))*I16*H16)+T16+(W16/4))/1200)+((AQ16*(AR16/9))/5) -> 1.7037037 | BT16: =(((K16*I16*H16)+(((I16*K16+P16)/F16)*Q16))/(1.25-((K16-J16)/4))+(W16/4))/1300 -> 1.808 | BU16: =(((L16*I16*H16)+(((I16*L16+P16)/F16)*(R16)))/(1.25-((L16-J16)/4))+(W16/4))/800 -> 0.285 | BV16: =(((M16*I16*H16)+(((I16*M16+P16)/F16)*(S16)))/(1.25-((M16-J16)/4))+(W16/4))/400 -> 0.57 | BW16: =(((N16*I16*H16)+(((I16*N16+P16)/F16)*(T16)))/(1.25-((N16-J16)/4))+(W16/4))/250 -> 0.912 | BY16: =((BT16/2)*X16)/2.5 -> 2.6517333 | BZ16: =((BU16)*(X16/2))/3.5 -> 0.29857143 | CA16: =((BV16*1.5)*(X16/3))/3 -> 0.69666667 | CB16: =((BW16*2)*(X16/4))/5 -> 0.6688 | CD16: =(AL16*BY16)/3 -> 5.3034667 | CE16: =(AL16*BZ16)/2.7 -> 0.66349206 | CF16: =(AL16*CA16)/2.5 -> 1.672 | CG16: =(AL16*CB16)/1.9 -> 2.112 | CI16: =SUM(AL16*4, AJ16*2, X16*2, BD16*2)/6 -> 9.4444444 | CJ16: =SUM(AVERAGE(AA16, (AVERAGE(BY16, BZ16))/1.5)*4, X16*4, Y16*2, CI16*2)/9 -> 6.0210102 | CK16: =SUM(AC16*5, (AVERAGE(BY16, BZ16, CA16, CB16)/2)*2, BD16*2)/6 -> 0.17982381 | CL16: =IF(AB16<6, (AB16/2)*U16/2000, IF(AB16<7, (AB16/2)*(AVERAGE(BT16, BU16, BV16, BW16)/2.5), (AB16/2)*(AVERAGE(BT16, BU16, BV16, BW16)/2.5)+(U16/2000))) -> 1.35 | CM16: =SUM(AM16*4, AP16*2/(AO16+1), AN16*4)/7.5 -> 0 | CN16: =SUM(AP16*3, AQ16*2, AR16*2, AS16*2, AM16*3)/8 -> 0 | CO16: =(SUM(AA16*2, BK16*1, AU16*3)/4.5)*1.5 -> 7.6666667
B17: 12 | C17: TICK | D17: easy_approach | E17: multiple_pets_generation | F17: 6 | G17: =14/F17 -> 2.3333333 | H17: 1360 | I17: =(1.65-((O17*1.65)/2)) -> 0.9625 | J17: 1.5 | K17: 0.6 | L17: 1.2 | M17: 1.8 | N17: 0.6 | O17: =2.5 / 3 -> 0.83333333 | P17: =2-(2*(V17/2)) -> 1.9 | Q17: 4000 | R17: 3000 | S17: 2000 | T17: 1000 | U17: 4000 | V17: 0.1 | W17: 0 | X17: =4800/1400 -> 3.4285714 | Y17: 7 | Z17: 0 | AA17: 1 | AB17: 7 | AC17: =(6 + 2 + 3 + 8)/4 -> 4.75 | AD17: 1 | AE17: 0 | AF17: 6 | AG17: 0 | AH17: 0 | AI17: 0 | AJ17: 5 | AK17: 0 | AL17: =(BK17/5+1)*AK17 -> 0 | AM17: 4 | AN17: 1 | AO17: 0 | AP17: 2 | AQ17: 6 | AR17: 1 | AS17: 10 | AT17: 5 | AU17: 1 | AV17: =(3 + 5 + 5 + 5)/4 -> 4.5 | AW17: 0 | AX17: none | AY17: 0 | AZ17: 0 | BA17: 0 | BB17: 0 | BC17: 0 | BD17: 0 | BE17: 0 | BF17: 0 | BG17: 0 | BH17: 0 | BI17: 0 | BJ17: 0 | BK17: 0 | BL17: 0 | BM17: 0.5 | BN17: 7 | BO17: 0 | BP17: =(((J17*I17*H17)+Q17+(W17/4))/1500)+((AQ17*(AR17/3))/5) -> 4.3756667 | BQ17: =(((J17*I17*H17)+R17+(W17/4))/1500)+((AQ17*(AR17/5))/5) -> 3.549 | BR17: =((((J17*(Y17/7))*I17*H17)+S17+(W17/4))/1500)+((AQ17*(AR17/7))/5) -> 2.8137619 | BS17: =((((J17*(Y17/9))*I17*H17)+T17+(W17/4))/1200)+((AQ17*(AR17/9))/5) -> 2.2393056 | BT17: =(((K17*I17*H17)+(((I17*K17+P17)/F17)*Q17))/(1.25-((K17-J17)/4))+(W17/4))/1300 -> 1.2709605 | BU17: =(((L17*I17*H17)+(((I17*L17+P17)/F17)*(R17)))/(1.25-((L17-J17)/4))+(W17/4))/800 -> 2.9229245 | BV17: =(((M17*I17*H17)+(((I17*M17+P17)/F17)*(S17)))/(1.25-((M17-J17)/4))+(W17/4))/400 -> 7.5894326 | BW17: =(((N17*I17*H17)+(((I17*N17+P17)/F17)*(T17)))/(1.25-((N17-J17)/4))+(W17/4))/250 -> 3.2496723 | BY17: =((BT17/2)*X17)/2.5 -> 0.87151574 | BZ17: =((BU17)*(X17/2))/3.5 -> 1.4316365 | CA17: =((BV17*1.5)*(X17/3))/3 -> 4.3368186 | CB17: =((BW17*2)*(X17/4))/5 -> 1.1141734 | CD17: =(AL17*BY17)/3 -> 0 | CE17: =(AL17*BZ17)/2.7 -> 0 | CF17: =(AL17*CA17)/2.5 -> 0 | CG17: =(AL17*CB17)/1.9 -> 0 | CI17: =SUM(AL17*4, AJ17*2, X17*2, BD17*2)/6 -> 2.8095238 | CJ17: =SUM(AVERAGE(AA17, (AVERAGE(BY17, BZ17))/1.5)*4, X17*4, Y17*2, CI17*2)/9 -> 4.0965298 | CK17: =SUM(AC17*5, (AVERAGE(BY17, BZ17, CA17, CB17)/2)*2, BD17*2)/6 -> 4.2814227 | CL17: =IF(AB17<6, (AB17/2)*U17/2000, IF(AB17<7, (AB17/2)*(AVERAGE(BT17, BU17, BV17, BW17)/2.5), (AB17/2)*(AVERAGE(BT17, BU17, BV17, BW17)/2.5)+(U17/2000))) -> 7.2615465 | CM17: =SUM(AM17*4, AP17*2/(AO17+1), AN17*4)/7.5 -> 3.2 | CN17: =SUM(AP17*3, AQ17*2, AR17*2, AS17*2, AM17*3)/8 -> 6.5 | CO17: =(SUM(AA17*2, BK17*1, AU17*3)/4.5)*1.5 -> 1.6666667
B18: 76 | C18: JUJU | D18: easy_approach | E18: wall_break_efficiency | F18: 7 | G18: =16/F18 -> 2.2857143 | H18: 1800 | I18: =(2.5-((O18*2.5)/2)) -> 1.9166667 | J18: 1 | K18: 1 | L18: 0.8 | M18: 0.4 | N18: 0.2 | O18: =1.4 / 3 -> 0.46666667 | P18: =2.5-(2.5*(V18/2)) -> 2.25 | Q18: 1600 | R18: 3200 | S18: 2400 | T18: 0 | U18: 6400 | V18: 0.2 | W18: 0 | X18: =6200/1400 -> 4.4285714 | Y18: 7 | Z18: 0 | AA18: 1 | AB18: 6 | AC18: 0 | AD18: 0 | AE18: 1 | AF18: 7 | AG18: 0 | AH18: 0 | AI18: 0 | AJ18: 5 | AK18: 0 | AL18: =(BK18/5+1)*AK18 -> 0 | AM18: 4 | AN18: 1 | AO18: 0 | AP18: 7 | AQ18: 4 | AR18: 4 | AS18: 4 | AT18: 7.5 | AU18: 0 | AV18: =(3 + 5 + 5 + 5)/4 -> 4.5 | AW18: 5 | AX18: Some of this brawler's abilities are only available on maps with water and grass. | AY18: 0 | AZ18: 0 | BA18: 0 | BB18: 0 | BC18: 0 | BD18: 0 | BE18: 0 | BF18: 0 | BG18: 0 | BH18: 0 | BI18: 0 | BJ18: 0 | BK18: =(5 + 5 + 10)/3 -> 6.6666667 | BL18: 0 | BM18: 0 | BN18: 7 | BO18: 0 | BP18: =(((J18*I18*H18)+Q18+(W18/4))/1500)+((AQ18*(AR18/3))/5) -> 4.4333333 | BQ18: =(((J18*I18*H18)+R18+(W18/4))/1500)+((AQ18*(AR18/5))/5) -> 5.0733333 | BR18: =((((J18*(Y18/7))*I18*H18)+S18+(W18/4))/1500)+((AQ18*(AR18/7))/5) -> 4.3571429 | BS18: =((((J18*(Y18/9))*I18*H18)+T18+(W18/4))/1200)+((AQ18*(AR18/9))/5) -> 2.5916667 | BT18: =(((K18*I18*H18)+(((I18*K18+P18)/F18)*Q18))/(1.25-((K18-J18)/4))+(W18/4))/1300 -> 2.7091575 | BU18: =(((L18*I18*H18)+(((I18*L18+P18)/F18)*(R18)))/(1.25-((L18-J18)/4))+(W18/4))/800 -> 4.3168498 | BV18: =(((M18*I18*H18)+(((I18*M18+P18)/F18)*(S18)))/(1.25-((M18-J18)/4))+(W18/4))/400 -> 4.3112245 | BW18: =(((N18*I18*H18)+(((I18*N18+P18)/F18)*(T18)))/(1.25-((N18-J18)/4))+(W18/4))/250 -> 1.9034483 | BY18: =((BT18/2)*X18)/2.5 -> 2.3995395 | BZ18: =((BU18)*(X18/2))/3.5 -> 2.7310683 | CA18: =((BV18*1.5)*(X18/3))/3 -> 3.1820943 | CB18: =((BW18*2)*(X18/4))/5 -> 0.84295567 | CD18: =(AL18*BY18)/3 -> 0 | CE18: =(AL18*BZ18)/2.7 -> 0 | CF18: =(AL18*CA18)/2.5 -> 0 | CG18: =(AL18*CB18)/1.9 -> 0 | CI18: =SUM(AL18*4, AJ18*2, X18*2, BD18*2)/6 -> 3.1428571 | CJ18: =SUM(AVERAGE(AA18, (AVERAGE(BY18, BZ18))/1.5)*4, X18*4, Y18*2, CI18*2)/9 -> 4.8244895 | CK18: =SUM(AC18*5, (AVERAGE(BY18, BZ18, CA18, CB18)/2)*2, BD18*2)/6 -> 0.38148574 | CL18: =IF(AB18<6, (AB18/2)*U18/2000, IF(AB18<7, (AB18/2)*(AVERAGE(BT18, BU18, BV18, BW18)/2.5), (AB18/2)*(AVERAGE(BT18, BU18, BV18, BW18)/2.5)+(U18/2000))) -> 3.972204 | CM18: =SUM(AM18*4, AP18*2/(AO18+1), AN18*4)/7.5 -> 4.5333333 | CN18: =SUM(AP18*3, AQ18*2, AR18*2, AS18*2, AM18*3)/8 -> 7.125 | CO18: =(SUM(AA18*2, BK18*1, AU18*3)/4.5)*1.5 -> 2.8888889
